Workbook

Sheet Nach Mannschaften sortiert
A1: fortlaufende Nummer | B1: Runde | C1: Mannschaft | D1: fixierter Termin | E1: fixierte Uhrzeit | F1: Ort | G1: Gegner | H1: Auswärt/Heim
B2: 0 | C2: KM | D2: 46220 | E2: 0.79166667 | F2: Rohrbach | G2: Rohrbach | H2: Auswärts
B3: 0 | C3: KM | D3: 46241 | E3: 0.79166667 | F3: Neufeld | G3: Bad Fischau | H3: Heim
B4: 0 | C4: U16 | D4: 46199 | E4: 0.75 | F4: Wimpassing | G4: SK Rapid Wien | H4: Heim
B5: 0 | C5: U15 | D5: 46199 | E5: 0.66666667 | F5: Wimpassing | G5: SK Rapid Wien | H5: Heim
A6: 1 | B6: 1 | C6: KM
A7: 2 | B7: 2 | C7: KM
A8: 3 | B8: 3 | C8: KM
A9: 4 | B9: 4 | C9: KM
A10: 5 | B10: 5 | C10: KM
A11: 6 | B11: 6 | C11: KM
A12: 7 | B12: 7 | C12: KM
A13: 8 | B13: 8 | C13: KM
A14: 9 | B14: 9 | C14: KM
A15: 10 | B15: 10 | C15: KM
A16: 11 | B16: 11 | C16: KM
A17: 12 | B17: 12 | C17: KM
... A77: 67 | B77: 4 | C77: U11
B78: 5 | C78: U11
B79: 6 | C79: U11
B80: 7 | C80: U11
B81: 8 | C81: U11
B82: 9 | C82: U11
A83: 68 | B83: 10 | C83: U11
A84: 69 | B84: 1 | C84: U10
A85: 70 | B85: 2 | C85: U10
A86: 71 | B86: 3 | C86: U10
B87: 4 | C87: U10
B88: 5 | C88: U10
B89: 6 | C89: U10
B90: 7 | C90: U10
B91: 8 | C91: U10
A92: 72 | B92: 9 | C92: U10
A93: 73 | B93: 10 | C93: U10
A94: 74 | B94: 1 | C94: U9
A95: 75 | B95: 2 | C95: U9
B96: 3 | C96: U9
B97: 4 | C97: U9
B98: 5 | C98: U9
B99: 6 | C99: U9
...

Sheet ICS2
A1: TITEL | B1: DATUM | C1: STARTZEIT | D1: ENDZEIT | E1: ORT | F1: BESCHREIBUNG | G1: TYP | H1: GEGNER | I1: LIGA | J1: STATUS | K1: SPIELART | L1: ART
B2: 46220 | C2: 0.79166667 | D2: =IF(I2 = "KM",C2+"1:45",IF(I2="U23",C2+"1:45",IF(I2 = "U16",C2+"1:45",IF(I2 = "U15",C2+"1:30",IF(I2 = "U14",C2+"1:30",IF(I2 = "U13",C2+"1:35",IF(I2 = "U12",C2+"1:10",IF(I2 = "U11",C2+"1:10",IF(I2 = "U10",C2+"1:03",C2+"3:00"))))))))) -> 0.86458333 | E2: ROHRBACH | G2: Auswärts | H2: Rohrbach | I2: KM | J2: aktiv | K2: Freundschaft | L2: Spiel
B3: 46241 | C3: 0.79166667 | D3: =IF(I3 = "KM",C3+"1:45",IF(I3="U23",C3+"1:45",IF(I3 = "U16",C3+"1:45",IF(I3 = "U15",C3+"1:30",IF(I3 = "U14",C3+"1:30",IF(I3 = "U13",C3+"1:35",IF(I3 = "U12",C3+"1:10",IF(I3 = "U11",C3+"1:10",IF(I3 = "U10",C3+"1:03",C3+"3:00"))))))))) -> 0.86458333 | E3: NEUFELD | G3: Heim | H3: Bad Fischau | I3: KM | J3: aktiv | K3: Freundschaft | L3: Spiel
B4: 46199 | C4: 0.75 | D4: =IF(I4 = "KM",C4+"1:45",IF(I4="U23",C4+"1:45",IF(I4 = "U16",C4+"1:45",IF(I4 = "U15",C4+"1:30",IF(I4 = "U14",C4+"1:30",IF(I4 = "U13",C4+"1:35",IF(I4 = "U12",C4+"1:10",IF(I4 = "U11",C4+"1:10",IF(I4 = "U10",C4+"1:03",C4+"3:00"))))))))) -> 0.82291667 | E4: WIMPASSING | G4: Heim | H4: SK Rapid Wien | I4: U16 | J4: aktiv | K4: Freundschaft | L4: Spiel
B5: 46199 | C5: 0.66666667 | D5: =IF(I5 = "KM",C5+"1:45",IF(I5="U23",C5+"1:45",IF(I5 = "U16",C5+"1:45",IF(I5 = "U15",C5+"1:30",IF(I5 = "U14",C5+"1:30",IF(I5 = "U13",C5+"1:35",IF(I5 = "U12",C5+"1:10",IF(I5 = "U11",C5+"1:10",IF(I5 = "U10",C5+"1:03",C5+"3:00"))))))))) -> 0.72916667 | E5: WIMPASSING | G5: Heim | H5: SK Rapid Wien | I5: U15 | J5: aktiv | K5: Freundschaft | L5: Spiel
B6: 36526 | C6: 0 | D6: 0.072916667 | I6: ='Nach Mannschaften sortiert'!C6 -> KM | J6: inaktiv | K6: Liga | L6: Spiel
B7: 36527 | C7: 0 | D7: 0.072916667 | I7: ='Nach Mannschaften sortiert'!C7 -> KM | J7: inaktiv | K7: Liga | L7: Spiel
B8: 36528 | C8: 0 | D8: 0.072916667 | I8: ='Nach Mannschaften sortiert'!C8 -> KM | J8: inaktiv | K8: Liga | L8: Spiel
B9: 36529 | C9: 0 | D9: 0.072916667 | I9: ='Nach Mannschaften sortiert'!C9 -> KM | J9: inaktiv | K9: Liga | L9: Spiel
B10: 36530 | C10: 0 | D10: 0.072916667 | I10: ='Nach Mannschaften sortiert'!C10 -> KM | J10: inaktiv | K10: Liga | L10: Spiel
B11: 36531 | C11: 0 | D11: 0.072916667 | I11: ='Nach Mannschaften sortiert'!C11 -> KM | J11: inaktiv | K11: Liga | L11: Spiel
B12: 36532 | C12: 0 | D12: 0.072916667 | I12: ='Nach Mannschaften sortiert'!C12 -> KM | J12: inaktiv | K12: Liga | L12: Spiel
B13: 36533 | C13: 0 | D13: 0.072916667 | I13: ='Nach Mannschaften sortiert'!C13 -> KM | J13: inaktiv | K13: Liga | L13: Spiel
B14: 36534 | C14: 0 | D14: 0.072916667 | I14: ='Nach Mannschaften sortiert'!C14 -> KM | J14: inaktiv | K14: Liga | L14: Spiel
B15: 36535 | C15: 0 | D15: 0.072916667 | I15: ='Nach Mannschaften sortiert'!C15 -> KM | J15: inaktiv | K15: Liga | L15: Spiel
B16: 36536 | C16: 0 | D16: 0.072916667 | I16: ='Nach Mannschaften sortiert'!C16 -> KM | J16: inaktiv | K16: Liga | L16: Spiel
B17: 36537 | C17: 0 | D17: 0.072916667 | I17: ='Nach Mannschaften sortiert'!C17 -> KM | J17: inaktiv | K17: Liga | L17: Spiel
... B113: 36633 | C113: 0 | D113: 0.072916667 | I113: ='Nach Mannschaften sortiert'!C113 -> U7 | J113: inaktiv | K113: Liga | L113: Spiel
B114: ='Nach Mannschaften sortiert'!D114 -> 46321 | C114: 0.375 | D114: =IF(I114 = "KM",C114+"1:45",IF(I114="U23",C114+"1:45",IF(I114 = "U16",C114+"1:45",IF(I114 = "U15",C114+"1:30",IF(I114 = "U14",C114+"1:30",IF(I114 = "U13",C114+"1:35",IF(I114 = "U12",C114+"1:10",IF(I114 = "U11",C114+"1:10",IF(I114 = "U10",C114+"1:03",C114+"3:00"))))))))) -> 0.5 | E114: Neufeld | G114: Heim | H114: CAMP | I114: TECO 7 CAMP | J114: aktiv | K114: Camp | L114: Camp
B115: ='Nach Mannschaften sortiert'!D115 -> 46322 | C115: 0.375 | D115: =IF(I115 = "KM",C115+"1:45",IF(I115="U23",C115+"1:45",IF(I115 = "U16",C115+"1:45",IF(I115 = "U15",C115+"1:30",IF(I115 = "U14",C115+"1:30",IF(I115 = "U13",C115+"1:35",IF(I115 = "U12",C115+"1:10",IF(I115 = "U11",C115+"1:10",IF(I115 = "U10",C115+"1:03",C115+"3:00"))))))))) -> 0.5 | E115: Neufeld | G115: Heim | H115: CAMP | I115: TECO 7 CAMP | J115: aktiv | K115: Camp | L115: Camp
B116: ='Nach Mannschaften sortiert'!D116 -> 46323 | C116: 0.375 | D116: =IF(I116 = "KM",C116+"1:45",IF(I116="U23",C116+"1:45",IF(I116 = "U16",C116+"1:45",IF(I116 = "U15",C116+"1:30",IF(I116 = "U14",C116+"1:30",IF(I116 = "U13",C116+"1:35",IF(I116 = "U12",C116+"1:10",IF(I116 = "U11",C116+"1:10",IF(I116 = "U10",C116+"1:03",C116+"3:00"))))))))) -> 0.5 | E116: Neufeld | G116: Heim | H116: CAMP | I116: TECO 7 CAMP | J116: aktiv | K116: Camp | L116: Camp
B117: ='Nach Mannschaften sortiert'!D117 -> 46230 | C117: 0.375 | D117: =IF(I117 = "KM",C117+"1:45",IF(I117="U23",C117+"1:45",IF(I117 = "U16",C117+"1:45",IF(I117 = "U15",C117+"1:30",IF(I117 = "U14",C117+"1:30",IF(I117 = "U13",C117+"1:35",IF(I117 = "U12",C117+"1:10",IF(I117 = "U11",C117+"1:10",IF(I117 = "U10",C117+"1:03",C117+"3:00"))))))))) -> 0.5 | E117: Neufeld | G117: Heim | H117: CAMP | I117: REAL MADRID CAMP | J117: aktiv | K117: Camp | L117: Camp
B118: ='Nach Mannschaften sortiert'!D118 -> 46231 | C118: 0.375 | D118: =IF(I118 = "KM",C118+"1:45",IF(I118="U23",C118+"1:45",IF(I118 = "U16",C118+"1:45",IF(I118 = "U15",C118+"1:30",IF(I118 = "U14",C118+"1:30",IF(I118 = "U13",C118+"1:35",IF(I118 = "U12",C118+"1:10",IF(I118 = "U11",C118+"1:10",IF(I118 = "U10",C118+"1:03",C118+"3:00"))))))))) -> 0.5 | E118: Neufeld | G118: Heim | H118: CAMP | I118: REAL MADRID CAMP | J118: aktiv | K118: Camp | L118: Camp
B119: ='Nach Mannschaften sortiert'!D119 -> 46232 | C119: 0.375 | D119: =IF(I119 = "KM",C119+"1:45",IF(I119="U23",C119+"1:45",IF(I119 = "U16",C119+"1:45",IF(I119 = "U15",C119+"1:30",IF(I119 = "U14",C119+"1:30",IF(I119 = "U13",C119+"1:35",IF(I119 = "U12",C119+"1:10",IF(I119 = "U11",C119+"1:10",IF(I119 = "U10",C119+"1:03",C119+"3:00"))))))))) -> 0.5 | E119: Neufeld | G119: Heim | H119: CAMP | I119: REAL MADRID CAMP | J119: aktiv | K119: Camp | L119: Camp
B120: ='Nach Mannschaften sortiert'!D120 -> 46233 | C120: 0.375 | D120: =IF(I120 = "KM",C120+"1:45",IF(I120="U23",C120+"1:45",IF(I120 = "U16",C120+"1:45",IF(I120 = "U15",C120+"1:30",IF(I120 = "U14",C120+"1:30",IF(I120 = "U13",C120+"1:35",IF(I120 = "U12",C120+"1:10",IF(I120 = "U11",C120+"1:10",IF(I120 = "U10",C120+"1:03",C120+"3:00"))))))))) -> 0.5 | E120: Neufeld | G120: Heim | H120: CAMP | I120: REAL MADRID CAMP | J120: aktiv | K120: Camp | L120: Camp
B121: ='Nach Mannschaften sortiert'!D121 -> 46234 | C121: 0.375 | D121: =IF(I121 = "KM",C121+"1:45",IF(I121="U23",C121+"1:45",IF(I121 = "U16",C121+"1:45",IF(I121 = "U15",C121+"1:30",IF(I121 = "U14",C121+"1:30",IF(I121 = "U13",C121+"1:35",IF(I121 = "U12",C121+"1:10",IF(I121 = "U11",C121+"1:10",IF(I121 = "U10",C121+"1:03",C121+"3:00"))))))))) -> 0.5 | E121: Neufeld | G121: Heim | H121: CAMP | I121: REAL MADRID CAMP | J121: aktiv | K121: Camp | L121: Camp
B122: 46237 | C122: 0.375 | D122: 0.625 | E122: Neufeld | G122: Heim | H122: CAMP | I122: MÄDCHEN CAMP | J122: aktiv | K122: Camp | L122: Camp
B123: 46238 | C123: 0.375 | D123: 0.625 | E123: Neufeld | G123: Heim | H123: CAMP | I123: MÄDCHEN CAMP | J123: aktiv | K123: Camp | L123: Camp
B124: 46239 | C124: 0.375 | D124: 0.625 | E124: Neufeld | G124: Heim | H124: CAMP | I124: MÄDCHEN CAMP | J124: aktiv | K124: Camp | L124: Camp
B125: ='Nach Mannschaften sortiert'!D122 -> 46256 | C125: ='Nach Mannschaften sortiert'!E122 -> 0.375 | D125: =IF(I125 = "KM",C125+"1:45",IF(I125="U23",C125+"1:45",IF(I125 = "U16",C125+"1:45",IF(I125 = "U15",C125+"1:30",IF(I125 = "U14",C125+"1:30",IF(I125 = "U13",C125+"1:35",IF(I125 = "U12",C125+"1:10",IF(I125 = "U11",C125+"1:10",IF(I125 = "U10",C125+"1:03",C125+"3:00"))))))))) -> 0.5 | E125: Neufeld | G125: Heim | H125: ='Nach Mannschaften sortiert'!G122 -> viele Gegner | I125: ='Nach Mannschaften sortiert'!C122 -> GGG | J125: aktiv | K125: Turnier | L125: Turnier
B126: 26.06.2026 | C126: 10:00 | D126: 11:30 | E126: Neufeld | G126: Heim | H126: FC Arsenal | I126: U14 | J126: Aktiv | L126: Spiel

Sheet Kalendernamen
A1: Kategorie | C1: ABOLINK
A2: Alle Spiele des ASV Neufeld | B2: alle_spiele.ics | C2: ="https://dtb-asv.github.io/asv-neufeld/"&B2 -> https://dtb-asv.github.io/asv-neufeld/alle_spiele.ics
A3: Alle Heimspiele des ASV Neufelds | B3: heimspiele.ics | C3: ="https://dtb-asv.github.io/asv-neufeld/"&B3 -> https://dtb-asv.github.io/asv-neufeld/heimspiele.ics
A4: Alle Auswärtsspiele des ASV Neufelds | B4: auswaertsspiele.ics | C4: ="https://dtb-asv.github.io/asv-neufeld/"&B4 -> https://dtb-asv.github.io/asv-neufeld/auswaertsspiele.ics
A5: Alle Spiele der Kampfmannschaft | B5: KM.ics | C5: ="https://dtb-asv.github.io/asv-neufeld/"&B5 -> https://dtb-asv.github.io/asv-neufeld/KM.ics
A6: Alle Spiele der U23 | B6: U23.ics | C6: ="https://dtb-asv.github.io/asv-neufeld/"&B6 -> https://dtb-asv.github.io/asv-neufeld/U23.ics
A7: Alle Spiele der U16 | B7: U16.ics | C7: ="https://dtb-asv.github.io/asv-neufeld/"&B7 -> https://dtb-asv.github.io/asv-neufeld/U16.ics
A8: Alle Spiele der U15 | B8: U15.ics | C8: ="https://dtb-asv.github.io/asv-neufeld/"&B8 -> https://dtb-asv.github.io/asv-neufeld/U15.ics
A9: Alle Spiele der U14 | B9: U14.ics | C9: ="https://dtb-asv.github.io/asv-neufeld/"&B9 -> https://dtb-asv.github.io/asv-neufeld/U14.ics
A10: Alle Spiele der U13 | B10: U13.ics | C10: ="https://dtb-asv.github.io/asv-neufeld/"&B10 -> https://dtb-asv.github.io/asv-neufeld/U13.ics
A11: Alle Spiele der U12 | B11: U12.ics | C11: ="https://dtb-asv.github.io/asv-neufeld/"&B11 -> https://dtb-asv.github.io/asv-neufeld/U12.ics
A12: Alle Spiele der U11 | B12: U11.ics | C12: ="https://dtb-asv.github.io/asv-neufeld/"&B12 -> https://dtb-asv.github.io/asv-neufeld/U11.ics
A13: Alle Spiele der U10 | B13: U10.ics | C13: ="https://dtb-asv.github.io/asv-neufeld/"&B13 -> https://dtb-asv.github.io/asv-neufeld/U10.ics
... A16: Alle Spiele der U7 | B16: U7.ics | C16: ="https://dtb-asv.github.io/asv-neufeld/"&B16 -> https://dtb-asv.github.io/asv-neufeld/ U7.ics
B17: Camp.ics | C17: ="https://dtb-asv.github.io/asv-neufeld/"&B17 -> https://dtb-asv.github.io/asv-neufeld/ Camp.ics
B18: GGG.ics | C18: ="https://dtb-asv.github.io/asv-neufeld/"&B18 -> https://dtb-asv.github.io/asv-neufeld/ GGG.ics

Sheet Trainingsplan
A1: TRAININGSORTE/TAGE
A2: MANNSCHAFT | B2: TRAINER | C2: MONTAG | D2: DIENSTAG | E2: MITTWOCH | F2: DONNERSTAG | G2: FREITAG | H2: SAMSTAG | I2: WENN KM-TRAINING MUSS DAS HAUPTFELD AB 18:45 FREI SEIN
A3: FKG | B3: RONNIE ARCHAM | E3: 16:00 - 16:45
A4: U7 | B4: ÖMER TÜRKES TAHA MAHSUMI | D4: 17:30 - 18:30 | F4: 17:30 - 18:30
A5: U8 | B5: TOBIAS BERGER SEBASTIAN PUTRIC | C5: 16:30 - 18:00 | F5: 17: 00 - 18:30
A6: U9 | B6: THOMAS BRANDL DANIEL HOFBAUER | D6: 17:00 - 18:30 | F6: 17:00 - 18:30
A7: U11 | B7: MARIO MAGLER RONNIE ARCHAM | C7: 17:00 - 18:30 | E7: 17:00 - 18:30 | G7: 17:00 - 18:30
A8: U13 | B8: THOMAS PÖSCHL LENZ HONC | C8: 17:00 - 18:30 | E8: 17:00 - 18:30 | G8: 17:00 - 18:30
A9: U14 | B9: GERNOT SEVELDA MARKUS DORINGER | C9: 17:00 - 18:30 | F9: 17:00 - 18:30 | G9: 17:00 - 18:30 | H9: 10:00 - 11:00
A10: U15 | B10: SERDAR EKINCI HUBERT OBERHOFER | D10: 18:30 - 20:15 | F10: 18:00 - 19:30 | G10: 18:30 - 20:15
A11: U16 | B11: JOSCH KÖGL | E11: 17:15 - 19:00 | G11: WIMPASSING
A12: U23 | B12: DINGES STEFAN | C12: 18:45 - 20:15 | E12: 18:45 - 20:15 | F12: 18:45 - 20:15
A13: KM | B13: PLENINGER STEFAN | C13: 18:45 - 20:15 | E13: 18:45 - 20:15 | F13: 18:45 - 20:15
A14: JUNIOREN/SENIOREN | D14: 18:45 - 20:15
A15: HAUPTFELD
A16: TRAININGSPLATZ
A17: HINTERM TOR
A18: SPIELGEMEINSCHAFTEN MIT WIMPASSING

Sheet Heimspiele
A1: ='Nach Mannschaften sortiert'!A1 -> fortlaufende Nummer | B1: ='Nach Mannschaften sortiert'!B1 -> Runde | C1: ='Nach Mannschaften sortiert'!C1 -> Mannschaft | D1: ='Nach Mannschaften sortiert'!D1 -> fixierter Termin | E1: ='Nach Mannschaften sortiert'!E1 -> fixierte Uhrzeit | F1: ='Nach Mannschaften sortiert'!F1 -> Ort | G1: ='Nach Mannschaften sortiert'!G1 -> Gegner | H1: ='Nach Mannschaften sortiert'!H1 -> Auswärt/Heim
A2: ='Nach Mannschaften sortiert'!A6 -> 1 | B2: ='Nach Mannschaften sortiert'!B6 -> 1 | C2: ='Nach Mannschaften sortiert'!C6 -> KM | D2: ='Nach Mannschaften sortiert'!D6 -> 0 | E2: ='Nach Mannschaften sortiert'!E6 -> 0 | F2: ='Nach Mannschaften sortiert'!F6 -> 0 | G2: ='Nach Mannschaften sortiert'!G6 -> 0 | H2: ='Nach Mannschaften sortiert'!H6 -> 0
A3: ='Nach Mannschaften sortiert'!A7 -> 2 | B3: ='Nach Mannschaften sortiert'!B7 -> 2 | C3: ='Nach Mannschaften sortiert'!C7 -> KM | D3: ='Nach Mannschaften sortiert'!D7 -> 0 | E3: ='Nach Mannschaften sortiert'!E7 -> 0 | F3: ='Nach Mannschaften sortiert'!F7 -> 0 | G3: ='Nach Mannschaften sortiert'!G7 -> 0 | H3: ='Nach Mannschaften sortiert'!H7 -> 0
A4: ='Nach Mannschaften sortiert'!A8 -> 3 | B4: ='Nach Mannschaften sortiert'!B8 -> 3 | C4: ='Nach Mannschaften sortiert'!C8 -> KM | D4: ='Nach Mannschaften sortiert'!D8 -> 0 | E4: ='Nach Mannschaften sortiert'!E8 -> 0 | F4: ='Nach Mannschaften sortiert'!F8 -> 0 | G4: ='Nach Mannschaften sortiert'!G8 -> 0 | H4: ='Nach Mannschaften sortiert'!H8 -> 0
A5: ='Nach Mannschaften sortiert'!A50 -> 34 | B5: ='Nach Mannschaften sortiert'!B50 -> 1 | C5: ='Nach Mannschaften sortiert'!C50 -> U13 | D5: ='Nach Mannschaften sortiert'!D50 -> 0 | E5: ='Nach Mannschaften sortiert'!E50 -> 0 | F5: ='Nach Mannschaften sortiert'!F50 -> 0 | G5: ='Nach Mannschaften sortiert'!G50 -> 0 | H5: ='Nach Mannschaften sortiert'!H50 -> 0
A6: ='Nach Mannschaften sortiert'!A10 -> 5 | B6: ='Nach Mannschaften sortiert'!B10 -> 5 | C6: ='Nach Mannschaften sortiert'!C10 -> KM | D6: ='Nach Mannschaften sortiert'!D10 -> 0 | E6: ='Nach Mannschaften sortiert'!E10 -> 0 | F6: ='Nach Mannschaften sortiert'!F10 -> 0 | G6: ='Nach Mannschaften sortiert'!G10 -> 0 | H6: ='Nach Mannschaften sortiert'!H10 -> 0
A7: ='Nach Mannschaften sortiert'!A58 -> 44 | B7: ='Nach Mannschaften sortiert'!B58 -> 1 | C7: ='Nach Mannschaften sortiert'!C58 -> U12_1 | D7: ='Nach Mannschaften sortiert'!D58 -> 0 | E7: ='Nach Mannschaften sortiert'!E58 -> 0 | F7: ='Nach Mannschaften sortiert'!F58 -> 0 | G7: ='Nach Mannschaften sortiert'!G58 -> 0 | H7: ='Nach Mannschaften sortiert'!H58 -> 0
A8: ='Nach Mannschaften sortiert'!A12 -> 7 | B8: ='Nach Mannschaften sortiert'!B12 -> 7 | C8: ='Nach Mannschaften sortiert'!C12 -> KM | D8: ='Nach Mannschaften sortiert'!D12 -> 0 | E8: ='Nach Mannschaften sortiert'!E12 -> 0 | F8: ='Nach Mannschaften sortiert'!F12 -> 0 | G8: ='Nach Mannschaften sortiert'!G12 -> 0 | H8: ='Nach Mannschaften sortiert'!H12 -> 0
A9: ='Nach Mannschaften sortiert'!A104 -> 79 | B9: ='Nach Mannschaften sortiert'!B104 -> 1 | C9: ='Nach Mannschaften sortiert'!C104 -> U8 | D9: ='Nach Mannschaften sortiert'!D104 -> 0 | E9: ='Nach Mannschaften sortiert'!E104 -> 0 | F9: ='Nach Mannschaften sortiert'!F104 -> 0 | G9: ='Nach Mannschaften sortiert'!G104 -> 0 | H9: ='Nach Mannschaften sortiert'!H104 -> 0
A10: ='Nach Mannschaften sortiert'!A14 -> 9 | B10: ='Nach Mannschaften sortiert'!B14 -> 9 | C10: ='Nach Mannschaften sortiert'!C14 -> KM | D10: ='Nach Mannschaften sortiert'!D14 -> 0 | E10: ='Nach Mannschaften sortiert'!E14 -> 0 | F10: ='Nach Mannschaften sortiert'!F14 -> 0 | G10: ='Nach Mannschaften sortiert'!G14 -> 0 | H10: ='Nach Mannschaften sortiert'!H14 -> 0
A11: ='Nach Mannschaften sortiert'!A112 -> 80 | B11: ='Nach Mannschaften sortiert'!B112 -> 4 | C11: ='Nach Mannschaften sortiert'!C112 -> U7 | D11: ='Nach Mannschaften sortiert'!D112 -> 0 | E11: ='Nach Mannschaften sortiert'!E112 -> 0 | F11: ='Nach Mannschaften sortiert'!F112 -> 0 | G11: ='Nach Mannschaften sortiert'!G112 -> 0 | H11: ='Nach Mannschaften sortiert'!H112 -> 0
A12: ='Nach Mannschaften sortiert'!A16 -> 11 | B12: ='Nach Mannschaften sortiert'!B16 -> 11 | C12: ='Nach Mannschaften sortiert'!C16 -> KM | D12: ='Nach Mannschaften sortiert'!D16 -> 0 | E12: ='Nach Mannschaften sortiert'!E16 -> 0 | F12: ='Nach Mannschaften sortiert'!F16 -> 0 | G12: ='Nach Mannschaften sortiert'!G16 -> 0 | H12: ='Nach Mannschaften sortiert'!H16 -> 0
A13: ='Nach Mannschaften sortiert'!A17 -> 12 | B13: ='Nach Mannschaften sortiert'!B17 -> 12 | C13: ='Nach Mannschaften sortiert'!C17 -> KM | D13: ='Nach Mannschaften sortiert'!D17 -> 0 | E13: ='Nach Mannschaften sortiert'!E17 -> 0 | F13: ='Nach Mannschaften sortiert'!F17 -> 0 | G13: ='Nach Mannschaften sortiert'!G17 -> 0 | H13: ='Nach Mannschaften sortiert'!H17 -> 0
A14: ='Nach Mannschaften sortiert'!A113 -> 81 | B14: ='Nach Mannschaften sortiert'!B113 -> 5 | C14: ='Nach Mannschaften sortiert'!C113 -> U7 | D14: ='Nach Mannschaften sortiert'!D113 -> 0 | E14: ='Nach Mannschaften sortiert'!E113 -> 0 | F14: ='Nach Mannschaften sortiert'!F113 -> 0 | G14: ='Nach Mannschaften sortiert'!G113 -> 0 | H14: ='Nach Mannschaften sortiert'!H113 -> 0
A15: ='Nach Mannschaften sortiert'!A32 -> 14 | B15: ='Nach Mannschaften sortiert'!B32 -> 1 | C15: ='Nach Mannschaften sortiert'!C32 -> U16 | D15: ='Nach Mannschaften sortiert'!D32 -> 0 | E15: ='Nach Mannschaften sortiert'!E32 -> 0 | F15: ='Nach Mannschaften sortiert'!F32 -> 0 | G15: ='Nach Mannschaften sortiert'!G32 -> 0 | H15: ='Nach Mannschaften sortiert'!H32 -> 0
A16: ='Nach Mannschaften sortiert'!A33 -> 15 | B16: ='Nach Mannschaften sortiert'!B33 -> 2 | C16: ='Nach Mannschaften sortiert'!C33 -> U16 | D16: ='Nach Mannschaften sortiert'!D33 -> 0 | E16: ='Nach Mannschaften sortiert'!E33 -> 0 | F16: ='Nach Mannschaften sortiert'!F33 -> 0 | G16: ='Nach Mannschaften sortiert'!G33 -> 0 | H16: ='Nach Mannschaften sortiert'!H33 -> 0
A17: ='Nach Mannschaften sortiert'!A34 -> 16 | B17: ='Nach Mannschaften sortiert'!B34 -> 3 | C17: ='Nach Mannschaften sortiert'!C34 -> U16 | D17: ='Nach Mannschaften sortiert'!D34 -> 0 | E17: ='Nach Mannschaften sortiert'!E34 -> 0 | F17: ='Nach Mannschaften sortiert'!F34 -> 0 | G17: ='Nach Mannschaften sortiert'!G34 -> 0 | H17: ='Nach Mannschaften sortiert'!H34 -> 0
A18: ='Nach Mannschaften sortiert'!A9 -> 4 | B18: ='Nach Mannschaften sortiert'!B9 -> 4 | C18: ='Nach Mannschaften sortiert'!C9 -> KM | D18: ='Nach Mannschaften sortiert'!D9 -> 0 | E18: ='Nach Mannschaften sortiert'!E9 -> 0 | F18: ='Nach Mannschaften sortiert'!F9 -> 0 | G18: ='Nach Mannschaften sortiert'!G9 -> 0 | H18: ='Nach Mannschaften sortiert'!H9 -> 0
A19: ='Nach Mannschaften sortiert'!A36 -> 18 | B19: ='Nach Mannschaften sortiert'!B36 -> 5 | C19: ='Nach Mannschaften sortiert'!C36 -> U16 | D19: ='Nach Mannschaften sortiert'!D36 -> 0 | E19: ='Nach Mannschaften sortiert'!E36 -> 0 | F19: ='Nach Mannschaften sortiert'!F36 -> 0 | G19: ='Nach Mannschaften sortiert'!G36 -> 0 | H19: ='Nach Mannschaften sortiert'!H36 -> 0
A20: ='Nach Mannschaften sortiert'!A37 -> 19 | B20: ='Nach Mannschaften sortiert'!B37 -> 6 | C20: ='Nach Mannschaften sortiert'!C37 -> U16 | D20: ='Nach Mannschaften sortiert'!D37 -> 0 | E20: ='Nach Mannschaften sortiert'!E37 -> 0 | F20: ='Nach Mannschaften sortiert'!F37 -> 0 | G20: ='Nach Mannschaften sortiert'!G37 -> 0 | H20: ='Nach Mannschaften sortiert'!H37 -> 0
A21: ='Nach Mannschaften sortiert'!A38 -> 20 | B21: ='Nach Mannschaften sortiert'!B38 -> 7 | C21: ='Nach Mannschaften sortiert'!C38 -> U16 | D21: ='Nach Mannschaften sortiert'!D38 -> 0 | E21: ='Nach Mannschaften sortiert'!E38 -> 0 | F21: ='Nach Mannschaften sortiert'!F38 -> 0 | G21: ='Nach Mannschaften sortiert'!G38 -> 0 | H21: ='Nach Mannschaften sortiert'!H38 -> 0
A22: ='Nach Mannschaften sortiert'!A39 -> 21 | B22: ='Nach Mannschaften sortiert'!B39 -> 8 | C22: ='Nach Mannschaften sortiert'!C39 -> U16 | D22: ='Nach Mannschaften sortiert'!D39 -> 0 | E22: ='Nach Mannschaften sortiert'!E39 -> 0 | F22: ='Nach Mannschaften sortiert'!F39 -> 0 | G22: ='Nach Mannschaften sortiert'!G39 -> 0 | H22: ='Nach Mannschaften sortiert'!H39 -> 0
A23: ='Nach Mannschaften sortiert'!A40 -> 22 | B23: ='Nach Mannschaften sortiert'!B40 -> 9 | C23: ='Nach Mannschaften sortiert'!C40 -> U16 | D23: ='Nach Mannschaften sortiert'!D40 -> 0 | E23: ='Nach Mannschaften sortiert'!E40 -> 0 | F23: ='Nach Mannschaften sortiert'!F40 -> 0 | G23: ='Nach Mannschaften sortiert'!G40 -> 0 | H23: ='Nach Mannschaften sortiert'!H40 -> 0
A24: ='Nach Mannschaften sortiert'!A74 -> 64 | B24: ='Nach Mannschaften sortiert'!B74 -> 1 | C24: ='Nach Mannschaften sortiert'!C74 -> U11 | D24: ='Nach Mannschaften sortiert'!D74 -> 0 | E24: ='Nach Mannschaften sortiert'!E74 -> 0 | F24: ='Nach Mannschaften sortiert'!F74 -> 0 | G24: ='Nach Mannschaften sortiert'!G74 -> 0 | H24: ='Nach Mannschaften sortiert'!H74 -> 0
A25: ='Nach Mannschaften sortiert'!#REF! -> #REF! | B25: ='Nach Mannschaften sortiert'!#REF! -> #REF! | C25: ='Nach Mannschaften sortiert'!#REF! -> #REF! | D25: ='Nach Mannschaften sortiert'!#REF! -> #REF! | E25: ='Nach Mannschaften sortiert'!#REF! -> #REF! | F25: ='Nach Mannschaften sortiert'!#REF! -> #REF! | G25: ='Nach Mannschaften sortiert'!#REF! -> #REF! | H25: ='Nach Mannschaften sortiert'!#REF! -> #REF!
A26: ='Nach Mannschaften sortiert'!A84 -> 69 | B26: ='Nach Mannschaften sortiert'!B84 -> 1 | C26: ='Nach Mannschaften sortiert'!C84 -> U10 | D26: ='Nach Mannschaften sortiert'!D84 -> 0 | E26: ='Nach Mannschaften sortiert'!E84 -> 0 | F26: ='Nach Mannschaften sortiert'!F84 -> 0 | G26: ='Nach Mannschaften sortiert'!G84 -> 0 | H26: ='Nach Mannschaften sortiert'!H84 -> 0
A27: ='Nach Mannschaften sortiert'!A43 -> 26 | B27: ='Nach Mannschaften sortiert'!B43 -> 3 | C27: ='Nach Mannschaften sortiert'!C43 -> U14 | D27: ='Nach Mannschaften sortiert'!D43 -> 0 | E27: ='Nach Mannschaften sortiert'!E43 -> 0 | F27: ='Nach Mannschaften sortiert'!F43 -> 0 | G27: ='Nach Mannschaften sortiert'!G43 -> 0 | H27: ='Nach Mannschaften sortiert'!H43 -> 0
A28: ='Nach Mannschaften sortiert'!A44 -> 27 | B28: ='Nach Mannschaften sortiert'!B44 -> 4 | C28: ='Nach Mannschaften sortiert'!C44 -> U14 | D28: ='Nach Mannschaften sortiert'!D44 -> 0 | E28: ='Nach Mannschaften sortiert'!E44 -> 0 | F28: ='Nach Mannschaften sortiert'!F44 -> 0 | G28: ='Nach Mannschaften sortiert'!G44 -> 0 | H28: ='Nach Mannschaften sortiert'!H44 -> 0
A29: ='Nach Mannschaften sortiert'!A94 -> 74 | B29: ='Nach Mannschaften sortiert'!B94 -> 1 | C29: ='Nach Mannschaften sortiert'!C94 -> U9 | D29: ='Nach Mannschaften sortiert'!D94 -> 0 | E29: ='Nach Mannschaften sortiert'!E94 -> 0 | F29: ='Nach Mannschaften sortiert'!F94 -> 0 | G29: ='Nach Mannschaften sortiert'!G94 -> 0 | H29: ='Nach Mannschaften sortiert'!H94 -> 0
A30: ='Nach Mannschaften sortiert'!#REF! -> #REF! | B30: ='Nach Mannschaften sortiert'!#REF! -> #REF! | C30: ='Nach Mannschaften sortiert'!#REF! -> #REF! | D30: ='Nach Mannschaften sortiert'!#REF! -> #REF! | E30: ='Nach Mannschaften sortiert'!#REF! -> #REF! | F30: ='Nach Mannschaften sortiert'!#REF! -> #REF! | G30: ='Nach Mannschaften sortiert'!#REF! -> #REF! | H30: ='Nach Mannschaften sortiert'!#REF! -> #REF!
A31: ='Nach Mannschaften sortiert'!A46 -> 30 | B31: ='Nach Mannschaften sortiert'!B46 -> 7 | C31: ='Nach Mannschaften sortiert'!C46 -> U14 | D31: ='Nach Mannschaften sortiert'!D46 -> 0 | E31: ='Nach Mannschaften sortiert'!E46 -> 0 | F31: ='Nach Mannschaften sortiert'!F46 -> 0 | G31: ='Nach Mannschaften sortiert'!G46 -> 0 | H31: ='Nach Mannschaften sortiert'!H46 -> 0
A32: ='Nach Mannschaften sortiert'!A47 -> 31 | B32: ='Nach Mannschaften sortiert'!B47 -> 8 | C32: ='Nach Mannschaften sortiert'!C47 -> U14 | D32: ='Nach Mannschaften sortiert'!D47 -> 0 | E32: ='Nach Mannschaften sortiert'!E47 -> 0 | F32: ='Nach Mannschaften sortiert'!F47 -> 0 | G32: ='Nach Mannschaften sortiert'!G47 -> 0 | H32: ='Nach Mannschaften sortiert'!H47 -> 0
A33: ='Nach Mannschaften sortiert'!A48 -> 32 | B33: ='Nach Mannschaften sortiert'!B48 -> 9 | C33: ='Nach Mannschaften sortiert'!C48 -> U14 | D33: ='Nach Mannschaften sortiert'!D48 -> 0 | E33: ='Nach Mannschaften sortiert'!E48 -> 0 | F33: ='Nach Mannschaften sortiert'!F48 -> 0 | G33: ='Nach Mannschaften sortiert'!G48 -> 0 | H33: ='Nach Mannschaften sortiert'!H48 -> 0
A34: ='Nach Mannschaften sortiert'!A49 -> 33 | B34: ='Nach Mannschaften sortiert'!B49 -> 10 | C34: ='Nach Mannschaften sortiert'!C49 -> U14 | D34: ='Nach Mannschaften sortiert'!D49 -> 0 | E34: ='Nach Mannschaften sortiert'!E49 -> 0 | F34: ='Nach Mannschaften sortiert'!F49 -> 0 | G34: ='Nach Mannschaften sortiert'!G49 -> 0 | H34: ='Nach Mannschaften sortiert'!H49 -> 0
A35: ='Nach Mannschaften sortiert'!A67 -> 55 | B35: ='Nach Mannschaften sortiert'!B67 -> 2 | C35: ='Nach Mannschaften sortiert'!C67 -> U12_2 | D35: ='Nach Mannschaften sortiert'!D67 -> 0 | E35: ='Nach Mannschaften sortiert'!E67 -> 0 | F35: ='Nach Mannschaften sortiert'!F67 -> 0 | G35: ='Nach Mannschaften sortiert'!G67 -> 0 | H35: ='Nach Mannschaften sortiert'!H67 -> 0
A36: ='Nach Mannschaften sortiert'!A51 -> 35 | B36: ='Nach Mannschaften sortiert'!B51 -> 2 | C36: ='Nach Mannschaften sortiert'!C51 -> U13 | D36: ='Nach Mannschaften sortiert'!D51 -> 0 | E36: ='Nach Mannschaften sortiert'!E51 -> 0 | F36: ='Nach Mannschaften sortiert'!F51 -> 0 | G36: ='Nach Mannschaften sortiert'!G51 -> 0 | H36: ='Nach Mannschaften sortiert'!H51 -> 0
A37: ='Nach Mannschaften sortiert'!A52 -> 36 | B37: ='Nach Mannschaften sortiert'!B52 -> 3 | C37: ='Nach Mannschaften sortiert'!C52 -> U13 | D37: ='Nach Mannschaften sortiert'!D52 -> 0 | E37: ='Nach Mannschaften sortiert'!E52 -> 0 | F37: ='Nach Mannschaften sortiert'!F52 -> 0 | G37: ='Nach Mannschaften sortiert'!G52 -> 0 | H37: ='Nach Mannschaften sortiert'!H52 -> 0
A38: ='Nach Mannschaften sortiert'!A42 -> 25 | B38: ='Nach Mannschaften sortiert'!B42 -> 2 | C38: ='Nach Mannschaften sortiert'!C42 -> U14 | D38: ='Nach Mannschaften sortiert'!D42 -> 0 | E38: ='Nach Mannschaften sortiert'!E42 -> 0 | F38: ='Nach Mannschaften sortiert'!F42 -> 0 | G38: ='Nach Mannschaften sortiert'!G42 -> 0 | H38: ='Nach Mannschaften sortiert'!H42 -> 0
A39: ='Nach Mannschaften sortiert'!#REF! -> #REF! | B39: ='Nach Mannschaften sortiert'!#REF! -> #REF! | C39: ='Nach Mannschaften sortiert'!#REF! -> #REF! | D39: ='Nach Mannschaften sortiert'!#REF! -> #REF! | E39: ='Nach Mannschaften sortiert'!#REF! -> #REF! | F39: ='Nach Mannschaften sortiert'!#REF! -> #REF! | G39: ='Nach Mannschaften sortiert'!#REF! -> #REF! | H39: ='Nach Mannschaften sortiert'!#REF! -> #REF!
A40: ='Nach Mannschaften sortiert'!A54 -> 39 | B40: ='Nach Mannschaften sortiert'!B54 -> 6 | C40: ='Nach Mannschaften sortiert'!C54 -> U13 | D40: ='Nach Mannschaften sortiert'!D54 -> 0 | E40: ='Nach Mannschaften sortiert'!E54 -> 0 | F40: ='Nach Mannschaften sortiert'!F54 -> 0 | G40: ='Nach Mannschaften sortiert'!G54 -> 0 | H40: ='Nach Mannschaften sortiert'!H54 -> 0
...

Sheet Tabelle1
A1: U11 | B1: 25 - 26.04 | C1: freihalten
A2: U9 | B2: 04.06. - 08.06. | C2: kein Turnier

Sheet Stefans Liste 2026
A1: Mannschaft | B1: fixierter Termin | C1: Uhrzeit | D1: Ort | E1: Gegner | F1: Spielfeld | G1: Spielfeldgröße | H1: Tore | I1: Ball | J1: Trainer/Ansprechpartner | K1: Tel
A2: U8 | B2: 46091 | C2: 0.6875 | D2: Neufeld | E2: Freundschaftsspiel Großhöflein | F2: U8 | G2: =IF(F2="Großfeld","Großfeld",IF(F2="U16","Großfeld",IF(F2="U15","Großfeld",IF(F2="U14","Großfeld",IF(F2="U13","75x55",IF(F2="U11/U12","55x40",IF(F2="U9/U10","40x25",IF(F2="U8","29x22","25x20")))))))) -> 29x22 | H2: =IF(F2="Großfeld","7,32x2,44",IF(F2="U16","7,32x2,44",IF(F2="U15","7,32x2,44",IF(F2="U14","7,32x2,44",IF(F2="U13","5x2",IF(F2="U11/U12","5x2",IF(F2="U9/U10","5x2","4 Minitore"))))))) -> 4 Minitore | I2: =IF(F2="Großfeld","5",IF(F2="U16","5",IF(F2="U15","5",IF(F2="U14","4",IF(F2="U13","4",IF(F2="U11/U12","4",IF(F2="U9/U10","4",IF(F2="U9","4","3")))))))) -> 3 | J2: =IF(A2="KM Neufeld","Pleninger Stefan",IF(A2="U16 LL","Josch Kögl",IF(A2="U15 LL Nord","Serdar Ekinci",IF(A2="U14 Nord","Gernot Servelda",IF(A2="U13 Nord","Thomas Pöschl & Lenz Honc",IF(A2="U11 Nord D","Mario Magler&Ronny Archam",IF(A2="U9","Thomas Brandl&Daniel Hofbauer",IF(A2="U8","Berger Tobias&Sebastian Putric",IF(A2="U7","Türkes Ömer&Mahsumi Taha",IF(A2="Camp","Berger Dieter",IF(A2="Turnier","Berger Dieter","FEHLER"))))))))))) -> Berger Tobias&Sebastian Putric | K2: =IF(A2="KM Neufeld","+43 664 415 99 09",IF(A2="U16 LL","+43 650 262 82 63",IF(A2="U15 LL Nord","+43 650 701 02 44",IF(A2="U14 Nord","+43 676 401 09 13",IF(A2="U13 Nord","+43 677 613 55 114 & +43 664 114 43 52",IF(A2="U11 Nord D","+43 664 762 09 93 & +43 699 111 93 828",IF(A2="U9","+43 676 377 16 30 & +43 399 197 871 81",IF(A2="U8","+43 660 199 13 52 & +43 660 914 92 36",IF(A2="U7","+43 676 661 62 26 & +43 681 208 115 99",IF(A2="Camp","+43 660 77 39 500",IF(A2="Turnier","+43 660 77 39 500","FEHLER"))))))))))) -> +43 660 199 13 52 & +43 660 914 92 36
A3: =Heimspiele!C4 -> KM | B3: =Heimspiele!D4 -> 0 | D3: =Heimspiele!F4 -> 0 | E3: =Heimspiele!G4 -> 0 | F3: Großfeld | G3: =IF(F3="Großfeld","Großfeld",IF(F3="U16","Großfeld",IF(F3="U15","Großfeld",IF(F3="U14","Großfeld",IF(F3="U13","75x55",IF(F3="U11/U12","55x40",IF(F3="U9/U10","40x25",IF(F3="U8","29x22","25x20")))))))) -> Großfeld | H3: =IF(F3="Großfeld","7,32x2,44",IF(F3="U16","7,32x2,44",IF(F3="U15","7,32x2,44",IF(F3="U14","7,32x2,44",IF(F3="U13","5x2",IF(F3="U11/U12","5x2",IF(F3="U9/U10","5x2","4 Minitore"))))))) -> 7,32x2,44 | I3: =IF(F3="Großfeld","5",IF(F3="U16","5",IF(F3="U15","5",IF(F3="U14","4",IF(F3="U13","4",IF(F3="U11/U12","4",IF(F3="U9/U10","4",IF(F3="U9","4","3")))))))) -> 5 | J3: =IF(A3="KM Neufeld","Pleninger Stefan",IF(A3="U16 LL","Josch Kögl",IF(A3="U15 LL Nord","Serdar Ekinci",IF(A3="U14 Nord","Gernot Servelda",IF(A3="U13 - Nord","Thomas Pöschl & Lenz Honc",IF(A3="U11 Nord D","Mario Magler&Ronny Archam",IF(A3="U9","Thomas Brandl&Daniel Hofbauer",IF(A3="U8","Berger Tobias&Sebastian Putric",IF(A3="U7","Türkes Ömer&Mahsumi Taha",IF(A3="Camp","Berger Dieter",IF(A3="Turnier","Berger Dieter","FEHLER"))))))))))) -> FEHLER | K3: =IF(A3="KM Neufeld","+43 664 415 99 09",IF(A3="U16 LL","+43 650 262 82 63",IF(A3="U15 LL Nord","+43 650 701 02 44",IF(A3="U14 - Nord","+43 676 401 09 13",IF(A3="U13 - Nord","+43 677 613 55 114 & +43 664 114 43 52",IF(A3="U11 Nord D","+43 664 762 09 93 & +43 699 111 93 828",IF(A3="U9","+43 676 377 16 30 & +43 399 197 871 81",IF(A3="U8","+43 660 199 13 52 & +43 660 914 92 36",IF(A3="U7","+43 676 661 62 26 & +43 681 208 115 99",IF(A3="Camp","+43 660 77 39 500",IF(A3="Turnier","+43 660 77 39 500","FEHLER"))))))))))) -> FEHLER
A4: U16 LL | B4: 46095 | C4: 0.54166667 | D4: Neufeld | E4: Freundschaftspiel Felixdorf | F4: U16 | G4: =IF(F4="Großfeld","Großfeld",IF(F4="U16","Großfeld",IF(F4="U15","Großfeld",IF(F4="U14","Großfeld",IF(F4="U13","75x55",IF(F4="U11/U12","55x40",IF(F4="U9/U10","40x25",IF(F4="U8","29x22","25x20")))))))) -> Großfeld | H4: =IF(F4="Großfeld","7,32x2,44",IF(F4="U16","7,32x2,44",IF(F4="U15","7,32x2,44",IF(F4="U14","7,32x2,44",IF(F4="U13","5x2",IF(F4="U11/U12","5x2",IF(F4="U9/U10","5x2",IF(F3="Turnier","5x2","4 Minitore")))))))) -> 7,32x2,44 | I4: =IF(F4="Großfeld","5",IF(F4="U16","5",IF(F4="U15","5",IF(F4="U14","4",IF(F4="U13","4",IF(F4="U11/U12","4",IF(F4="U9/U10","4",IF(F4="U9","4","3")))))))) -> 5 | J4: =IF(A4="KM Neufeld","Pleninger Stefan",IF(A4="U16 LL","Josch Kögl",IF(A4="U15 LL Nord","Serdar Ekinci",IF(A4="U14 Nord","Gernot Servelda",IF(A4="U13 Nord","Thomas Pöschl & Lenz Honc",IF(A4="U11 Nord D","Mario Magler&Ronny Archam",IF(A4="U9","Thomas Brandl&Daniel Hofbauer",IF(A4="U8","Berger Tobias&Sebastian Putric",IF(A4="U7","Türkes Ömer&Mahsumi Taha",IF(A4="Camp","Berger Dieter",IF(A4="Turnier","Berger Dieter","FEHLER"))))))))))) -> Josch Kögl | K4: =IF(A4="KM Neufeld","+43 664 415 99 09",IF(A4="U16 LL","+43 650 262 82 63",IF(A4="U15 LL Nord","+43 650 701 02 44",IF(A4="U14 Nord","+43 676 401 09 13",IF(A4="U13 Nord","+43 677 613 55 114 & +43 664 114 43 52",IF(A4="U11 Nord D","+43 664 762 09 93 & +43 699 111 93 828",IF(A4="U9","+43 676 377 16 30 & +43 399 197 871 81",IF(A4="U8","+43 660 199 13 52 & +43 660 914 92 36",IF(A4="U7","+43 676 661 62 26 & +43 681 208 115 99",IF(A4="Camp","+43 660 77 39 500",IF(A4="Turnier","+43 660 77 39 500","FEHLER"))))))))))) -> +43 650 262 82 63
A5: =Heimspiele!C6 -> KM | B5: =Heimspiele!D6 -> 0 | D5: =Heimspiele!F6 -> 0 | E5: =Heimspiele!G6 -> 0 | F5: Großfeld | G5: =IF(F5="Großfeld","Großfeld",IF(F5="U16","Großfeld",IF(F5="U15","Großfeld",IF(F5="U14","Großfeld",IF(F5="U13","75x55",IF(F5="U11/U12","55x40",IF(F5="U9/U10","40x25",IF(F5="U8","29x22","25x20")))))))) -> Großfeld | H5: =IF(F5="Großfeld","7,32x2,44",IF(F5="U16","7,32x2,44",IF(F5="U15","7,32x2,44",IF(F5="U14","7,32x2,44",IF(F5="U13","5x2",IF(F5="U11/U12","5x2",IF(F5="U9/U10","5x2","4 Minitore"))))))) -> 7,32x2,44 | I5: =IF(F5="Großfeld","5",IF(F5="U16","5",IF(F5="U15","5",IF(F5="U14","4",IF(F5="U13","4",IF(F5="U11/U12","4",IF(F5="U9/U10","4",IF(F5="U9","4","3")))))))) -> 5 | J5: =IF(A5="KM Neufeld","Pleninger Stefan",IF(A5="U16 LL","Josch Kögl",IF(A5="U15 LL Nord","Serdar Ekinci",IF(A5="U14 Nord","Gernot Servelda",IF(A5="U13 - Nord","Thomas Pöschl & Lenz Honc",IF(A5="U11 Nord D","Mario Magler&Ronny Archam",IF(A5="U9","Thomas Brandl&Daniel Hofbauer",IF(A5="U8","Berger Tobias&Sebastian Putric",IF(A5="U7","Türkes Ömer&Mahsumi Taha",IF(A5="Camp","Berger Dieter",IF(A5="Turnier","Berger Dieter","FEHLER"))))))))))) -> FEHLER | K5: =IF(A5="KM Neufeld","+43 664 415 99 09",IF(A5="U16 LL","+43 650 262 82 63",IF(A5="U15 LL Nord","+43 650 701 02 44",IF(A5="U14 - Nord","+43 676 401 09 13",IF(A5="U13 - Nord","+43 677 613 55 114 & +43 664 114 43 52",IF(A5="U11 Nord D","+43 664 762 09 93 & +43 699 111 93 828",IF(A5="U9","+43 676 377 16 30 & +43 399 197 871 81",IF(A5="U8","+43 660 199 13 52 & +43 660 914 92 36",IF(A5="U7","+43 676 661 62 26 & +43 681 208 115 99",IF(A5="Camp","+43 660 77 39 500",IF(A5="Turnier","+43 660 77 39 500","FEHLER"))))))))))) -> FEHLER
A6: U15 LL Nord | B6: 46096 | C6: 0.45833333 | D6: Neufeld | E6: Freundschaftsspiel Baden | F6: U15 | G6: =IF(F6="Großfeld","Großfeld",IF(F6="U16","Großfeld",IF(F6="U15","Großfeld",IF(F6="U14","Großfeld",IF(F6="U13","75x55",IF(F6="U11/U12","55x40",IF(F6="U9/U10","40x25",IF(F6="U8","29x22","25x20")))))))) -> Großfeld | H6: =IF(F6="Großfeld","7,32x2,44",IF(F6="U16","7,32x2,44",IF(F6="U15","7,32x2,44",IF(F6="U14","7,32x2,44",IF(F6="U13","5x2",IF(F6="U11/U12","5x2",IF(F6="U9/U10","5x2",IF(F5="Turnier","5x2","4 Minitore")))))))) -> 7,32x2,44 | I6: =IF(F6="Großfeld","5",IF(F6="U16","5",IF(F6="U15","5",IF(F6="U14","4",IF(F6="U13","4",IF(F6="U11/U12","4",IF(F6="U9/U10","4",IF(F6="U9","4","3")))))))) -> 5 | J6: =IF(A6="KM Neufeld","Pleninger Stefan",IF(A6="U16 LL","Josch Kögl",IF(A6="U15 LL Nord","Serdar Ekinci",IF(A6="U14 Nord","Gernot Servelda",IF(A6="U13 Nord","Thomas Pöschl & Lenz Honc",IF(A6="U11 Nord D","Mario Magler&Ronny Archam",IF(A6="U9","Thomas Brandl&Daniel Hofbauer",IF(A6="U8","Berger Tobias&Sebastian Putric",IF(A6="U7","Türkes Ömer&Mahsumi Taha",IF(A6="Camp","Berger Dieter",IF(A6="Turnier","Berger Dieter","FEHLER"))))))))))) -> Serdar Ekinci | K6: =IF(A6="KM Neufeld","+43 664 415 99 09",IF(A6="U16 LL","+43 650 262 82 63",IF(A6="U15 LL Nord","+43 650 701 02 44",IF(A6="U14 Nord","+43 676 401 09 13",IF(A6="U13 Nord","+43 677 613 55 114 & +43 664 114 43 52",IF(A6="U11 Nord D","+43 664 762 09 93 & +43 699 111 93 828",IF(A6="U9","+43 676 377 16 30 & +43 399 197 871 81",IF(A6="U8","+43 660 199 13 52 & +43 660 914 92 36",IF(A6="U7","+43 676 661 62 26 & +43 681 208 115 99",IF(A6="Camp","+43 660 77 39 500",IF(A6="Turnier","+43 660 77 39 500","FEHLER"))))))))))) -> +43 650 701 02 44
A7: =Heimspiele!C8 -> KM | B7: =Heimspiele!D8 -> 0 | D7: =Heimspiele!F8 -> 0 | E7: =Heimspiele!G8 -> 0 | F7: Großfeld | G7: =IF(F7="Großfeld","Großfeld",IF(F7="U16","Großfeld",IF(F7="U15","Großfeld",IF(F7="U14","Großfeld",IF(F7="U13","75x55",IF(F7="U11/U12","55x40",IF(F7="U9/U10","40x25",IF(F7="U8","29x22","25x20")))))))) -> Großfeld | H7: =IF(F7="Großfeld","7,32x2,44",IF(F7="U16","7,32x2,44",IF(F7="U15","7,32x2,44",IF(F7="U14","7,32x2,44",IF(F7="U13","5x2",IF(F7="U11/U12","5x2",IF(F7="U9/U10","5x2","4 Minitore"))))))) -> 7,32x2,44 | I7: =IF(F7="Großfeld","5",IF(F7="U16","5",IF(F7="U15","5",IF(F7="U14","4",IF(F7="U13","4",IF(F7="U11/U12","4",IF(F7="U9/U10","4",IF(F7="U9","4","3")))))))) -> 5 | J7: =IF(A7="KM Neufeld","Pleninger Stefan",IF(A7="U16 LL","Josch Kögl",IF(A7="U15 LL Nord","Serdar Ekinci",IF(A7="U14 Nord","Gernot Servelda",IF(A7="U13 - Nord","Thomas Pöschl & Lenz Honc",IF(A7="U11 Nord D","Mario Magler&Ronny Archam",IF(A7="U9","Thomas Brandl&Daniel Hofbauer",IF(A7="U8","Berger Tobias&Sebastian Putric",IF(A7="U7","Türkes Ömer&Mahsumi Taha",IF(A7="Camp","Berger Dieter",IF(A7="Turnier","Berger Dieter","FEHLER"))))))))))) -> FEHLER | K7: =IF(A7="KM Neufeld","+43 664 415 99 09",IF(A7="U16 LL","+43 650 262 82 63",IF(A7="U15 LL Nord","+43 650 701 02 44",IF(A7="U14 - Nord","+43 676 401 09 13",IF(A7="U13 - Nord","+43 677 613 55 114 & +43 664 114 43 52",IF(A7="U11 Nord D","+43 664 762 09 93 & +43 699 111 93 828",IF(A7="U9","+43 676 377 16 30 & +43 399 197 871 81",IF(A7="U8","+43 660 199 13 52 & +43 660 914 92 36",IF(A7="U7","+43 676 661 62 26 & +43 681 208 115 99",IF(A7="Camp","+43 660 77 39 500",IF(A7="Turnier","+43 660 77 39 500","FEHLER"))))))))))) -> FEHLER
A8: U11 Nord D | B8: 46102 | C8: 0.5 | D8: Neufeld | E8: Freundschaftspiel Pöttsching | F8: U11/U12 | G8: =IF(F8="Großfeld","Großfeld",IF(F8="U16","Großfeld",IF(F8="U15","Großfeld",IF(F8="U14","Großfeld",IF(F8="U13","75x55",IF(F8="U11/U12","55x40",IF(F8="U9/U10","40x25",IF(F8="U8","29x22","25x20")))))))) -> 55x40 | H8: =IF(F8="Großfeld","7,32x2,44",IF(F8="U16","7,32x2,44",IF(F8="U15","7,32x2,44",IF(F8="U14","7,32x2,44",IF(F8="U13","5x2",IF(F8="U11/U12","5x2",IF(F8="U9/U10","5x2",IF(F7="Turnier","5x2","4 Minitore")))))))) -> 5x2 | I8: =IF(F8="Großfeld","5",IF(F8="U16","5",IF(F8="U15","5",IF(F8="U14","4",IF(F8="U13","4",IF(F8="U11/U12","4",IF(F8="U9/U10","4",IF(F8="U9","4","3")))))))) -> 4 | J8: =IF(A8="KM Neufeld","Pleninger Stefan",IF(A8="U16 LL","Josch Kögl",IF(A8="U15 LL Nord","Serdar Ekinci",IF(A8="U14 Nord","Gernot Servelda",IF(A8="U13 Nord","Thomas Pöschl & Lenz Honc",IF(A8="U11 Nord D","Mario Magler&Ronny Archam",IF(A8="U9","Thomas Brandl&Daniel Hofbauer",IF(A8="U8","Berger Tobias&Sebastian Putric",IF(A8="U7","Türkes Ömer&Mahsumi Taha",IF(A8="Camp","Berger Dieter",IF(A8="Turnier","Berger Dieter","FEHLER"))))))))))) -> Mario Magler&Ronny Archam | K8: =IF(A8="KM Neufeld","+43 664 415 99 09",IF(A8="U16 LL","+43 650 262 82 63",IF(A8="U15 LL Nord","+43 650 701 02 44",IF(A8="U14 Nord","+43 676 401 09 13",IF(A8="U13 Nord","+43 677 613 55 114 & +43 664 114 43 52",IF(A8="U11 Nord D","+43 664 762 09 93 & +43 699 111 93 828",IF(A8="U9","+43 676 377 16 30 & +43 399 197 871 81",IF(A8="U8","+43 660 199 13 52 & +43 660 914 92 36",IF(A8="U7","+43 676 661 62 26 & +43 681 208 115 99",IF(A8="Camp","+43 660 77 39 500",IF(A8="Turnier","+43 660 77 39 500","FEHLER"))))))))))) -> +43 664 762 09 93 & +43 699 111 93 828
A9: =Heimspiele!C10 -> KM | B9: =Heimspiele!D10 -> 0 | D9: =Heimspiele!F10 -> 0 | E9: =Heimspiele!G10 -> 0 | F9: Großfeld | G9: =IF(F9="Großfeld","Großfeld",IF(F9="U16","Großfeld",IF(F9="U15","Großfeld",IF(F9="U14","Großfeld",IF(F9="U13","75x55",IF(F9="U11/U12","55x40",IF(F9="U9/U10","40x25",IF(F9="U8","29x22","25x20")))))))) -> Großfeld | H9: =IF(F9="Großfeld","7,32x2,44",IF(F9="U16","7,32x2,44",IF(F9="U15","7,32x2,44",IF(F9="U14","7,32x2,44",IF(F9="U13","5x2",IF(F9="U11/U12","5x2",IF(F9="U9/U10","5x2","4 Minitore"))))))) -> 7,32x2,44 | I9: =IF(F9="Großfeld","5",IF(F9="U16","5",IF(F9="U15","5",IF(F9="U14","4",IF(F9="U13","4",IF(F9="U11/U12","4",IF(F9="U9/U10","4",IF(F9="U9","4","3")))))))) -> 5 | J9: =IF(A9="KM Neufeld","Pleninger Stefan",IF(A9="U16 LL","Josch Kögl",IF(A9="U15 LL Nord","Serdar Ekinci",IF(A9="U14 Nord","Gernot Servelda",IF(A9="U13 - Nord","Thomas Pöschl & Lenz Honc",IF(A9="U11 Nord D","Mario Magler&Ronny Archam",IF(A9="U9","Thomas Brandl&Daniel Hofbauer",IF(A9="U8","Berger Tobias&Sebastian Putric",IF(A9="U7","Türkes Ömer&Mahsumi Taha",IF(A9="Camp","Berger Dieter",IF(A9="Turnier","Berger Dieter","FEHLER"))))))))))) -> FEHLER | K9: =IF(A9="KM Neufeld","+43 664 415 99 09",IF(A9="U16 LL","+43 650 262 82 63",IF(A9="U15 LL Nord","+43 650 701 02 44",IF(A9="U14 - Nord","+43 676 401 09 13",IF(A9="U13 - Nord","+43 677 613 55 114 & +43 664 114 43 52",IF(A9="U11 Nord D","+43 664 762 09 93 & +43 699 111 93 828",IF(A9="U9","+43 676 377 16 30 & +43 399 197 871 81",IF(A9="U8","+43 660 199 13 52 & +43 660 914 92 36",IF(A9="U7","+43 676 661 62 26 & +43 681 208 115 99",IF(A9="Camp","+43 660 77 39 500",IF(A9="Turnier","+43 660 77 39 500","FEHLER"))))))))))) -> FEHLER
A10: =Heimspiele!C3 -> KM | B10: =Heimspiele!D3 -> 0 | C10: =Heimspiele!E3 -> 0 | D10: =Heimspiele!F3 -> 0 | E10: =Heimspiele!G3 -> 0 | F10: Großfeld | G10: =IF(F10="Großfeld","Großfeld",IF(F10="U16","Großfeld",IF(F10="U15","Großfeld",IF(F10="U14","Großfeld",IF(F10="U13","75x55",IF(F10="U11/U12","55x40",IF(F10="U9/U10","40x25",IF(F10="U8","29x22","25x20")))))))) -> Großfeld | H10: =IF(F10="Großfeld","7,32x2,44",IF(F10="U16","7,32x2,44",IF(F10="U15","7,32x2,44",IF(F10="U14","7,32x2,44",IF(F10="U13","5x2",IF(F10="U11/U12","5x2",IF(F10="U9/U10","5x2","4 Minitore"))))))) -> 7,32x2,44 | I10: =IF(F10="Großfeld","5",IF(F10="U16","5",IF(F10="U15","5",IF(F10="U14","4",IF(F10="U13","4",IF(F10="U11/U12","4",IF(F10="U9/U10","4",IF(F10="U9","4","3")))))))) -> 5 | J10: =IF(A10="KM Neufeld","Pleninger Stefan",IF(A10="U16 LL","Josch Kögl",IF(A10="U15 LL Nord","Serdar Ekinci",IF(A10="U14 Nord","Gernot Servelda",IF(A10="U13 Nord","Thomas Pöschl & Lenz Honc",IF(A10="U11 Nord D","Mario Magler&Ronny Archam",IF(A10="U9","Thomas Brandl&Daniel Hofbauer",IF(A10="U8","Berger Tobias&Sebastian Putric",IF(A10="U7","Türkes Ömer&Mahsumi Taha",IF(A10="Camp","Berger Dieter",IF(A10="Turnier","Berger Dieter","FEHLER"))))))))))) -> FEHLER | K10: =IF(A10="KM Neufeld","+43 664 415 99 09",IF(A10="U16 LL","+43 650 262 82 63",IF(A10="U15 LL Nord","+43 650 701 02 44",IF(A10="U14 Nord","+43 676 401 09 13",IF(A10="U13 Nord","+43 677 613 55 114 & +43 664 114 43 52",IF(A10="U11 Nord D","+43 664 762 09 93 & +43 699 111 93 828",IF(A10="U9","+43 676 377 16 30 & +43 399 197 871 81",IF(A10="U8","+43 660 199 13 52 & +43 660 914 92 36",IF(A10="U7","+43 676 661 62 26 & +43 681 208 115 99",IF(A10="Camp","+43 660 77 39 500",IF(A10="Turnier","+43 660 77 39 500","FEHLER"))))))))))) -> FEHLER
A11: =Heimspiele!C12 -> KM | B11: =Heimspiele!D12 -> 0 | D11: =Heimspiele!F12 -> 0 | E11: =Heimspiele!G12 -> 0 | F11: Großfeld | G11: =IF(F11="Großfeld","Großfeld",IF(F11="U16","Großfeld",IF(F11="U15","Großfeld",IF(F11="U14","Großfeld",IF(F11="U13","75x55",IF(F11="U11/U12","55x40",IF(F11="U9/U10","40x25",IF(F11="U8","29x22","25x20")))))))) -> Großfeld | H11: =IF(F11="Großfeld","7,32x2,44",IF(F11="U16","7,32x2,44",IF(F11="U15","7,32x2,44",IF(F11="U14","7,32x2,44",IF(F11="U13","5x2",IF(F11="U11/U12","5x2",IF(F11="U9/U10","5x2","4 Minitore"))))))) -> 7,32x2,44 | I11: =IF(F11="Großfeld","5",IF(F11="U16","5",IF(F11="U15","5",IF(F11="U14","4",IF(F11="U13","4",IF(F11="U11/U12","4",IF(F11="U9/U10","4",IF(F11="U9","4","3")))))))) -> 5 | J11: =IF(A11="KM Neufeld","Pleninger Stefan",IF(A11="U16 LL","Josch Kögl",IF(A11="U15 LL Nord","Serdar Ekinci",IF(A11="U14 Nord","Gernot Servelda",IF(A11="U13 - Nord","Thomas Pöschl & Lenz Honc",IF(A11="U11 Nord D","Mario Magler&Ronny Archam",IF(A11="U9","Thomas Brandl&Daniel Hofbauer",IF(A11="U8","Berger Tobias&Sebastian Putric",IF(A11="U7","Türkes Ömer&Mahsumi Taha",IF(A11="Camp","Berger Dieter",IF(A11="Turnier","Berger Dieter","FEHLER"))))))))))) -> FEHLER | K11: =IF(A11="KM Neufeld","+43 664 415 99 09",IF(A11="U16 LL","+43 650 262 82 63",IF(A11="U15 LL Nord","+43 650 701 02 44",IF(A11="U14 - Nord","+43 676 401 09 13",IF(A11="U13 - Nord","+43 677 613 55 114 & +43 664 114 43 52",IF(A11="U11 Nord D","+43 664 762 09 93 & +43 699 111 93 828",IF(A11="U9","+43 676 377 16 30 & +43 399 197 871 81",IF(A11="U8","+43 660 199 13 52 & +43 660 914 92 36",IF(A11="U7","+43 676 661 62 26 & +43 681 208 115 99",IF(A11="Camp","+43 660 77 39 500",IF(A11="Turnier","+43 660 77 39 500","FEHLER"))))))))))) -> FEHLER
A12: =Heimspiele!C13 -> KM | B12: =Heimspiele!D13 -> 0 | D12: =Heimspiele!F13 -> 0 | E12: =Heimspiele!G13 -> 0 | F12: Großfeld | G12: =IF(F12="Großfeld","Großfeld",IF(F12="U16","Großfeld",IF(F12="U15","Großfeld",IF(F12="U14","Großfeld",IF(F12="U13","75x55",IF(F12="U11/U12","55x40",IF(F12="U9/U10","40x25",IF(F12="U8","29x22","25x20")))))))) -> Großfeld | H12: =IF(F12="Großfeld","7,32x2,44",IF(F12="U16","7,32x2,44",IF(F12="U15","7,32x2,44",IF(F12="U14","7,32x2,44",IF(F12="U13","5x2",IF(F12="U11/U12","5x2",IF(F12="U9/U10","5x2","4 Minitore"))))))) -> 7,32x2,44 | I12: =IF(F12="Großfeld","5",IF(F12="U16","5",IF(F12="U15","5",IF(F12="U14","4",IF(F12="U13","4",IF(F12="U11/U12","4",IF(F12="U9/U10","4",IF(F12="U9","4","3")))))))) -> 5 | J12: =IF(A12="KM Neufeld","Pleninger Stefan",IF(A12="U16 LL","Josch Kögl",IF(A12="U15 LL Nord","Serdar Ekinci",IF(A12="U14 Nord","Gernot Servelda",IF(A12="U13 - Nord","Thomas Pöschl & Lenz Honc",IF(A12="U11 Nord D","Mario Magler&Ronny Archam",IF(A12="U9","Thomas Brandl&Daniel Hofbauer",IF(A12="U8","Berger Tobias&Sebastian Putric",IF(A12="U7","Türkes Ömer&Mahsumi Taha",IF(A12="Camp","Berger Dieter",IF(A12="Turnier","Berger Dieter","FEHLER"))))))))))) -> FEHLER | K12: =IF(A12="KM Neufeld","+43 664 415 99 09",IF(A12="U16 LL","+43 650 262 82 63",IF(A12="U15 LL Nord","+43 650 701 02 44",IF(A12="U14 - Nord","+43 676 401 09 13",IF(A12="U13 - Nord","+43 677 613 55 114 & +43 664 114 43 52",IF(A12="U11 Nord D","+43 664 762 09 93 & +43 699 111 93 828",IF(A12="U9","+43 676 377 16 30 & +43 399 197 871 81",IF(A12="U8","+43 660 199 13 52 & +43 660 914 92 36",IF(A12="U7","+43 676 661 62 26 & +43 681 208 115 99",IF(A12="Camp","+43 660 77 39 500",IF(A12="Turnier","+43 660 77 39 500","FEHLER"))))))))))) -> FEHLER
A13: =Heimspiele!C5 -> U13 | B13: =Heimspiele!D5 -> 0 | C13: =Heimspiele!E5 -> 0 | D13: =Heimspiele!F5 -> 0 | E13: =Heimspiele!G5 -> 0 | F13: U14 | G13: =IF(F13="Großfeld","Großfeld",IF(F13="U16","Großfeld",IF(F13="U15","Großfeld",IF(F13="U14","Großfeld",IF(F13="U13","75x55",IF(F13="U11/U12","55x40",IF(F13="U9/U10","40x25",IF(F13="U8","29x22","25x20")))))))) -> Großfeld | H13: =IF(F13="Großfeld","7,32x2,44",IF(F13="U16","7,32x2,44",IF(F13="U15","7,32x2,44",IF(F13="U14","7,32x2,44",IF(F13="U13","5x2",IF(F13="U11/U12","5x2",IF(F13="U9/U10","5x2","4 Minitore"))))))) -> 7,32x2,44 | I13: =IF(F13="Großfeld","5",IF(F13="U16","5",IF(F13="U15","5",IF(F13="U14","4",IF(F13="U13","4",IF(F13="U11/U12","4",IF(F13="U9/U10","4",IF(F13="U9","4","3")))))))) -> 4 | J13: =IF(A13="KM Neufeld","Pleninger Stefan",IF(A13="U16 LL","Josch Kögl",IF(A13="U15 LL Nord","Serdar Ekinci",IF(A13="U14 Nord","Gernot Servelda",IF(A13="U13 Nord","Thomas Pöschl & Lenz Honc",IF(A13="U11 Nord D","Mario Magler&Ronny Archam",IF(A13="U9","Thomas Brandl&Daniel Hofbauer",IF(A13="U8","Berger Tobias&Sebastian Putric",IF(A13="U7","Türkes Ömer&Mahsumi Taha",IF(A13="Camp","Berger Dieter",IF(A13="Turnier","Berger Dieter","FEHLER"))))))))))) -> FEHLER | K13: =IF(A13="KM Neufeld","+43 664 415 99 09",IF(A13="U16 LL","+43 650 262 82 63",IF(A13="U15 LL Nord","+43 650 701 02 44",IF(A13="U14 Nord","+43 676 401 09 13",IF(A13="U13 Nord","+43 677 613 55 114 & +43 664 114 43 52",IF(A13="U11 Nord D","+43 664 762 09 93 & +43 699 111 93 828",IF(A13="U9","+43 676 377 16 30 & +43 399 197 871 81",IF(A13="U8","+43 660 199 13 52 & +43 660 914 92 36",IF(A13="U7","+43 676 661 62 26 & +43 681 208 115 99",IF(A13="Camp","+43 660 77 39 500",IF(A13="Turnier","+43 660 77 39 500","FEHLER"))))))))))) -> FEHLER
A14: =Heimspiele!C15 -> U16 | B14: =Heimspiele!D15 -> 0 | D14: =Heimspiele!F15 -> 0 | E14: =Heimspiele!G15 -> 0 | F14: Großfeld | G14: =IF(F14="Großfeld","Großfeld",IF(F14="U16","Großfeld",IF(F14="U15","Großfeld",IF(F14="U14","Großfeld",IF(F14="U13","75x55",IF(F14="U11/U12","55x40",IF(F14="U9/U10","40x25",IF(F14="U8","29x22","25x20")))))))) -> Großfeld | H14: =IF(F14="Großfeld","7,32x2,44",IF(F14="U16","7,32x2,44",IF(F14="U15","7,32x2,44",IF(F14="U14","7,32x2,44",IF(F14="U13","5x2",IF(F14="U11/U12","5x2",IF(F14="U9/U10","5x2","4 Minitore"))))))) -> 7,32x2,44 | I14: =IF(F14="Großfeld","5",IF(F14="U16","5",IF(F14="U15","5",IF(F14="U14","4",IF(F14="U13","4",IF(F14="U11/U12","4",IF(F14="U9/U10","4",IF(F14="U9","4","3")))))))) -> 5 | J14: =IF(A14="KM Neufeld","Pleninger Stefan",IF(A14="U16 LL","Josch Kögl",IF(A14="U15 LL Nord","Serdar Ekinci",IF(A14="U14 Nord","Gernot Servelda",IF(A14="U13 - Nord","Thomas Pöschl & Lenz Honc",IF(A14="U11 Nord D","Mario Magler&Ronny Archam",IF(A14="U9","Thomas Brandl&Daniel Hofbauer",IF(A14="U8","Berger Tobias&Sebastian Putric",IF(A14="U7","Türkes Ömer&Mahsumi Taha",IF(A14="Camp","Berger Dieter",IF(A14="Turnier","Berger Dieter","FEHLER"))))))))))) -> FEHLER | K14: =IF(A14="KM Neufeld","+43 664 415 99 09",IF(A14="U16 LL","+43 650 262 82 63",IF(A14="U15 LL Nord","+43 650 701 02 44",IF(A14="U14 - Nord","+43 676 401 09 13",IF(A14="U13 - Nord","+43 677 613 55 114 & +43 664 114 43 52",IF(A14="U11 Nord D","+43 664 762 09 93 & +43 699 111 93 828",IF(A14="U9","+43 676 377 16 30 & +43 399 197 871 81",IF(A14="U8","+43 660 199 13 52 & +43 660 914 92 36",IF(A14="U7","+43 676 661 62 26 & +43 681 208 115 99",IF(A14="Camp","+43 660 77 39 500",IF(A14="Turnier","+43 660 77 39 500","FEHLER"))))))))))) -> FEHLER
A15: =Heimspiele!C16 -> U16 | B15: =Heimspiele!D16 -> 0 | D15: =Heimspiele!F16 -> 0 | E15: =Heimspiele!G16 -> 0 | F15: Großfeld | G15: =IF(F15="Großfeld","Großfeld",IF(F15="U16","Großfeld",IF(F15="U15","Großfeld",IF(F15="U14","Großfeld",IF(F15="U13","75x55",IF(F15="U11/U12","55x40",IF(F15="U9/U10","40x25",IF(F15="U8","29x22","25x20")))))))) -> Großfeld | H15: =IF(F15="Großfeld","7,32x2,44",IF(F15="U16","7,32x2,44",IF(F15="U15","7,32x2,44",IF(F15="U14","7,32x2,44",IF(F15="U13","5x2",IF(F15="U11/U12","5x2",IF(F15="U9/U10","5x2","4 Minitore"))))))) -> 7,32x2,44 | I15: =IF(F15="Großfeld","5",IF(F15="U16","5",IF(F15="U15","5",IF(F15="U14","4",IF(F15="U13","4",IF(F15="U11/U12","4",IF(F15="U9/U10","4",IF(F15="U9","4","3")))))))) -> 5 | J15: =IF(A15="KM Neufeld","Pleninger Stefan",IF(A15="U16 LL","Josch Kögl",IF(A15="U15 LL Nord","Serdar Ekinci",IF(A15="U14 Nord","Gernot Servelda",IF(A15="U13 - Nord","Thomas Pöschl & Lenz Honc",IF(A15="U11 Nord D","Mario Magler&Ronny Archam",IF(A15="U9","Thomas Brandl&Daniel Hofbauer",IF(A15="U8","Berger Tobias&Sebastian Putric",IF(A15="U7","Türkes Ömer&Mahsumi Taha",IF(A15="Camp","Berger Dieter",IF(A15="Turnier","Berger Dieter","FEHLER"))))))))))) -> FEHLER | K15: =IF(A15="KM Neufeld","+43 664 415 99 09",IF(A15="U16 LL","+43 650 262 82 63",IF(A15="U15 LL Nord","+43 650 701 02 44",IF(A15="U14 - Nord","+43 676 401 09 13",IF(A15="U13 - Nord","+43 677 613 55 114 & +43 664 114 43 52",IF(A15="U11 Nord D","+43 664 762 09 93 & +43 699 111 93 828",IF(A15="U9","+43 676 377 16 30 & +43 399 197 871 81",IF(A15="U8","+43 660 199 13 52 & +43 660 914 92 36",IF(A15="U7","+43 676 661 62 26 & +43 681 208 115 99",IF(A15="Camp","+43 660 77 39 500",IF(A15="Turnier","+43 660 77 39 500","FEHLER"))))))))))) -> FEHLER
A16: =Heimspiele!C17 -> U16 | B16: =Heimspiele!D17 -> 0 | D16: =Heimspiele!F17 -> 0 | E16: =Heimspiele!G17 -> 0 | F16: Großfeld | G16: =IF(F16="Großfeld","Großfeld",IF(F16="U16","Großfeld",IF(F16="U15","Großfeld",IF(F16="U14","Großfeld",IF(F16="U13","75x55",IF(F16="U11/U12","55x40",IF(F16="U9/U10","40x25",IF(F16="U8","29x22","25x20")))))))) -> Großfeld | H16: =IF(F16="Großfeld","7,32x2,44",IF(F16="U16","7,32x2,44",IF(F16="U15","7,32x2,44",IF(F16="U14","7,32x2,44",IF(F16="U13","5x2",IF(F16="U11/U12","5x2",IF(F16="U9/U10","5x2","4 Minitore"))))))) -> 7,32x2,44 | I16: =IF(F16="Großfeld","5",IF(F16="U16","5",IF(F16="U15","5",IF(F16="U14","4",IF(F16="U13","4",IF(F16="U11/U12","4",IF(F16="U9/U10","4",IF(F16="U9","4","3")))))))) -> 5 | J16: =IF(A16="KM Neufeld","Pleninger Stefan",IF(A16="U16 LL","Josch Kögl",IF(A16="U15 LL Nord","Serdar Ekinci",IF(A16="U14 Nord","Gernot Servelda",IF(A16="U13 - Nord","Thomas Pöschl & Lenz Honc",IF(A16="U11 Nord D","Mario Magler&Ronny Archam",IF(A16="U9","Thomas Brandl&Daniel Hofbauer",IF(A16="U8","Berger Tobias&Sebastian Putric",IF(A16="U7","Türkes Ömer&Mahsumi Taha",IF(A16="Camp","Berger Dieter",IF(A16="Turnier","Berger Dieter","FEHLER"))))))))))) -> FEHLER | K16: =IF(A16="KM Neufeld","+43 664 415 99 09",IF(A16="U16 LL","+43 650 262 82 63",IF(A16="U15 LL Nord","+43 650 701 02 44",IF(A16="U14 - Nord","+43 676 401 09 13",IF(A16="U13 - Nord","+43 677 613 55 114 & +43 664 114 43 52",IF(A16="U11 Nord D","+43 664 762 09 93 & +43 699 111 93 828",IF(A16="U9","+43 676 377 16 30 & +43 399 197 871 81",IF(A16="U8","+43 660 199 13 52 & +43 660 914 92 36",IF(A16="U7","+43 676 661 62 26 & +43 681 208 115 99",IF(A16="Camp","+43 660 77 39 500",IF(A16="Turnier","+43 660 77 39 500","FEHLER"))))))))))) -> FEHLER
A17: =Heimspiele!C7 -> U12_1 | B17: =Heimspiele!D7 -> 0 | C17: =Heimspiele!E7 -> 0 | D17: =Heimspiele!F7 -> 0 | E17: =Heimspiele!G7 -> 0 | F17: U13 | G17: =IF(F17="Großfeld","Großfeld",IF(F17="U16","Großfeld",IF(F17="U15","Großfeld",IF(F17="U14","Großfeld",IF(F17="U13","75x55",IF(F17="U11/U12","55x40",IF(F17="U9/U10","40x25",IF(F17="U8","29x22","25x20")))))))) -> 75x55 | H17: =IF(F17="Großfeld","7,32x2,44",IF(F17="U16","7,32x2,44",IF(F17="U15","7,32x2,44",IF(F17="U14","7,32x2,44",IF(F17="U13","5x2",IF(F17="U11/U12","5x2",IF(F17="U9/U10","5x2","4 Minitore"))))))) -> 5x2 | I17: =IF(F17="Großfeld","5",IF(F17="U16","5",IF(F17="U15","5",IF(F17="U14","4",IF(F17="U13","4",IF(F17="U11/U12","4",IF(F17="U9/U10","4",IF(F17="U9","4","3")))))))) -> 4 | J17: =IF(A17="KM Neufeld","Pleninger Stefan",IF(A17="U16 LL","Josch Kögl",IF(A17="U15 LL Nord","Serdar Ekinci",IF(A17="U14 Nord","Gernot Servelda",IF(A17="U13 Nord","Thomas Pöschl & Lenz Honc",IF(A17="U11 Nord D","Mario Magler&Ronny Archam",IF(A17="U9","Thomas Brandl&Daniel Hofbauer",IF(A17="U8","Berger Tobias&Sebastian Putric",IF(A17="U7","Türkes Ömer&Mahsumi Taha",IF(A17="Camp","Berger Dieter",IF(A17="Turnier","Berger Dieter","FEHLER"))))))))))) -> FEHLER | K17: =IF(A17="KM Neufeld","+43 664 415 99 09",IF(A17="U16 LL","+43 650 262 82 63",IF(A17="U15 LL Nord","+43 650 701 02 44",IF(A17="U14 Nord","+43 676 401 09 13",IF(A17="U13 Nord","+43 677 613 55 114 & +43 664 114 43 52",IF(A17="U11 Nord D","+43 664 762 09 93 & +43 699 111 93 828",IF(A17="U9","+43 676 377 16 30 & +43 399 197 871 81",IF(A17="U8","+43 660 199 13 52 & +43 660 914 92 36",IF(A17="U7","+43 676 661 62 26 & +43 681 208 115 99",IF(A17="Camp","+43 660 77 39 500",IF(A17="Turnier","+43 660 77 39 500","FEHLER"))))))))))) -> FEHLER
A18: =Heimspiele!C19 -> U16 | B18: =Heimspiele!D19 -> 0 | D18: =Heimspiele!F19 -> 0 | E18: =Heimspiele!G19 -> 0 | F18: Großfeld | G18: =IF(F18="Großfeld","Großfeld",IF(F18="U16","Großfeld",IF(F18="U15","Großfeld",IF(F18="U14","Großfeld",IF(F18="U13","75x55",IF(F18="U11/U12","55x40",IF(F18="U9/U10","40x25",IF(F18="U8","29x22","25x20")))))))) -> Großfeld | H18: =IF(F18="Großfeld","7,32x2,44",IF(F18="U16","7,32x2,44",IF(F18="U15","7,32x2,44",IF(F18="U14","7,32x2,44",IF(F18="U13","5x2",IF(F18="U11/U12","5x2",IF(F18="U9/U10","5x2","4 Minitore"))))))) -> 7,32x2,44 | I18: =IF(F18="Großfeld","5",IF(F18="U16","5",IF(F18="U15","5",IF(F18="U14","4",IF(F18="U13","4",IF(F18="U11/U12","4",IF(F18="U9/U10","4",IF(F18="U9","4","3")))))))) -> 5 | J18: =IF(A18="KM Neufeld","Pleninger Stefan",IF(A18="U16 LL","Josch Kögl",IF(A18="U15 LL Nord","Serdar Ekinci",IF(A18="U14 Nord","Gernot Servelda",IF(A18="U13 - Nord","Thomas Pöschl & Lenz Honc",IF(A18="U11 Nord D","Mario Magler&Ronny Archam",IF(A18="U9","Thomas Brandl&Daniel Hofbauer",IF(A18="U8","Berger Tobias&Sebastian Putric",IF(A18="U7","Türkes Ömer&Mahsumi Taha",IF(A18="Camp","Berger Dieter",IF(A18="Turnier","Berger Dieter","FEHLER"))))))))))) -> FEHLER | K18: =IF(A18="KM Neufeld","+43 664 415 99 09",IF(A18="U16 LL","+43 650 262 82 63",IF(A18="U15 LL Nord","+43 650 701 02 44",IF(A18="U14 - Nord","+43 676 401 09 13",IF(A18="U13 - Nord","+43 677 613 55 114 & +43 664 114 43 52",IF(A18="U11 Nord D","+43 664 762 09 93 & +43 699 111 93 828",IF(A18="U9","+43 676 377 16 30 & +43 399 197 871 81",IF(A18="U8","+43 660 199 13 52 & +43 660 914 92 36",IF(A18="U7","+43 676 661 62 26 & +43 681 208 115 99",IF(A18="Camp","+43 660 77 39 500",IF(A18="Turnier","+43 660 77 39 500","FEHLER"))))))))))) -> FEHLER
A19: =Heimspiele!C20 -> U16 | B19: =Heimspiele!D20 -> 0 | D19: =Heimspiele!F20 -> 0 | E19: =Heimspiele!G20 -> 0 | F19: Großfeld | G19: =IF(F19="Großfeld","Großfeld",IF(F19="U16","Großfeld",IF(F19="U15","Großfeld",IF(F19="U14","Großfeld",IF(F19="U13","75x55",IF(F19="U11/U12","55x40",IF(F19="U9/U10","40x25",IF(F19="U8","29x22","25x20")))))))) -> Großfeld | H19: =IF(F19="Großfeld","7,32x2,44",IF(F19="U16","7,32x2,44",IF(F19="U15","7,32x2,44",IF(F19="U14","7,32x2,44",IF(F19="U13","5x2",IF(F19="U11/U12","5x2",IF(F19="U9/U10","5x2","4 Minitore"))))))) -> 7,32x2,44 | I19: =IF(F19="Großfeld","5",IF(F19="U16","5",IF(F19="U15","5",IF(F19="U14","4",IF(F19="U13","4",IF(F19="U11/U12","4",IF(F19="U9/U10","4",IF(F19="U9","4","3")))))))) -> 5 | J19: =IF(A19="KM Neufeld","Pleninger Stefan",IF(A19="U16 LL","Josch Kögl",IF(A19="U15 LL Nord","Serdar Ekinci",IF(A19="U14 Nord","Gernot Servelda",IF(A19="U13 - Nord","Thomas Pöschl & Lenz Honc",IF(A19="U11 Nord D","Mario Magler&Ronny Archam",IF(A19="U9","Thomas Brandl&Daniel Hofbauer",IF(A19="U8","Berger Tobias&Sebastian Putric",IF(A19="U7","Türkes Ömer&Mahsumi Taha",IF(A19="Camp","Berger Dieter",IF(A19="Turnier","Berger Dieter","FEHLER"))))))))))) -> FEHLER | K19: =IF(A19="KM Neufeld","+43 664 415 99 09",IF(A19="U16 LL","+43 650 262 82 63",IF(A19="U15 LL Nord","+43 650 701 02 44",IF(A19="U14 - Nord","+43 676 401 09 13",IF(A19="U13 - Nord","+43 677 613 55 114 & +43 664 114 43 52",IF(A19="U11 Nord D","+43 664 762 09 93 & +43 699 111 93 828",IF(A19="U9","+43 676 377 16 30 & +43 399 197 871 81",IF(A19="U8","+43 660 199 13 52 & +43 660 914 92 36",IF(A19="U7","+43 676 661 62 26 & +43 681 208 115 99",IF(A19="Camp","+43 660 77 39 500",IF(A19="Turnier","+43 660 77 39 500","FEHLER"))))))))))) -> FEHLER
