Workbook

Sheet Nach Mannschaften sortiert
A1: fortlaufende Nummer | B1: Runde | C1: Mannschaft | D1: fixierter Termin | E1: fixierte Uhrzeit | F1: Ort | G1: Gegner | H1: Auswärt/Heim
B2: 0 | C2: KM | D2: 46220 | E2: 0.79166667 | F2: Rohrbach | G2: Rohrbach | H2: Auswärts
B3: 0 | C3: KM | D3: 46241 | E3: 0.79166667 | F3: Neufeld | G3: Bad Fischau | H3: Heim
B4: 0 | C4: U16 | D4: 46199 | E4: 0.75 | F4: Wimpassing | G4: SK Rapid Wien | H4: Heim
B5: 0 | C5: U15 | D5: 46199 | E5: 0.66666667 | F5: Wimpassing | G5: SK Rapid Wien | H5: Heim
A6: 1 | B6: 1 | C6: KM
A7: 2 | B7: 2 | C7: KM
A8: 3 | B8: 3 | C8: KM
A9: 4 | B9: 4 | C9: KM
A10: 5 | B10: 5 | C10: KM
A11: 6 | B11: 6 | C11: KM
A12: 7 | B12: 7 | C12: KM
A13: 8 | B13: 8 | C13: KM
A14: 9 | B14: 9 | C14: KM
A15: 10 | B15: 10 | C15: KM
A16: 11 | B16: 11 | C16: KM
A17: 12 | B17: 12 | C17: KM
... A77: 67 | B77: 4 | C77: U11
B78: 5 | C78: U11
B79: 6 | C79: U11
B80: 7 | C80: U11
B81: 8 | C81: U11
B82: 9 | C82: U11
A83: 68 | B83: 10 | C83: U11
A84: 69 | B84: 1 | C84: U10
A85: 70 | B85: 2 | C85: U10
A86: 71 | B86: 3 | C86: U10
B87: 4 | C87: U10
B88: 5 | C88: U10
B89: 6 | C89: U10
B90: 7 | C90: U10
B91: 8 | C91: U10
A92: 72 | B92: 9 | C92: U10
A93: 73 | B93: 10 | C93: U10
A94: 74 | B94: 1 | C94: U9
A95: 75 | B95: 2 | C95: U9
B96: 3 | C96: U9
B97: 4 | C97: U9
B98: 5 | C98: U9
B99: 6 | C99: U9
...

Sheet ICS2
A1: GAME_ID | B1: TITEL | C1: DATUM | D1: STARTZEIT | E1: ENDZEIT | F1: ORT | G1: BESCHREIBUNG | H1: TYP | I1: GEGNER | J1: LIGA | K1: STATUS | L1: SPIELART | M1: ART
A2: GAME000001 | C2: 46220 | D2: 0.79166667 | E2: =IF(I2 = "KM",C2+"1:45",IF(I2="U23",C2+"1:45",IF(I2 = "U16",C2+"1:45",IF(I2 = "U15",C2+"1:30",IF(I2 = "U14",C2+"1:30",IF(I2 = "U13",C2+"1:35",IF(I2 = "U12",C2+"1:10",IF(I2 = "U11",C2+"1:10",IF(I2 = "U10",C2+"1:03",C2+"3:00"))))))))) | F2: ROHRBACH | H2: Auswärts | I2: Rohrbach | J2: KM | K2: aktiv | L2: Freundschaft | M2: Spiel
A3: GAME000002 | C3: 46241 | D3: 0.79166667 | E3: =IF(I3 = "KM",C3+"1:45",IF(I3="U23",C3+"1:45",IF(I3 = "U16",C3+"1:45",IF(I3 = "U15",C3+"1:30",IF(I3 = "U14",C3+"1:30",IF(I3 = "U13",C3+"1:35",IF(I3 = "U12",C3+"1:10",IF(I3 = "U11",C3+"1:10",IF(I3 = "U10",C3+"1:03",C3+"3:00"))))))))) | F3: NEUFELD | H3: Heim | I3: Bad Fischau | J3: KM | K3: aktiv | L3: Freundschaft | M3: Spiel
A4: GAME000003 | C4: 2026-08-07 | D4: 19:00 | E4: 20:00 | F4: WIMPASSING | G4: nan | H4: Heim | I4: Austria Wien | J4: U16 | K4: aktiv | L4: Freundschaft | M4: Spiel
A5: GAME000004 | C5: 46199 | D5: 0.66666667 | E5: =IF(I5 = "KM",C5+"1:45",IF(I5="U23",C5+"1:45",IF(I5 = "U16",C5+"1:45",IF(I5 = "U15",C5+"1:30",IF(I5 = "U14",C5+"1:30",IF(I5 = "U13",C5+"1:35",IF(I5 = "U12",C5+"1:10",IF(I5 = "U11",C5+"1:10",IF(I5 = "U10",C5+"1:03",C5+"3:00"))))))))) | F5: WIMPASSING | H5: Heim | I5: SK Rapid Wien | J5: U15 | K5: aktiv | L5: Freundschaft | M5: Spiel
A6: GAME000005 | C6: 36526 | D6: 0 | E6: 0.072916667 | J6: ='Nach Mannschaften sortiert'!C6 | K6: inaktiv | L6: Liga | M6: Spiel
A7: GAME000006 | C7: 36527 | D7: 0 | E7: 0.072916667 | J7: ='Nach Mannschaften sortiert'!C7 | K7: inaktiv | L7: Liga | M7: Spiel
A8: GAME000007 | C8: 36528 | D8: 0 | E8: 0.072916667 | J8: ='Nach Mannschaften sortiert'!C8 | K8: inaktiv | L8: Liga | M8: Spiel
A9: GAME000008 | C9: 36529 | D9: 0 | E9: 0.072916667 | J9: ='Nach Mannschaften sortiert'!C9 | K9: inaktiv | L9: Liga | M9: Spiel
A10: GAME000009 | C10: 36530 | D10: 0 | E10: 0.072916667 | J10: ='Nach Mannschaften sortiert'!C10 | K10: inaktiv | L10: Liga | M10: Spiel
A11: GAME000010 | C11: 36531 | D11: 0 | E11: 0.072916667 | J11: ='Nach Mannschaften sortiert'!C11 | K11: inaktiv | L11: Liga | M11: Spiel
A12: GAME000011 | C12: 36532 | D12: 0 | E12: 0.072916667 | J12: ='Nach Mannschaften sortiert'!C12 | K12: inaktiv | L12: Liga | M12: Spiel
A13: GAME000012 | C13: 36533 | D13: 0 | E13: 0.072916667 | J13: ='Nach Mannschaften sortiert'!C13 | K13: inaktiv | L13: Liga | M13: Spiel
A14: GAME000013 | C14: 36534 | D14: 0 | E14: 0.072916667 | J14: ='Nach Mannschaften sortiert'!C14 | K14: inaktiv | L14: Liga | M14: Spiel
A15: GAME000014 | C15: 36535 | D15: 0 | E15: 0.072916667 | J15: ='Nach Mannschaften sortiert'!C15 | K15: inaktiv | L15: Liga | M15: Spiel
A16: GAME000015 | C16: 36536 | D16: 0 | E16: 0.072916667 | J16: ='Nach Mannschaften sortiert'!C16 | K16: inaktiv | L16: Liga | M16: Spiel
A17: GAME000016 | C17: 36537 | D17: 0 | E17: 0.072916667 | J17: ='Nach Mannschaften sortiert'!C17 | K17: inaktiv | L17: Liga | M17: Spiel
... A113: GAME000112 | C113: 36633 | D113: 0 | E113: 0.072916667 | J113: ='Nach Mannschaften sortiert'!C113 | K113: inaktiv | L113: Liga | M113: Spiel
A114: GAME000113 | C114: ='Nach Mannschaften sortiert'!D114 | D114: 0.375 | E114: =IF(I114 = "KM",C114+"1:45",IF(I114="U23",C114+"1:45",IF(I114 = "U16",C114+"1:45",IF(I114 = "U15",C114+"1:30",IF(I114 = "U14",C114+"1:30",IF(I114 = "U13",C114+"1:35",IF(I114 = "U12",C114+"1:10",IF(I114 = "U11",C114+"1:10",IF(I114 = "U10",C114+"1:03",C114+"3:00"))))))))) | F114: Neufeld | H114: Heim | I114: CAMP | J114: TECO 7 CAMP | K114: aktiv | L114: Camp | M114: Camp
A115: GAME000114 | C115: ='Nach Mannschaften sortiert'!D115 | D115: 0.375 | E115: =IF(I115 = "KM",C115+"1:45",IF(I115="U23",C115+"1:45",IF(I115 = "U16",C115+"1:45",IF(I115 = "U15",C115+"1:30",IF(I115 = "U14",C115+"1:30",IF(I115 = "U13",C115+"1:35",IF(I115 = "U12",C115+"1:10",IF(I115 = "U11",C115+"1:10",IF(I115 = "U10",C115+"1:03",C115+"3:00"))))))))) | F115: Neufeld | H115: Heim | I115: CAMP | J115: TECO 7 CAMP | K115: aktiv | L115: Camp | M115: Camp
A116: GAME000115 | C116: ='Nach Mannschaften sortiert'!D116 | D116: 0.375 | E116: =IF(I116 = "KM",C116+"1:45",IF(I116="U23",C116+"1:45",IF(I116 = "U16",C116+"1:45",IF(I116 = "U15",C116+"1:30",IF(I116 = "U14",C116+"1:30",IF(I116 = "U13",C116+"1:35",IF(I116 = "U12",C116+"1:10",IF(I116 = "U11",C116+"1:10",IF(I116 = "U10",C116+"1:03",C116+"3:00"))))))))) | F116: Neufeld | H116: Heim | I116: CAMP | J116: TECO 7 CAMP | K116: aktiv | L116: Camp | M116: Camp
A117: GAME000116 | C117: ='Nach Mannschaften sortiert'!D117 | D117: 0.375 | E117: =IF(I117 = "KM",C117+"1:45",IF(I117="U23",C117+"1:45",IF(I117 = "U16",C117+"1:45",IF(I117 = "U15",C117+"1:30",IF(I117 = "U14",C117+"1:30",IF(I117 = "U13",C117+"1:35",IF(I117 = "U12",C117+"1:10",IF(I117 = "U11",C117+"1:10",IF(I117 = "U10",C117+"1:03",C117+"3:00"))))))))) | F117: Neufeld | H117: Heim | I117: CAMP | J117: REAL MADRID CAMP | K117: aktiv | L117: Camp | M117: Camp
A118: GAME000117 | C118: ='Nach Mannschaften sortiert'!D118 | D118: 0.375 | E118: =IF(I118 = "KM",C118+"1:45",IF(I118="U23",C118+"1:45",IF(I118 = "U16",C118+"1:45",IF(I118 = "U15",C118+"1:30",IF(I118 = "U14",C118+"1:30",IF(I118 = "U13",C118+"1:35",IF(I118 = "U12",C118+"1:10",IF(I118 = "U11",C118+"1:10",IF(I118 = "U10",C118+"1:03",C118+"3:00"))))))))) | F118: Neufeld | H118: Heim | I118: CAMP | J118: REAL MADRID CAMP | K118: aktiv | L118: Camp | M118: Camp
A119: GAME000118 | C119: ='Nach Mannschaften sortiert'!D119 | D119: 0.375 | E119: =IF(I119 = "KM",C119+"1:45",IF(I119="U23",C119+"1:45",IF(I119 = "U16",C119+"1:45",IF(I119 = "U15",C119+"1:30",IF(I119 = "U14",C119+"1:30",IF(I119 = "U13",C119+"1:35",IF(I119 = "U12",C119+"1:10",IF(I119 = "U11",C119+"1:10",IF(I119 = "U10",C119+"1:03",C119+"3:00"))))))))) | F119: Neufeld | H119: Heim | I119: CAMP | J119: REAL MADRID CAMP | K119: aktiv | L119: Camp | M119: Camp
A120: GAME000119 | C120: ='Nach Mannschaften sortiert'!D120 | D120: 0.375 | E120: =IF(I120 = "KM",C120+"1:45",IF(I120="U23",C120+"1:45",IF(I120 = "U16",C120+"1:45",IF(I120 = "U15",C120+"1:30",IF(I120 = "U14",C120+"1:30",IF(I120 = "U13",C120+"1:35",IF(I120 = "U12",C120+"1:10",IF(I120 = "U11",C120+"1:10",IF(I120 = "U10",C120+"1:03",C120+"3:00"))))))))) | F120: Neufeld | H120: Heim | I120: CAMP | J120: REAL MADRID CAMP | K120: aktiv | L120: Camp | M120: Camp
A121: GAME000120 | C121: ='Nach Mannschaften sortiert'!D121 | D121: 0.375 | E121: =IF(I121 = "KM",C121+"1:45",IF(I121="U23",C121+"1:45",IF(I121 = "U16",C121+"1:45",IF(I121 = "U15",C121+"1:30",IF(I121 = "U14",C121+"1:30",IF(I121 = "U13",C121+"1:35",IF(I121 = "U12",C121+"1:10",IF(I121 = "U11",C121+"1:10",IF(I121 = "U10",C121+"1:03",C121+"3:00"))))))))) | F121: Neufeld | H121: Heim | I121: CAMP | J121: REAL MADRID CAMP | K121: aktiv | L121: Camp | M121: Camp
A122: GAME000121 | C122: 03.08.2026 | D122: 10:00 | E122: 15:00 | F122: Neufeld | G122: nan | H122: Heim | I122: CAMP | J122: MÄDCHEN CAMP | K122: aktiv | L122: Camp | M122: Camp
A123: GAME000122 | C123: 46238 | D123: 0.375 | E123: 0.625 | F123: Neufeld | H123: Heim | I123: CAMP | J123: MÄDCHEN CAMP | K123: aktiv | L123: Camp | M123: Camp
A124: GAME000123 | C124: 46239 | D124: 0.375 | E124: 0.625 | F124: Neufeld | H124: Heim | I124: CAMP | J124: MÄDCHEN CAMP | K124: aktiv | L124: Camp | M124: Camp
A125: GAME000124 | C125: ='Nach Mannschaften sortiert'!D122 | D125: ='Nach Mannschaften sortiert'!E122 | E125: =IF(I125 = "KM",C125+"1:45",IF(I125="U23",C125+"1:45",IF(I125 = "U16",C125+"1:45",IF(I125 = "U15",C125+"1:30",IF(I125 = "U14",C125+"1:30",IF(I125 = "U13",C125+"1:35",IF(I125 = "U12",C125+"1:10",IF(I125 = "U11",C125+"1:10",IF(I125 = "U10",C125+"1:03",C125+"3:00"))))))))) | F125: Neufeld | H125: Heim | I125: ='Nach Mannschaften sortiert'!G122 | J125: ='Nach Mannschaften sortiert'!C122 | K125: aktiv | L125: Turnier | M125: Turnier
A126: GAME000125 | C126: 26.06.2026 | D126: 10:00 | E126: 11:30 | F126: Neufeld | H126: Heim | I126: FC Arsenal | J126: U14 | K126: Aktiv | M126: Spiel
A127: GAME000126 | C127: 28.06.2026 | D127: 10:00 | E127: 12:00 | F127: Neufeld | G127: Testspiel | H127: Heim | I127: Real Madrid | J127: U9 | K127: Aktiv | M127: Spiel

Sheet HISTORY
A1: Zeitpunkt | B1: GAME_ID | C1: Bereich | D1: Aktion | E1: Objekt | F1: ExcelZeile | G1: Grund | H1: Bemerkung | I1: Benutzer
A2: 26.06.2026 10:19:36 | C2: Spiel | D2: Bearbeitet | E2: MÄDCHEN CAMP | 03.08.2026 | CAMP | F2: 122 | H2: Spiel wurde bearbeitet | I2: System
A3: 26.06.2026 11:14:54 | B3: GAME000121 | C3: Spiel | D3: Bearbeitet | E3: MÄDCHEN CAMP | 03.08.2026 | CAMP | F3: 122 | H3: Spiel wurde bearbeitet | I3: System
A4: 26.06.2026 11:17:37 | B4: GAME000003 | C4: Spiel | D4: Bearbeitet | E4: U16 | 2026-08-07 | Austria Wien | F4: 4 | H4: Spiel wurde bearbeitet | I4: System

Sheet Kalendernamen
A1: Kategorie | C1: ABOLINK
A2: Alle Spiele des ASV Neufeld | B2: alle_spiele.ics | C2: ="https://dtb-asv.github.io/asv-neufeld/"&B2
A3: Alle Heimspiele des ASV Neufelds | B3: heimspiele.ics | C3: ="https://dtb-asv.github.io/asv-neufeld/"&B3
A4: Alle Auswärtsspiele des ASV Neufelds | B4: auswaertsspiele.ics | C4: ="https://dtb-asv.github.io/asv-neufeld/"&B4
A5: Alle Spiele der Kampfmannschaft | B5: KM.ics | C5: ="https://dtb-asv.github.io/asv-neufeld/"&B5
A6: Alle Spiele der U23 | B6: U23.ics | C6: ="https://dtb-asv.github.io/asv-neufeld/"&B6
A7: Alle Spiele der U16 | B7: U16.ics | C7: ="https://dtb-asv.github.io/asv-neufeld/"&B7
A8: Alle Spiele der U15 | B8: U15.ics | C8: ="https://dtb-asv.github.io/asv-neufeld/"&B8
A9: Alle Spiele der U14 | B9: U14.ics | C9: ="https://dtb-asv.github.io/asv-neufeld/"&B9
A10: Alle Spiele der U13 | B10: U13.ics | C10: ="https://dtb-asv.github.io/asv-neufeld/"&B10
A11: Alle Spiele der U12 | B11: U12.ics | C11: ="https://dtb-asv.github.io/asv-neufeld/"&B11
A12: Alle Spiele der U11 | B12: U11.ics | C12: ="https://dtb-asv.github.io/asv-neufeld/"&B12
A13: Alle Spiele der U10 | B13: U10.ics | C13: ="https://dtb-asv.github.io/asv-neufeld/"&B13
... A16: Alle Spiele der U7 | B16: U7.ics | C16: ="https://dtb-asv.github.io/asv-neufeld/"&B16
B17: Camp.ics | C17: ="https://dtb-asv.github.io/asv-neufeld/"&B17
B18: GGG.ics | C18: ="https://dtb-asv.github.io/asv-neufeld/"&B18

Sheet Trainingsplan
A1: TRAININGSORTE/TAGE
A2: MANNSCHAFT | B2: TRAINER | C2: MONTAG | D2: DIENSTAG | E2: MITTWOCH | F2: DONNERSTAG | G2: FREITAG | H2: SAMSTAG | I2: WENN KM-TRAINING MUSS DAS HAUPTFELD AB 18:45 FREI SEIN
A3: FKG | B3: RONNIE ARCHAM | E3: 16:00 - 16:45
A4: U7 | B4: ÖMER TÜRKES TAHA MAHSUMI | D4: 17:30 - 18:30 | F4: 17:30 - 18:30
A5: U8 | B5: TOBIAS BERGER SEBASTIAN PUTRIC | C5: 16:30 - 18:00 | F5: 17: 00 - 18:30
A6: U9 | B6: THOMAS BRANDL DANIEL HOFBAUER | D6: 17:00 - 18:30 | F6: 17:00 - 18:30
A7: U11 | B7: MARIO MAGLER RONNIE ARCHAM | C7: 17:00 - 18:30 | E7: 17:00 - 18:30 | G7: 17:00 - 18:30
A8: U13 | B8: THOMAS PÖSCHL LENZ HONC | C8: 17:00 - 18:30 | E8: 17:00 - 18:30 | G8: 17:00 - 18:30
A9: U14 | B9: GERNOT SEVELDA MARKUS DORINGER | C9: 17:00 - 18:30 | F9: 17:00 - 18:30 | G9: 17:00 - 18:30 | H9: 10:00 - 11:00
A10: U15 | B10: SERDAR EKINCI HUBERT OBERHOFER | D10: 18:30 - 20:15 | F10: 18:00 - 19:30 | G10: 18:30 - 20:15
A11: U16 | B11: JOSCH KÖGL | E11: 17:15 - 19:00 | G11: WIMPASSING
A12: U23 | B12: DINGES STEFAN | C12: 18:45 - 20:15 | E12: 18:45 - 20:15 | F12: 18:45 - 20:15
A13: KM | B13: PLENINGER STEFAN | C13: 18:45 - 20:15 | E13: 18:45 - 20:15 | F13: 18:45 - 20:15
A14: JUNIOREN/SENIOREN | D14: 18:45 - 20:15
A15: HAUPTFELD
A16: TRAININGSPLATZ
A17: HINTERM TOR
A18: SPIELGEMEINSCHAFTEN MIT WIMPASSING

Sheet Heimspiele
A1: ='Nach Mannschaften sortiert'!A1 | B1: ='Nach Mannschaften sortiert'!B1 | C1: ='Nach Mannschaften sortiert'!C1 | D1: ='Nach Mannschaften sortiert'!D1 | E1: ='Nach Mannschaften sortiert'!E1 | F1: ='Nach Mannschaften sortiert'!F1 | G1: ='Nach Mannschaften sortiert'!G1 | H1: ='Nach Mannschaften sortiert'!H1
A2: ='Nach Mannschaften sortiert'!A6 | B2: ='Nach Mannschaften sortiert'!B6 | C2: ='Nach Mannschaften sortiert'!C6 | D2: ='Nach Mannschaften sortiert'!D6 | E2: ='Nach Mannschaften sortiert'!E6 | F2: ='Nach Mannschaften sortiert'!F6 | G2: ='Nach Mannschaften sortiert'!G6 | H2: ='Nach Mannschaften sortiert'!H6
A3: ='Nach Mannschaften sortiert'!A7 | B3: ='Nach Mannschaften sortiert'!B7 | C3: ='Nach Mannschaften sortiert'!C7 | D3: ='Nach Mannschaften sortiert'!D7 | E3: ='Nach Mannschaften sortiert'!E7 | F3: ='Nach Mannschaften sortiert'!F7 | G3: ='Nach Mannschaften sortiert'!G7 | H3: ='Nach Mannschaften sortiert'!H7
A4: ='Nach Mannschaften sortiert'!A8 | B4: ='Nach Mannschaften sortiert'!B8 | C4: ='Nach Mannschaften sortiert'!C8 | D4: ='Nach Mannschaften sortiert'!D8 | E4: ='Nach Mannschaften sortiert'!E8 | F4: ='Nach Mannschaften sortiert'!F8 | G4: ='Nach Mannschaften sortiert'!G8 | H4: ='Nach Mannschaften sortiert'!H8
A5: ='Nach Mannschaften sortiert'!A50 | B5: ='Nach Mannschaften sortiert'!B50 | C5: ='Nach Mannschaften sortiert'!C50 | D5: ='Nach Mannschaften sortiert'!D50 | E5: ='Nach Mannschaften sortiert'!E50 | F5: ='Nach Mannschaften sortiert'!F50 | G5: ='Nach Mannschaften sortiert'!G50 | H5: ='Nach Mannschaften sortiert'!H50
A6: ='Nach Mannschaften sortiert'!A10 | B6: ='Nach Mannschaften sortiert'!B10 | C6: ='Nach Mannschaften sortiert'!C10 | D6: ='Nach Mannschaften sortiert'!D10 | E6: ='Nach Mannschaften sortiert'!E10 | F6: ='Nach Mannschaften sortiert'!F10 | G6: ='Nach Mannschaften sortiert'!G10 | H6: ='Nach Mannschaften sortiert'!H10
A7: ='Nach Mannschaften sortiert'!A58 | B7: ='Nach Mannschaften sortiert'!B58 | C7: ='Nach Mannschaften sortiert'!C58 | D7: ='Nach Mannschaften sortiert'!D58 | E7: ='Nach Mannschaften sortiert'!E58 | F7: ='Nach Mannschaften sortiert'!F58 | G7: ='Nach Mannschaften sortiert'!G58 | H7: ='Nach Mannschaften sortiert'!H58
A8: ='Nach Mannschaften sortiert'!A12 | B8: ='Nach Mannschaften sortiert'!B12 | C8: ='Nach Mannschaften sortiert'!C12 | D8: ='Nach Mannschaften sortiert'!D12 | E8: ='Nach Mannschaften sortiert'!E12 | F8: ='Nach Mannschaften sortiert'!F12 | G8: ='Nach Mannschaften sortiert'!G12 | H8: ='Nach Mannschaften sortiert'!H12
A9: ='Nach Mannschaften sortiert'!A104 | B9: ='Nach Mannschaften sortiert'!B104 | C9: ='Nach Mannschaften sortiert'!C104 | D9: ='Nach Mannschaften sortiert'!D104 | E9: ='Nach Mannschaften sortiert'!E104 | F9: ='Nach Mannschaften sortiert'!F104 | G9: ='Nach Mannschaften sortiert'!G104 | H9: ='Nach Mannschaften sortiert'!H104
A10: ='Nach Mannschaften sortiert'!A14 | B10: ='Nach Mannschaften sortiert'!B14 | C10: ='Nach Mannschaften sortiert'!C14 | D10: ='Nach Mannschaften sortiert'!D14 | E10: ='Nach Mannschaften sortiert'!E14 | F10: ='Nach Mannschaften sortiert'!F14 | G10: ='Nach Mannschaften sortiert'!G14 | H10: ='Nach Mannschaften sortiert'!H14
A11: ='Nach Mannschaften sortiert'!A112 | B11: ='Nach Mannschaften sortiert'!B112 | C11: ='Nach Mannschaften sortiert'!C112 | D11: ='Nach Mannschaften sortiert'!D112 | E11: ='Nach Mannschaften sortiert'!E112 | F11: ='Nach Mannschaften sortiert'!F112 | G11: ='Nach Mannschaften sortiert'!G112 | H11: ='Nach Mannschaften sortiert'!H112
A12: ='Nach Mannschaften sortiert'!A16 | B12: ='Nach Mannschaften sortiert'!B16 | C12: ='Nach Mannschaften sortiert'!C16 | D12: ='Nach Mannschaften sortiert'!D16 | E12: ='Nach Mannschaften sortiert'!E16 | F12: ='Nach Mannschaften sortiert'!F16 | G12: ='Nach Mannschaften sortiert'!G16 | H12: ='Nach Mannschaften sortiert'!H16
A13: ='Nach Mannschaften sortiert'!A17 | B13: ='Nach Mannschaften sortiert'!B17 | C13: ='Nach Mannschaften sortiert'!C17 | D13: ='Nach Mannschaften sortiert'!D17 | E13: ='Nach Mannschaften sortiert'!E17 | F13: ='Nach Mannschaften sortiert'!F17 | G13: ='Nach Mannschaften sortiert'!G17 | H13: ='Nach Mannschaften sortiert'!H17
A14: ='Nach Mannschaften sortiert'!A113 | B14: ='Nach Mannschaften sortiert'!B113 | C14: ='Nach Mannschaften sortiert'!C113 | D14: ='Nach Mannschaften sortiert'!D113 | E14: ='Nach Mannschaften sortiert'!E113 | F14: ='Nach Mannschaften sortiert'!F113 | G14: ='Nach Mannschaften sortiert'!G113 | H14: ='Nach Mannschaften sortiert'!H113
A15: ='Nach Mannschaften sortiert'!A32 | B15: ='Nach Mannschaften sortiert'!B32 | C15: ='Nach Mannschaften sortiert'!C32 | D15: ='Nach Mannschaften sortiert'!D32 | E15: ='Nach Mannschaften sortiert'!E32 | F15: ='Nach Mannschaften sortiert'!F32 | G15: ='Nach Mannschaften sortiert'!G32 | H15: ='Nach Mannschaften sortiert'!H32
A16: ='Nach Mannschaften sortiert'!A33 | B16: ='Nach Mannschaften sortiert'!B33 | C16: ='Nach Mannschaften sortiert'!C33 | D16: ='Nach Mannschaften sortiert'!D33 | E16: ='Nach Mannschaften sortiert'!E33 | F16: ='Nach Mannschaften sortiert'!F33 | G16: ='Nach Mannschaften sortiert'!G33 | H16: ='Nach Mannschaften sortiert'!H33
A17: ='Nach Mannschaften sortiert'!A34 | B17: ='Nach Mannschaften sortiert'!B34 | C17: ='Nach Mannschaften sortiert'!C34 | D17: ='Nach Mannschaften sortiert'!D34 | E17: ='Nach Mannschaften sortiert'!E34 | F17: ='Nach Mannschaften sortiert'!F34 | G17: ='Nach Mannschaften sortiert'!G34 | H17: ='Nach Mannschaften sortiert'!H34
A18: ='Nach Mannschaften sortiert'!A9 | B18: ='Nach Mannschaften sortiert'!B9 | C18: ='Nach Mannschaften sortiert'!C9 | D18: ='Nach Mannschaften sortiert'!D9 | E18: ='Nach Mannschaften sortiert'!E9 | F18: ='Nach Mannschaften sortiert'!F9 | G18: ='Nach Mannschaften sortiert'!G9 | H18: ='Nach Mannschaften sortiert'!H9
A19: ='Nach Mannschaften sortiert'!A36 | B19: ='Nach Mannschaften sortiert'!B36 | C19: ='Nach Mannschaften sortiert'!C36 | D19: ='Nach Mannschaften sortiert'!D36 | E19: ='Nach Mannschaften sortiert'!E36 | F19: ='Nach Mannschaften sortiert'!F36 | G19: ='Nach Mannschaften sortiert'!G36 | H19: ='Nach Mannschaften sortiert'!H36
A20: ='Nach Mannschaften sortiert'!A37 | B20: ='Nach Mannschaften sortiert'!B37 | C20: ='Nach Mannschaften sortiert'!C37 | D20: ='Nach Mannschaften sortiert'!D37 | E20: ='Nach Mannschaften sortiert'!E37 | F20: ='Nach Mannschaften sortiert'!F37 | G20: ='Nach Mannschaften sortiert'!G37 | H20: ='Nach Mannschaften sortiert'!H37
A21: ='Nach Mannschaften sortiert'!A38 | B21: ='Nach Mannschaften sortiert'!B38 | C21: ='Nach Mannschaften sortiert'!C38 | D21: ='Nach Mannschaften sortiert'!D38 | E21: ='Nach Mannschaften sortiert'!E38 | F21: ='Nach Mannschaften sortiert'!F38 | G21: ='Nach Mannschaften sortiert'!G38 | H21: ='Nach Mannschaften sortiert'!H38
A22: ='Nach Mannschaften sortiert'!A39 | B22: ='Nach Mannschaften sortiert'!B39 | C22: ='Nach Mannschaften sortiert'!C39 | D22: ='Nach Mannschaften sortiert'!D39 | E22: ='Nach Mannschaften sortiert'!E39 | F22: ='Nach Mannschaften sortiert'!F39 | G22: ='Nach Mannschaften sortiert'!G39 | H22: ='Nach Mannschaften sortiert'!H39
A23: ='Nach Mannschaften sortiert'!A40 | B23: ='Nach Mannschaften sortiert'!B40 | C23: ='Nach Mannschaften sortiert'!C40 | D23: ='Nach Mannschaften sortiert'!D40 | E23: ='Nach Mannschaften sortiert'!E40 | F23: ='Nach Mannschaften sortiert'!F40 | G23: ='Nach Mannschaften sortiert'!G40 | H23: ='Nach Mannschaften sortiert'!H40
A24: ='Nach Mannschaften sortiert'!A74 | B24: ='Nach Mannschaften sortiert'!B74 | C24: ='Nach Mannschaften sortiert'!C74 | D24: ='Nach Mannschaften sortiert'!D74 | E24: ='Nach Mannschaften sortiert'!E74 | F24: ='Nach Mannschaften sortiert'!F74 | G24: ='Nach Mannschaften sortiert'!G74 | H24: ='Nach Mannschaften sortiert'!H74
A25: ='Nach Mannschaften sortiert'!#REF! | B25: ='Nach Mannschaften sortiert'!#REF! | C25: ='Nach Mannschaften sortiert'!#REF! | D25: ='Nach Mannschaften sortiert'!#REF! | E25: ='Nach Mannschaften sortiert'!#REF! | F25: ='Nach Mannschaften sortiert'!#REF! | G25: ='Nach Mannschaften sortiert'!#REF! | H25: ='Nach Mannschaften sortiert'!#REF!
A26: ='Nach Mannschaften sortiert'!A84 | B26: ='Nach Mannschaften sortiert'!B84 | C26: ='Nach Mannschaften sortiert'!C84 | D26: ='Nach Mannschaften sortiert'!D84 | E26: ='Nach Mannschaften sortiert'!E84 | F26: ='Nach Mannschaften sortiert'!F84 | G26: ='Nach Mannschaften sortiert'!G84 | H26: ='Nach Mannschaften sortiert'!H84
A27: ='Nach Mannschaften sortiert'!A43 | B27: ='Nach Mannschaften sortiert'!B43 | C27: ='Nach Mannschaften sortiert'!C43 | D27: ='Nach Mannschaften sortiert'!D43 | E27: ='Nach Mannschaften sortiert'!E43 | F27: ='Nach Mannschaften sortiert'!F43 | G27: ='Nach Mannschaften sortiert'!G43 | H27: ='Nach Mannschaften sortiert'!H43
A28: ='Nach Mannschaften sortiert'!A44 | B28: ='Nach Mannschaften sortiert'!B44 | C28: ='Nach Mannschaften sortiert'!C44 | D28: ='Nach Mannschaften sortiert'!D44 | E28: ='Nach Mannschaften sortiert'!E44 | F28: ='Nach Mannschaften sortiert'!F44 | G28: ='Nach Mannschaften sortiert'!G44 | H28: ='Nach Mannschaften sortiert'!H44
A29: ='Nach Mannschaften sortiert'!A94 | B29: ='Nach Mannschaften sortiert'!B94 | C29: ='Nach Mannschaften sortiert'!C94 | D29: ='Nach Mannschaften sortiert'!D94 | E29: ='Nach Mannschaften sortiert'!E94 | F29: ='Nach Mannschaften sortiert'!F94 | G29: ='Nach Mannschaften sortiert'!G94 | H29: ='Nach Mannschaften sortiert'!H94
A30: ='Nach Mannschaften sortiert'!#REF! | B30: ='Nach Mannschaften sortiert'!#REF! | C30: ='Nach Mannschaften sortiert'!#REF! | D30: ='Nach Mannschaften sortiert'!#REF! | E30: ='Nach Mannschaften sortiert'!#REF! | F30: ='Nach Mannschaften sortiert'!#REF! | G30: ='Nach Mannschaften sortiert'!#REF! | H30: ='Nach Mannschaften sortiert'!#REF!
A31: ='Nach Mannschaften sortiert'!A46 | B31: ='Nach Mannschaften sortiert'!B46 | C31: ='Nach Mannschaften sortiert'!C46 | D31: ='Nach Mannschaften sortiert'!D46 | E31: ='Nach Mannschaften sortiert'!E46 | F31: ='Nach Mannschaften sortiert'!F46 | G31: ='Nach Mannschaften sortiert'!G46 | H31: ='Nach Mannschaften sortiert'!H46
A32: ='Nach Mannschaften sortiert'!A47 | B32: ='Nach Mannschaften sortiert'!B47 | C32: ='Nach Mannschaften sortiert'!C47 | D32: ='Nach Mannschaften sortiert'!D47 | E32: ='Nach Mannschaften sortiert'!E47 | F32: ='Nach Mannschaften sortiert'!F47 | G32: ='Nach Mannschaften sortiert'!G47 | H32: ='Nach Mannschaften sortiert'!H47
A33: ='Nach Mannschaften sortiert'!A48 | B33: ='Nach Mannschaften sortiert'!B48 | C33: ='Nach Mannschaften sortiert'!C48 | D33: ='Nach Mannschaften sortiert'!D48 | E33: ='Nach Mannschaften sortiert'!E48 | F33: ='Nach Mannschaften sortiert'!F48 | G33: ='Nach Mannschaften sortiert'!G48 | H33: ='Nach Mannschaften sortiert'!H48
A34: ='Nach Mannschaften sortiert'!A49 | B34: ='Nach Mannschaften sortiert'!B49 | C34: ='Nach Mannschaften sortiert'!C49 | D34: ='Nach Mannschaften sortiert'!D49 | E34: ='Nach Mannschaften sortiert'!E49 | F34: ='Nach Mannschaften sortiert'!F49 | G34: ='Nach Mannschaften sortiert'!G49 | H34: ='Nach Mannschaften sortiert'!H49
A35: ='Nach Mannschaften sortiert'!A67 | B35: ='Nach Mannschaften sortiert'!B67 | C35: ='Nach Mannschaften sortiert'!C67 | D35: ='Nach Mannschaften sortiert'!D67 | E35: ='Nach Mannschaften sortiert'!E67 | F35: ='Nach Mannschaften sortiert'!F67 | G35: ='Nach Mannschaften sortiert'!G67 | H35: ='Nach Mannschaften sortiert'!H67
A36: ='Nach Mannschaften sortiert'!A51 | B36: ='Nach Mannschaften sortiert'!B51 | C36: ='Nach Mannschaften sortiert'!C51 | D36: ='Nach Mannschaften sortiert'!D51 | E36: ='Nach Mannschaften sortiert'!E51 | F36: ='Nach Mannschaften sortiert'!F51 | G36: ='Nach Mannschaften sortiert'!G51 | H36: ='Nach Mannschaften sortiert'!H51
A37: ='Nach Mannschaften sortiert'!A52 | B37: ='Nach Mannschaften sortiert'!B52 | C37: ='Nach Mannschaften sortiert'!C52 | D37: ='Nach Mannschaften sortiert'!D52 | E37: ='Nach Mannschaften sortiert'!E52 | F37: ='Nach Mannschaften sortiert'!F52 | G37: ='Nach Mannschaften sortiert'!G52 | H37: ='Nach Mannschaften sortiert'!H52
A38: ='Nach Mannschaften sortiert'!A42 | B38: ='Nach Mannschaften sortiert'!B42 | C38: ='Nach Mannschaften sortiert'!C42 | D38: ='Nach Mannschaften sortiert'!D42 | E38: ='Nach Mannschaften sortiert'!E42 | F38: ='Nach Mannschaften sortiert'!F42 | G38: ='Nach Mannschaften sortiert'!G42 | H38: ='Nach Mannschaften sortiert'!H42
A39: ='Nach Mannschaften sortiert'!#REF! | B39: ='Nach Mannschaften sortiert'!#REF! | C39: ='Nach Mannschaften sortiert'!#REF! | D39: ='Nach Mannschaften sortiert'!#REF! | E39: ='Nach Mannschaften sortiert'!#REF! | F39: ='Nach Mannschaften sortiert'!#REF! | G39: ='Nach Mannschaften sortiert'!#REF! | H39: ='Nach Mannschaften sortiert'!#REF!
A40: ='Nach Mannschaften sortiert'!A54 | B40: ='Nach Mannschaften sortiert'!B54 | C40: ='Nach Mannschaften sortiert'!C54 | D40: ='Nach Mannschaften sortiert'!D54 | E40: ='Nach Mannschaften sortiert'!E54 | F40: ='Nach Mannschaften sortiert'!F54 | G40: ='Nach Mannschaften sortiert'!G54 | H40: ='Nach Mannschaften sortiert'!H54
...

Sheet Tabelle1
A1: U11 | B1: 25 - 26.04 | C1: freihalten
A2: U9 | B2: 04.06. - 08.06. | C2: kein Turnier

Sheet Stefans Liste 2026
A1: Mannschaft | B1: fixierter Termin | C1: Uhrzeit | D1: Ort | E1: Gegner | F1: Spielfeld | G1: Spielfeldgröße | H1: Tore | I1: Ball | J1: Trainer/Ansprechpartner | K1: Tel
A2: U8 | B2: 46091 | C2: 0.6875 | D2: Neufeld | E2: Freundschaftsspiel Großhöflein | F2: U8 | G2: =IF(F2="Großfeld","Großfeld",IF(F2="U16","Großfeld",IF(F2="U15","Großfeld",IF(F2="U14","Großfeld",IF(F2="U13","75x55",IF(F2="U11/U12","55x40",IF(F2="U9/U10","40x25",IF(F2="U8","29x22","25x20")))))))) | H2: =IF(F2="Großfeld","7,32x2,44",IF(F2="U16","7,32x2,44",IF(F2="U15","7,32x2,44",IF(F2="U14","7,32x2,44",IF(F2="U13","5x2",IF(F2="U11/U12","5x2",IF(F2="U9/U10","5x2","4 Minitore"))))))) | I2: =IF(F2="Großfeld","5",IF(F2="U16","5",IF(F2="U15","5",IF(F2="U14","4",IF(F2="U13","4",IF(F2="U11/U12","4",IF(F2="U9/U10","4",IF(F2="U9","4","3")))))))) | J2: =IF(A2="KM Neufeld","Pleninger Stefan",IF(A2="U16 LL","Josch Kögl",IF(A2="U15 LL Nord","Serdar Ekinci",IF(A2="U14 Nord","Gernot Servelda",IF(A2="U13 Nord","Thomas Pöschl & Lenz Honc",IF(A2="U11 Nord D","Mario Magler&Ronny Archam",IF(A2="U9","Thomas Brandl&Daniel Hofbauer",IF(A2="U8","Berger Tobias&Sebastian Putric",IF(A2="U7","Türkes Ömer&Mahsumi Taha",IF(A2="Camp","Berger Dieter",IF(A2="Turnier","Berger Dieter","FEHLER"))))))))))) | K2: =IF(A2="KM Neufeld","+43 664 415 99 09",IF(A2="U16 LL","+43 650 262 82 63",IF(A2="U15 LL Nord","+43 650 701 02 44",IF(A2="U14 Nord","+43 676 401 09 13",IF(A2="U13 Nord","+43 677 613 55 114 & +43 664 114 43 52",IF(A2="U11 Nord D","+43 664 762 09 93 & +43 699 111 93 828",IF(A2="U9","+43 676 377 16 30 & +43 399 197 871 81",IF(A2="U8","+43 660 199 13 52 & +43 660 914 92 36",IF(A2="U7","+43 676 661 62 26 & +43 681 208 115 99",IF(A2="Camp","+43 660 77 39 500",IF(A2="Turnier","+43 660 77 39 500","FEHLER")))))))))))
A3: =Heimspiele!C4 | B3: =Heimspiele!D4 | D3: =Heimspiele!F4 | E3: =Heimspiele!G4 | F3: Großfeld | G3: =IF(F3="Großfeld","Großfeld",IF(F3="U16","Großfeld",IF(F3="U15","Großfeld",IF(F3="U14","Großfeld",IF(F3="U13","75x55",IF(F3="U11/U12","55x40",IF(F3="U9/U10","40x25",IF(F3="U8","29x22","25x20")))))))) | H3: =IF(F3="Großfeld","7,32x2,44",IF(F3="U16","7,32x2,44",IF(F3="U15","7,32x2,44",IF(F3="U14","7,32x2,44",IF(F3="U13","5x2",IF(F3="U11/U12","5x2",IF(F3="U9/U10","5x2","4 Minitore"))))))) | I3: =IF(F3="Großfeld","5",IF(F3="U16","5",IF(F3="U15","5",IF(F3="U14","4",IF(F3="U13","4",IF(F3="U11/U12","4",IF(F3="U9/U10","4",IF(F3="U9","4","3")))))))) | J3: =IF(A3="KM Neufeld","Pleninger Stefan",IF(A3="U16 LL","Josch Kögl",IF(A3="U15 LL Nord","Serdar Ekinci",IF(A3="U14 Nord","Gernot Servelda",IF(A3="U13 - Nord","Thomas Pöschl & Lenz Honc",IF(A3="U11 Nord D","Mario Magler&Ronny Archam",IF(A3="U9","Thomas Brandl&Daniel Hofbauer",IF(A3="U8","Berger Tobias&Sebastian Putric",IF(A3="U7","Türkes Ömer&Mahsumi Taha",IF(A3="Camp","Berger Dieter",IF(A3="Turnier","Berger Dieter","FEHLER"))))))))))) | K3: =IF(A3="KM Neufeld","+43 664 415 99 09",IF(A3="U16 LL","+43 650 262 82 63",IF(A3="U15 LL Nord","+43 650 701 02 44",IF(A3="U14 - Nord","+43 676 401 09 13",IF(A3="U13 - Nord","+43 677 613 55 114 & +43 664 114 43 52",IF(A3="U11 Nord D","+43 664 762 09 93 & +43 699 111 93 828",IF(A3="U9","+43 676 377 16 30 & +43 399 197 871 81",IF(A3="U8","+43 660 199 13 52 & +43 660 914 92 36",IF(A3="U7","+43 676 661 62 26 & +43 681 208 115 99",IF(A3="Camp","+43 660 77 39 500",IF(A3="Turnier","+43 660 77 39 500","FEHLER")))))))))))
A4: U16 LL | B4: 46095 | C4: 0.54166667 | D4: Neufeld | E4: Freundschaftspiel Felixdorf | F4: U16 | G4: =IF(F4="Großfeld","Großfeld",IF(F4="U16","Großfeld",IF(F4="U15","Großfeld",IF(F4="U14","Großfeld",IF(F4="U13","75x55",IF(F4="U11/U12","55x40",IF(F4="U9/U10","40x25",IF(F4="U8","29x22","25x20")))))))) | H4: =IF(F4="Großfeld","7,32x2,44",IF(F4="U16","7,32x2,44",IF(F4="U15","7,32x2,44",IF(F4="U14","7,32x2,44",IF(F4="U13","5x2",IF(F4="U11/U12","5x2",IF(F4="U9/U10","5x2",IF(F3="Turnier","5x2","4 Minitore")))))))) | I4: =IF(F4="Großfeld","5",IF(F4="U16","5",IF(F4="U15","5",IF(F4="U14","4",IF(F4="U13","4",IF(F4="U11/U12","4",IF(F4="U9/U10","4",IF(F4="U9","4","3")))))))) | J4: =IF(A4="KM Neufeld","Pleninger Stefan",IF(A4="U16 LL","Josch Kögl",IF(A4="U15 LL Nord","Serdar Ekinci",IF(A4="U14 Nord","Gernot Servelda",IF(A4="U13 Nord","Thomas Pöschl & Lenz Honc",IF(A4="U11 Nord D","Mario Magler&Ronny Archam",IF(A4="U9","Thomas Brandl&Daniel Hofbauer",IF(A4="U8","Berger Tobias&Sebastian Putric",IF(A4="U7","Türkes Ömer&Mahsumi Taha",IF(A4="Camp","Berger Dieter",IF(A4="Turnier","Berger Dieter","FEHLER"))))))))))) | K4: =IF(A4="KM Neufeld","+43 664 415 99 09",IF(A4="U16 LL","+43 650 262 82 63",IF(A4="U15 LL Nord","+43 650 701 02 44",IF(A4="U14 Nord","+43 676 401 09 13",IF(A4="U13 Nord","+43 677 613 55 114 & +43 664 114 43 52",IF(A4="U11 Nord D","+43 664 762 09 93 & +43 699 111 93 828",IF(A4="U9","+43 676 377 16 30 & +43 399 197 871 81",IF(A4="U8","+43 660 199 13 52 & +43 660 914 92 36",IF(A4="U7","+43 676 661 62 26 & +43 681 208 115 99",IF(A4="Camp","+43 660 77 39 500",IF(A4="Turnier","+43 660 77 39 500","FEHLER")))))))))))
A5: =Heimspiele!C6 | B5: =Heimspiele!D6 | D5: =Heimspiele!F6 | E5: =Heimspiele!G6 | F5: Großfeld | G5: =IF(F5="Großfeld","Großfeld",IF(F5="U16","Großfeld",IF(F5="U15","Großfeld",IF(F5="U14","Großfeld",IF(F5="U13","75x55",IF(F5="U11/U12","55x40",IF(F5="U9/U10","40x25",IF(F5="U8","29x22","25x20")))))))) | H5: =IF(F5="Großfeld","7,32x2,44",IF(F5="U16","7,32x2,44",IF(F5="U15","7,32x2,44",IF(F5="U14","7,32x2,44",IF(F5="U13","5x2",IF(F5="U11/U12","5x2",IF(F5="U9/U10","5x2","4 Minitore"))))))) | I5: =IF(F5="Großfeld","5",IF(F5="U16","5",IF(F5="U15","5",IF(F5="U14","4",IF(F5="U13","4",IF(F5="U11/U12","4",IF(F5="U9/U10","4",IF(F5="U9","4","3")))))))) | J5: =IF(A5="KM Neufeld","Pleninger Stefan",IF(A5="U16 LL","Josch Kögl",IF(A5="U15 LL Nord","Serdar Ekinci",IF(A5="U14 Nord","Gernot Servelda",IF(A5="U13 - Nord","Thomas Pöschl & Lenz Honc",IF(A5="U11 Nord D","Mario Magler&Ronny Archam",IF(A5="U9","Thomas Brandl&Daniel Hofbauer",IF(A5="U8","Berger Tobias&Sebastian Putric",IF(A5="U7","Türkes Ömer&Mahsumi Taha",IF(A5="Camp","Berger Dieter",IF(A5="Turnier","Berger Dieter","FEHLER"))))))))))) | K5: =IF(A5="KM Neufeld","+43 664 415 99 09",IF(A5="U16 LL","+43 650 262 82 63",IF(A5="U15 LL Nord","+43 650 701 02 44",IF(A5="U14 - Nord","+43 676 401 09 13",IF(A5="U13 - Nord","+43 677 613 55 114 & +43 664 114 43 52",IF(A5="U11 Nord D","+43 664 762 09 93 & +43 699 111 93 828",IF(A5="U9","+43 676 377 16 30 & +43 399 197 871 81",IF(A5="U8","+43 660 199 13 52 & +43 660 914 92 36",IF(A5="U7","+43 676 661 62 26 & +43 681 208 115 99",IF(A5="Camp","+43 660 77 39 500",IF(A5="Turnier","+43 660 77 39 500","FEHLER")))))))))))
A6: U15 LL Nord | B6: 46096 | C6: 0.45833333 | D6: Neufeld | E6: Freundschaftsspiel Baden | F6: U15 | G6: =IF(F6="Großfeld","Großfeld",IF(F6="U16","Großfeld",IF(F6="U15","Großfeld",IF(F6="U14","Großfeld",IF(F6="U13","75x55",IF(F6="U11/U12","55x40",IF(F6="U9/U10","40x25",IF(F6="U8","29x22","25x20")))))))) | H6: =IF(F6="Großfeld","7,32x2,44",IF(F6="U16","7,32x2,44",IF(F6="U15","7,32x2,44",IF(F6="U14","7,32x2,44",IF(F6="U13","5x2",IF(F6="U11/U12","5x2",IF(F6="U9/U10","5x2",IF(F5="Turnier","5x2","4 Minitore")))))))) | I6: =IF(F6="Großfeld","5",IF(F6="U16","5",IF(F6="U15","5",IF(F6="U14","4",IF(F6="U13","4",IF(F6="U11/U12","4",IF(F6="U9/U10","4",IF(F6="U9","4","3")))))))) | J6: =IF(A6="KM Neufeld","Pleninger Stefan",IF(A6="U16 LL","Josch Kögl",IF(A6="U15 LL Nord","Serdar Ekinci",IF(A6="U14 Nord","Gernot Servelda",IF(A6="U13 Nord","Thomas Pöschl & Lenz Honc",IF(A6="U11 Nord D","Mario Magler&Ronny Archam",IF(A6="U9","Thomas Brandl&Daniel Hofbauer",IF(A6="U8","Berger Tobias&Sebastian Putric",IF(A6="U7","Türkes Ömer&Mahsumi Taha",IF(A6="Camp","Berger Dieter",IF(A6="Turnier","Berger Dieter","FEHLER"))))))))))) | K6: =IF(A6="KM Neufeld","+43 664 415 99 09",IF(A6="U16 LL","+43 650 262 82 63",IF(A6="U15 LL Nord","+43 650 701 02 44",IF(A6="U14 Nord","+43 676 401 09 13",IF(A6="U13 Nord","+43 677 613 55 114 & +43 664 114 43 52",IF(A6="U11 Nord D","+43 664 762 09 93 & +43 699 111 93 828",IF(A6="U9","+43 676 377 16 30 & +43 399 197 871 81",IF(A6="U8","+43 660 199 13 52 & +43 660 914 92 36",IF(A6="U7","+43 676 661 62 26 & +43 681 208 115 99",IF(A6="Camp","+43 660 77 39 500",IF(A6="Turnier","+43 660 77 39 500","FEHLER")))))))))))
A7: =Heimspiele!C8 | B7: =Heimspiele!D8 | D7: =Heimspiele!F8 | E7: =Heimspiele!G8 | F7: Großfeld | G7: =IF(F7="Großfeld","Großfeld",IF(F7="U16","Großfeld",IF(F7="U15","Großfeld",IF(F7="U14","Großfeld",IF(F7="U13","75x55",IF(F7="U11/U12","55x40",IF(F7="U9/U10","40x25",IF(F7="U8","29x22","25x20")))))))) | H7: =IF(F7="Großfeld","7,32x2,44",IF(F7="U16","7,32x2,44",IF(F7="U15","7,32x2,44",IF(F7="U14","7,32x2,44",IF(F7="U13","5x2",IF(F7="U11/U12","5x2",IF(F7="U9/U10","5x2","4 Minitore"))))))) | I7: =IF(F7="Großfeld","5",IF(F7="U16","5",IF(F7="U15","5",IF(F7="U14","4",IF(F7="U13","4",IF(F7="U11/U12","4",IF(F7="U9/U10","4",IF(F7="U9","4","3")))))))) | J7: =IF(A7="KM Neufeld","Pleninger Stefan",IF(A7="U16 LL","Josch Kögl",IF(A7="U15 LL Nord","Serdar Ekinci",IF(A7="U14 Nord","Gernot Servelda",IF(A7="U13 - Nord","Thomas Pöschl & Lenz Honc",IF(A7="U11 Nord D","Mario Magler&Ronny Archam",IF(A7="U9","Thomas Brandl&Daniel Hofbauer",IF(A7="U8","Berger Tobias&Sebastian Putric",IF(A7="U7","Türkes Ömer&Mahsumi Taha",IF(A7="Camp","Berger Dieter",IF(A7="Turnier","Berger Dieter","FEHLER"))))))))))) | K7: =IF(A7="KM Neufeld","+43 664 415 99 09",IF(A7="U16 LL","+43 650 262 82 63",IF(A7="U15 LL Nord","+43 650 701 02 44",IF(A7="U14 - Nord","+43 676 401 09 13",IF(A7="U13 - Nord","+43 677 613 55 114 & +43 664 114 43 52",IF(A7="U11 Nord D","+43 664 762 09 93 & +43 699 111 93 828",IF(A7="U9","+43 676 377 16 30 & +43 399 197 871 81",IF(A7="U8","+43 660 199 13 52 & +43 660 914 92 36",IF(A7="U7","+43 676 661 62 26 & +43 681 208 115 99",IF(A7="Camp","+43 660 77 39 500",IF(A7="Turnier","+43 660 77 39 500","FEHLER")))))))))))
A8: U11 Nord D | B8: 46102 | C8: 0.5 | D8: Neufeld | E8: Freundschaftspiel Pöttsching | F8: U11/U12 | G8: =IF(F8="Großfeld","Großfeld",IF(F8="U16","Großfeld",IF(F8="U15","Großfeld",IF(F8="U14","Großfeld",IF(F8="U13","75x55",IF(F8="U11/U12","55x40",IF(F8="U9/U10","40x25",IF(F8="U8","29x22","25x20")))))))) | H8: =IF(F8="Großfeld","7,32x2,44",IF(F8="U16","7,32x2,44",IF(F8="U15","7,32x2,44",IF(F8="U14","7,32x2,44",IF(F8="U13","5x2",IF(F8="U11/U12","5x2",IF(F8="U9/U10","5x2",IF(F7="Turnier","5x2","4 Minitore")))))))) | I8: =IF(F8="Großfeld","5",IF(F8="U16","5",IF(F8="U15","5",IF(F8="U14","4",IF(F8="U13","4",IF(F8="U11/U12","4",IF(F8="U9/U10","4",IF(F8="U9","4","3")))))))) | J8: =IF(A8="KM Neufeld","Pleninger Stefan",IF(A8="U16 LL","Josch Kögl",IF(A8="U15 LL Nord","Serdar Ekinci",IF(A8="U14 Nord","Gernot Servelda",IF(A8="U13 Nord","Thomas Pöschl & Lenz Honc",IF(A8="U11 Nord D","Mario Magler&Ronny Archam",IF(A8="U9","Thomas Brandl&Daniel Hofbauer",IF(A8="U8","Berger Tobias&Sebastian Putric",IF(A8="U7","Türkes Ömer&Mahsumi Taha",IF(A8="Camp","Berger Dieter",IF(A8="Turnier","Berger Dieter","FEHLER"))))))))))) | K8: =IF(A8="KM Neufeld","+43 664 415 99 09",IF(A8="U16 LL","+43 650 262 82 63",IF(A8="U15 LL Nord","+43 650 701 02 44",IF(A8="U14 Nord","+43 676 401 09 13",IF(A8="U13 Nord","+43 677 613 55 114 & +43 664 114 43 52",IF(A8="U11 Nord D","+43 664 762 09 93 & +43 699 111 93 828",IF(A8="U9","+43 676 377 16 30 & +43 399 197 871 81",IF(A8="U8","+43 660 199 13 52 & +43 660 914 92 36",IF(A8="U7","+43 676 661 62 26 & +43 681 208 115 99",IF(A8="Camp","+43 660 77 39 500",IF(A8="Turnier","+43 660 77 39 500","FEHLER")))))))))))
A9: =Heimspiele!C10 | B9: =Heimspiele!D10 | D9: =Heimspiele!F10 | E9: =Heimspiele!G10 | F9: Großfeld | G9: =IF(F9="Großfeld","Großfeld",IF(F9="U16","Großfeld",IF(F9="U15","Großfeld",IF(F9="U14","Großfeld",IF(F9="U13","75x55",IF(F9="U11/U12","55x40",IF(F9="U9/U10","40x25",IF(F9="U8","29x22","25x20")))))))) | H9: =IF(F9="Großfeld","7,32x2,44",IF(F9="U16","7,32x2,44",IF(F9="U15","7,32x2,44",IF(F9="U14","7,32x2,44",IF(F9="U13","5x2",IF(F9="U11/U12","5x2",IF(F9="U9/U10","5x2","4 Minitore"))))))) | I9: =IF(F9="Großfeld","5",IF(F9="U16","5",IF(F9="U15","5",IF(F9="U14","4",IF(F9="U13","4",IF(F9="U11/U12","4",IF(F9="U9/U10","4",IF(F9="U9","4","3")))))))) | J9: =IF(A9="KM Neufeld","Pleninger Stefan",IF(A9="U16 LL","Josch Kögl",IF(A9="U15 LL Nord","Serdar Ekinci",IF(A9="U14 Nord","Gernot Servelda",IF(A9="U13 - Nord","Thomas Pöschl & Lenz Honc",IF(A9="U11 Nord D","Mario Magler&Ronny Archam",IF(A9="U9","Thomas Brandl&Daniel Hofbauer",IF(A9="U8","Berger Tobias&Sebastian Putric",IF(A9="U7","Türkes Ömer&Mahsumi Taha",IF(A9="Camp","Berger Dieter",IF(A9="Turnier","Berger Dieter","FEHLER"))))))))))) | K9: =IF(A9="KM Neufeld","+43 664 415 99 09",IF(A9="U16 LL","+43 650 262 82 63",IF(A9="U15 LL Nord","+43 650 701 02 44",IF(A9="U14 - Nord","+43 676 401 09 13",IF(A9="U13 - Nord","+43 677 613 55 114 & +43 664 114 43 52",IF(A9="U11 Nord D","+43 664 762 09 93 & +43 699 111 93 828",IF(A9="U9","+43 676 377 16 30 & +43 399 197 871 81",IF(A9="U8","+43 660 199 13 52 & +43 660 914 92 36",IF(A9="U7","+43 676 661 62 26 & +43 681 208 115 99",IF(A9="Camp","+43 660 77 39 500",IF(A9="Turnier","+43 660 77 39 500","FEHLER")))))))))))
A10: =Heimspiele!C3 | B10: =Heimspiele!D3 | C10: =Heimspiele!E3 | D10: =Heimspiele!F3 | E10: =Heimspiele!G3 | F10: Großfeld | G10: =IF(F10="Großfeld","Großfeld",IF(F10="U16","Großfeld",IF(F10="U15","Großfeld",IF(F10="U14","Großfeld",IF(F10="U13","75x55",IF(F10="U11/U12","55x40",IF(F10="U9/U10","40x25",IF(F10="U8","29x22","25x20")))))))) | H10: =IF(F10="Großfeld","7,32x2,44",IF(F10="U16","7,32x2,44",IF(F10="U15","7,32x2,44",IF(F10="U14","7,32x2,44",IF(F10="U13","5x2",IF(F10="U11/U12","5x2",IF(F10="U9/U10","5x2","4 Minitore"))))))) | I10: =IF(F10="Großfeld","5",IF(F10="U16","5",IF(F10="U15","5",IF(F10="U14","4",IF(F10="U13","4",IF(F10="U11/U12","4",IF(F10="U9/U10","4",IF(F10="U9","4","3")))))))) | J10: =IF(A10="KM Neufeld","Pleninger Stefan",IF(A10="U16 LL","Josch Kögl",IF(A10="U15 LL Nord","Serdar Ekinci",IF(A10="U14 Nord","Gernot Servelda",IF(A10="U13 Nord","Thomas Pöschl & Lenz Honc",IF(A10="U11 Nord D","Mario Magler&Ronny Archam",IF(A10="U9","Thomas Brandl&Daniel Hofbauer",IF(A10="U8","Berger Tobias&Sebastian Putric",IF(A10="U7","Türkes Ömer&Mahsumi Taha",IF(A10="Camp","Berger Dieter",IF(A10="Turnier","Berger Dieter","FEHLER"))))))))))) | K10: =IF(A10="KM Neufeld","+43 664 415 99 09",IF(A10="U16 LL","+43 650 262 82 63",IF(A10="U15 LL Nord","+43 650 701 02 44",IF(A10="U14 Nord","+43 676 401 09 13",IF(A10="U13 Nord","+43 677 613 55 114 & +43 664 114 43 52",IF(A10="U11 Nord D","+43 664 762 09 93 & +43 699 111 93 828",IF(A10="U9","+43 676 377 16 30 & +43 399 197 871 81",IF(A10="U8","+43 660 199 13 52 & +43 660 914 92 36",IF(A10="U7","+43 676 661 62 26 & +43 681 208 115 99",IF(A10="Camp","+43 660 77 39 500",IF(A10="Turnier","+43 660 77 39 500","FEHLER")))))))))))
A11: =Heimspiele!C12 | B11: =Heimspiele!D12 | D11: =Heimspiele!F12 | E11: =Heimspiele!G12 | F11: Großfeld | G11: =IF(F11="Großfeld","Großfeld",IF(F11="U16","Großfeld",IF(F11="U15","Großfeld",IF(F11="U14","Großfeld",IF(F11="U13","75x55",IF(F11="U11/U12","55x40",IF(F11="U9/U10","40x25",IF(F11="U8","29x22","25x20")))))))) | H11: =IF(F11="Großfeld","7,32x2,44",IF(F11="U16","7,32x2,44",IF(F11="U15","7,32x2,44",IF(F11="U14","7,32x2,44",IF(F11="U13","5x2",IF(F11="U11/U12","5x2",IF(F11="U9/U10","5x2","4 Minitore"))))))) | I11: =IF(F11="Großfeld","5",IF(F11="U16","5",IF(F11="U15","5",IF(F11="U14","4",IF(F11="U13","4",IF(F11="U11/U12","4",IF(F11="U9/U10","4",IF(F11="U9","4","3")))))))) | J11: =IF(A11="KM Neufeld","Pleninger Stefan",IF(A11="U16 LL","Josch Kögl",IF(A11="U15 LL Nord","Serdar Ekinci",IF(A11="U14 Nord","Gernot Servelda",IF(A11="U13 - Nord","Thomas Pöschl & Lenz Honc",IF(A11="U11 Nord D","Mario Magler&Ronny Archam",IF(A11="U9","Thomas Brandl&Daniel Hofbauer",IF(A11="U8","Berger Tobias&Sebastian Putric",IF(A11="U7","Türkes Ömer&Mahsumi Taha",IF(A11="Camp","Berger Dieter",IF(A11="Turnier","Berger Dieter","FEHLER"))))))))))) | K11: =IF(A11="KM Neufeld","+43 664 415 99 09",IF(A11="U16 LL","+43 650 262 82 63",IF(A11="U15 LL Nord","+43 650 701 02 44",IF(A11="U14 - Nord","+43 676 401 09 13",IF(A11="U13 - Nord","+43 677 613 55 114 & +43 664 114 43 52",IF(A11="U11 Nord D","+43 664 762 09 93 & +43 699 111 93 828",IF(A11="U9","+43 676 377 16 30 & +43 399 197 871 81",IF(A11="U8","+43 660 199 13 52 & +43 660 914 92 36",IF(A11="U7","+43 676 661 62 26 & +43 681 208 115 99",IF(A11="Camp","+43 660 77 39 500",IF(A11="Turnier","+43 660 77 39 500","FEHLER")))))))))))
A12: =Heimspiele!C13 | B12: =Heimspiele!D13 | D12: =Heimspiele!F13 | E12: =Heimspiele!G13 | F12: Großfeld | G12: =IF(F12="Großfeld","Großfeld",IF(F12="U16","Großfeld",IF(F12="U15","Großfeld",IF(F12="U14","Großfeld",IF(F12="U13","75x55",IF(F12="U11/U12","55x40",IF(F12="U9/U10","40x25",IF(F12="U8","29x22","25x20")))))))) | H12: =IF(F12="Großfeld","7,32x2,44",IF(F12="U16","7,32x2,44",IF(F12="U15","7,32x2,44",IF(F12="U14","7,32x2,44",IF(F12="U13","5x2",IF(F12="U11/U12","5x2",IF(F12="U9/U10","5x2","4 Minitore"))))))) | I12: =IF(F12="Großfeld","5",IF(F12="U16","5",IF(F12="U15","5",IF(F12="U14","4",IF(F12="U13","4",IF(F12="U11/U12","4",IF(F12="U9/U10","4",IF(F12="U9","4","3")))))))) | J12: =IF(A12="KM Neufeld","Pleninger Stefan",IF(A12="U16 LL","Josch Kögl",IF(A12="U15 LL Nord","Serdar Ekinci",IF(A12="U14 Nord","Gernot Servelda",IF(A12="U13 - Nord","Thomas Pöschl & Lenz Honc",IF(A12="U11 Nord D","Mario Magler&Ronny Archam",IF(A12="U9","Thomas Brandl&Daniel Hofbauer",IF(A12="U8","Berger Tobias&Sebastian Putric",IF(A12="U7","Türkes Ömer&Mahsumi Taha",IF(A12="Camp","Berger Dieter",IF(A12="Turnier","Berger Dieter","FEHLER"))))))))))) | K12: =IF(A12="KM Neufeld","+43 664 415 99 09",IF(A12="U16 LL","+43 650 262 82 63",IF(A12="U15 LL Nord","+43 650 701 02 44",IF(A12="U14 - Nord","+43 676 401 09 13",IF(A12="U13 - Nord","+43 677 613 55 114 & +43 664 114 43 52",IF(A12="U11 Nord D","+43 664 762 09 93 & +43 699 111 93 828",IF(A12="U9","+43 676 377 16 30 & +43 399 197 871 81",IF(A12="U8","+43 660 199 13 52 & +43 660 914 92 36",IF(A12="U7","+43 676 661 62 26 & +43 681 208 115 99",IF(A12="Camp","+43 660 77 39 500",IF(A12="Turnier","+43 660 77 39 500","FEHLER")))))))))))
A13: =Heimspiele!C5 | B13: =Heimspiele!D5 | C13: =Heimspiele!E5 | D13: =Heimspiele!F5 | E13: =Heimspiele!G5 | F13: U14 | G13: =IF(F13="Großfeld","Großfeld",IF(F13="U16","Großfeld",IF(F13="U15","Großfeld",IF(F13="U14","Großfeld",IF(F13="U13","75x55",IF(F13="U11/U12","55x40",IF(F13="U9/U10","40x25",IF(F13="U8","29x22","25x20")))))))) | H13: =IF(F13="Großfeld","7,32x2,44",IF(F13="U16","7,32x2,44",IF(F13="U15","7,32x2,44",IF(F13="U14","7,32x2,44",IF(F13="U13","5x2",IF(F13="U11/U12","5x2",IF(F13="U9/U10","5x2","4 Minitore"))))))) | I13: =IF(F13="Großfeld","5",IF(F13="U16","5",IF(F13="U15","5",IF(F13="U14","4",IF(F13="U13","4",IF(F13="U11/U12","4",IF(F13="U9/U10","4",IF(F13="U9","4","3")))))))) | J13: =IF(A13="KM Neufeld","Pleninger Stefan",IF(A13="U16 LL","Josch Kögl",IF(A13="U15 LL Nord","Serdar Ekinci",IF(A13="U14 Nord","Gernot Servelda",IF(A13="U13 Nord","Thomas Pöschl & Lenz Honc",IF(A13="U11 Nord D","Mario Magler&Ronny Archam",IF(A13="U9","Thomas Brandl&Daniel Hofbauer",IF(A13="U8","Berger Tobias&Sebastian Putric",IF(A13="U7","Türkes Ömer&Mahsumi Taha",IF(A13="Camp","Berger Dieter",IF(A13="Turnier","Berger Dieter","FEHLER"))))))))))) | K13: =IF(A13="KM Neufeld","+43 664 415 99 09",IF(A13="U16 LL","+43 650 262 82 63",IF(A13="U15 LL Nord","+43 650 701 02 44",IF(A13="U14 Nord","+43 676 401 09 13",IF(A13="U13 Nord","+43 677 613 55 114 & +43 664 114 43 52",IF(A13="U11 Nord D","+43 664 762 09 93 & +43 699 111 93 828",IF(A13="U9","+43 676 377 16 30 & +43 399 197 871 81",IF(A13="U8","+43 660 199 13 52 & +43 660 914 92 36",IF(A13="U7","+43 676 661 62 26 & +43 681 208 115 99",IF(A13="Camp","+43 660 77 39 500",IF(A13="Turnier","+43 660 77 39 500","FEHLER")))))))))))
A14: =Heimspiele!C15 | B14: =Heimspiele!D15 | D14: =Heimspiele!F15 | E14: =Heimspiele!G15 | F14: Großfeld | G14: =IF(F14="Großfeld","Großfeld",IF(F14="U16","Großfeld",IF(F14="U15","Großfeld",IF(F14="U14","Großfeld",IF(F14="U13","75x55",IF(F14="U11/U12","55x40",IF(F14="U9/U10","40x25",IF(F14="U8","29x22","25x20")))))))) | H14: =IF(F14="Großfeld","7,32x2,44",IF(F14="U16","7,32x2,44",IF(F14="U15","7,32x2,44",IF(F14="U14","7,32x2,44",IF(F14="U13","5x2",IF(F14="U11/U12","5x2",IF(F14="U9/U10","5x2","4 Minitore"))))))) | I14: =IF(F14="Großfeld","5",IF(F14="U16","5",IF(F14="U15","5",IF(F14="U14","4",IF(F14="U13","4",IF(F14="U11/U12","4",IF(F14="U9/U10","4",IF(F14="U9","4","3")))))))) | J14: =IF(A14="KM Neufeld","Pleninger Stefan",IF(A14="U16 LL","Josch Kögl",IF(A14="U15 LL Nord","Serdar Ekinci",IF(A14="U14 Nord","Gernot Servelda",IF(A14="U13 - Nord","Thomas Pöschl & Lenz Honc",IF(A14="U11 Nord D","Mario Magler&Ronny Archam",IF(A14="U9","Thomas Brandl&Daniel Hofbauer",IF(A14="U8","Berger Tobias&Sebastian Putric",IF(A14="U7","Türkes Ömer&Mahsumi Taha",IF(A14="Camp","Berger Dieter",IF(A14="Turnier","Berger Dieter","FEHLER"))))))))))) | K14: =IF(A14="KM Neufeld","+43 664 415 99 09",IF(A14="U16 LL","+43 650 262 82 63",IF(A14="U15 LL Nord","+43 650 701 02 44",IF(A14="U14 - Nord","+43 676 401 09 13",IF(A14="U13 - Nord","+43 677 613 55 114 & +43 664 114 43 52",IF(A14="U11 Nord D","+43 664 762 09 93 & +43 699 111 93 828",IF(A14="U9","+43 676 377 16 30 & +43 399 197 871 81",IF(A14="U8","+43 660 199 13 52 & +43 660 914 92 36",IF(A14="U7","+43 676 661 62 26 & +43 681 208 115 99",IF(A14="Camp","+43 660 77 39 500",IF(A14="Turnier","+43 660 77 39 500","FEHLER")))))))))))
A15: =Heimspiele!C16 | B15: =Heimspiele!D16 | D15: =Heimspiele!F16 | E15: =Heimspiele!G16 | F15: Großfeld | G15: =IF(F15="Großfeld","Großfeld",IF(F15="U16","Großfeld",IF(F15="U15","Großfeld",IF(F15="U14","Großfeld",IF(F15="U13","75x55",IF(F15="U11/U12","55x40",IF(F15="U9/U10","40x25",IF(F15="U8","29x22","25x20")))))))) | H15: =IF(F15="Großfeld","7,32x2,44",IF(F15="U16","7,32x2,44",IF(F15="U15","7,32x2,44",IF(F15="U14","7,32x2,44",IF(F15="U13","5x2",IF(F15="U11/U12","5x2",IF(F15="U9/U10","5x2","4 Minitore"))))))) | I15: =IF(F15="Großfeld","5",IF(F15="U16","5",IF(F15="U15","5",IF(F15="U14","4",IF(F15="U13","4",IF(F15="U11/U12","4",IF(F15="U9/U10","4",IF(F15="U9","4","3")))))))) | J15: =IF(A15="KM Neufeld","Pleninger Stefan",IF(A15="U16 LL","Josch Kögl",IF(A15="U15 LL Nord","Serdar Ekinci",IF(A15="U14 Nord","Gernot Servelda",IF(A15="U13 - Nord","Thomas Pöschl & Lenz Honc",IF(A15="U11 Nord D","Mario Magler&Ronny Archam",IF(A15="U9","Thomas Brandl&Daniel Hofbauer",IF(A15="U8","Berger Tobias&Sebastian Putric",IF(A15="U7","Türkes Ömer&Mahsumi Taha",IF(A15="Camp","Berger Dieter",IF(A15="Turnier","Berger Dieter","FEHLER"))))))))))) | K15: =IF(A15="KM Neufeld","+43 664 415 99 09",IF(A15="U16 LL","+43 650 262 82 63",IF(A15="U15 LL Nord","+43 650 701 02 44",IF(A15="U14 - Nord","+43 676 401 09 13",IF(A15="U13 - Nord","+43 677 613 55 114 & +43 664 114 43 52",IF(A15="U11 Nord D","+43 664 762 09 93 & +43 699 111 93 828",IF(A15="U9","+43 676 377 16 30 & +43 399 197 871 81",IF(A15="U8","+43 660 199 13 52 & +43 660 914 92 36",IF(A15="U7","+43 676 661 62 26 & +43 681 208 115 99",IF(A15="Camp","+43 660 77 39 500",IF(A15="Turnier","+43 660 77 39 500","FEHLER")))))))))))
A16: =Heimspiele!C17 | B16: =Heimspiele!D17 | D16: =Heimspiele!F17 | E16: =Heimspiele!G17 | F16: Großfeld | G16: =IF(F16="Großfeld","Großfeld",IF(F16="U16","Großfeld",IF(F16="U15","Großfeld",IF(F16="U14","Großfeld",IF(F16="U13","75x55",IF(F16="U11/U12","55x40",IF(F16="U9/U10","40x25",IF(F16="U8","29x22","25x20")))))))) | H16: =IF(F16="Großfeld","7,32x2,44",IF(F16="U16","7,32x2,44",IF(F16="U15","7,32x2,44",IF(F16="U14","7,32x2,44",IF(F16="U13","5x2",IF(F16="U11/U12","5x2",IF(F16="U9/U10","5x2","4 Minitore"))))))) | I16: =IF(F16="Großfeld","5",IF(F16="U16","5",IF(F16="U15","5",IF(F16="U14","4",IF(F16="U13","4",IF(F16="U11/U12","4",IF(F16="U9/U10","4",IF(F16="U9","4","3")))))))) | J16: =IF(A16="KM Neufeld","Pleninger Stefan",IF(A16="U16 LL","Josch Kögl",IF(A16="U15 LL Nord","Serdar Ekinci",IF(A16="U14 Nord","Gernot Servelda",IF(A16="U13 - Nord","Thomas Pöschl & Lenz Honc",IF(A16="U11 Nord D","Mario Magler&Ronny Archam",IF(A16="U9","Thomas Brandl&Daniel Hofbauer",IF(A16="U8","Berger Tobias&Sebastian Putric",IF(A16="U7","Türkes Ömer&Mahsumi Taha",IF(A16="Camp","Berger Dieter",IF(A16="Turnier","Berger Dieter","FEHLER"))))))))))) | K16: =IF(A16="KM Neufeld","+43 664 415 99 09",IF(A16="U16 LL","+43 650 262 82 63",IF(A16="U15 LL Nord","+43 650 701 02 44",IF(A16="U14 - Nord","+43 676 401 09 13",IF(A16="U13 - Nord","+43 677 613 55 114 & +43 664 114 43 52",IF(A16="U11 Nord D","+43 664 762 09 93 & +43 699 111 93 828",IF(A16="U9","+43 676 377 16 30 & +43 399 197 871 81",IF(A16="U8","+43 660 199 13 52 & +43 660 914 92 36",IF(A16="U7","+43 676 661 62 26 & +43 681 208 115 99",IF(A16="Camp","+43 660 77 39 500",IF(A16="Turnier","+43 660 77 39 500","FEHLER")))))))))))
A17: =Heimspiele!C7 | B17: =Heimspiele!D7 | C17: =Heimspiele!E7 | D17: =Heimspiele!F7 | E17: =Heimspiele!G7 | F17: U13 | G17: =IF(F17="Großfeld","Großfeld",IF(F17="U16","Großfeld",IF(F17="U15","Großfeld",IF(F17="U14","Großfeld",IF(F17="U13","75x55",IF(F17="U11/U12","55x40",IF(F17="U9/U10","40x25",IF(F17="U8","29x22","25x20")))))))) | H17: =IF(F17="Großfeld","7,32x2,44",IF(F17="U16","7,32x2,44",IF(F17="U15","7,32x2,44",IF(F17="U14","7,32x2,44",IF(F17="U13","5x2",IF(F17="U11/U12","5x2",IF(F17="U9/U10","5x2","4 Minitore"))))))) | I17: =IF(F17="Großfeld","5",IF(F17="U16","5",IF(F17="U15","5",IF(F17="U14","4",IF(F17="U13","4",IF(F17="U11/U12","4",IF(F17="U9/U10","4",IF(F17="U9","4","3")))))))) | J17: =IF(A17="KM Neufeld","Pleninger Stefan",IF(A17="U16 LL","Josch Kögl",IF(A17="U15 LL Nord","Serdar Ekinci",IF(A17="U14 Nord","Gernot Servelda",IF(A17="U13 Nord","Thomas Pöschl & Lenz Honc",IF(A17="U11 Nord D","Mario Magler&Ronny Archam",IF(A17="U9","Thomas Brandl&Daniel Hofbauer",IF(A17="U8","Berger Tobias&Sebastian Putric",IF(A17="U7","Türkes Ömer&Mahsumi Taha",IF(A17="Camp","Berger Dieter",IF(A17="Turnier","Berger Dieter","FEHLER"))))))))))) | K17: =IF(A17="KM Neufeld","+43 664 415 99 09",IF(A17="U16 LL","+43 650 262 82 63",IF(A17="U15 LL Nord","+43 650 701 02 44",IF(A17="U14 Nord","+43 676 401 09 13",IF(A17="U13 Nord","+43 677 613 55 114 & +43 664 114 43 52",IF(A17="U11 Nord D","+43 664 762 09 93 & +43 699 111 93 828",IF(A17="U9","+43 676 377 16 30 & +43 399 197 871 81",IF(A17="U8","+43 660 199 13 52 & +43 660 914 92 36",IF(A17="U7","+43 676 661 62 26 & +43 681 208 115 99",IF(A17="Camp","+43 660 77 39 500",IF(A17="Turnier","+43 660 77 39 500","FEHLER")))))))))))
A18: =Heimspiele!C19 | B18: =Heimspiele!D19 | D18: =Heimspiele!F19 | E18: =Heimspiele!G19 | F18: Großfeld | G18: =IF(F18="Großfeld","Großfeld",IF(F18="U16","Großfeld",IF(F18="U15","Großfeld",IF(F18="U14","Großfeld",IF(F18="U13","75x55",IF(F18="U11/U12","55x40",IF(F18="U9/U10","40x25",IF(F18="U8","29x22","25x20")))))))) | H18: =IF(F18="Großfeld","7,32x2,44",IF(F18="U16","7,32x2,44",IF(F18="U15","7,32x2,44",IF(F18="U14","7,32x2,44",IF(F18="U13","5x2",IF(F18="U11/U12","5x2",IF(F18="U9/U10","5x2","4 Minitore"))))))) | I18: =IF(F18="Großfeld","5",IF(F18="U16","5",IF(F18="U15","5",IF(F18="U14","4",IF(F18="U13","4",IF(F18="U11/U12","4",IF(F18="U9/U10","4",IF(F18="U9","4","3")))))))) | J18: =IF(A18="KM Neufeld","Pleninger Stefan",IF(A18="U16 LL","Josch Kögl",IF(A18="U15 LL Nord","Serdar Ekinci",IF(A18="U14 Nord","Gernot Servelda",IF(A18="U13 - Nord","Thomas Pöschl & Lenz Honc",IF(A18="U11 Nord D","Mario Magler&Ronny Archam",IF(A18="U9","Thomas Brandl&Daniel Hofbauer",IF(A18="U8","Berger Tobias&Sebastian Putric",IF(A18="U7","Türkes Ömer&Mahsumi Taha",IF(A18="Camp","Berger Dieter",IF(A18="Turnier","Berger Dieter","FEHLER"))))))))))) | K18: =IF(A18="KM Neufeld","+43 664 415 99 09",IF(A18="U16 LL","+43 650 262 82 63",IF(A18="U15 LL Nord","+43 650 701 02 44",IF(A18="U14 - Nord","+43 676 401 09 13",IF(A18="U13 - Nord","+43 677 613 55 114 & +43 664 114 43 52",IF(A18="U11 Nord D","+43 664 762 09 93 & +43 699 111 93 828",IF(A18="U9","+43 676 377 16 30 & +43 399 197 871 81",IF(A18="U8","+43 660 199 13 52 & +43 660 914 92 36",IF(A18="U7","+43 676 661 62 26 & +43 681 208 115 99",IF(A18="Camp","+43 660 77 39 500",IF(A18="Turnier","+43 660 77 39 500","FEHLER")))))))))))
A19: =Heimspiele!C20 | B19: =Heimspiele!D20 | D19: =Heimspiele!F20 | E19: =Heimspiele!G20 | F19: Großfeld | G19: =IF(F19="Großfeld","Großfeld",IF(F19="U16","Großfeld",IF(F19="U15","Großfeld",IF(F19="U14","Großfeld",IF(F19="U13","75x55",IF(F19="U11/U12","55x40",IF(F19="U9/U10","40x25",IF(F19="U8","29x22","25x20")))))))) | H19: =IF(F19="Großfeld","7,32x2,44",IF(F19="U16","7,32x2,44",IF(F19="U15","7,32x2,44",IF(F19="U14","7,32x2,44",IF(F19="U13","5x2",IF(F19="U11/U12","5x2",IF(F19="U9/U10","5x2","4 Minitore"))))))) | I19: =IF(F19="Großfeld","5",IF(F19="U16","5",IF(F19="U15","5",IF(F19="U14","4",IF(F19="U13","4",IF(F19="U11/U12","4",IF(F19="U9/U10","4",IF(F19="U9","4","3")))))))) | J19: =IF(A19="KM Neufeld","Pleninger Stefan",IF(A19="U16 LL","Josch Kögl",IF(A19="U15 LL Nord","Serdar Ekinci",IF(A19="U14 Nord","Gernot Servelda",IF(A19="U13 - Nord","Thomas Pöschl & Lenz Honc",IF(A19="U11 Nord D","Mario Magler&Ronny Archam",IF(A19="U9","Thomas Brandl&Daniel Hofbauer",IF(A19="U8","Berger Tobias&Sebastian Putric",IF(A19="U7","Türkes Ömer&Mahsumi Taha",IF(A19="Camp","Berger Dieter",IF(A19="Turnier","Berger Dieter","FEHLER"))))))))))) | K19: =IF(A19="KM Neufeld","+43 664 415 99 09",IF(A19="U16 LL","+43 650 262 82 63",IF(A19="U15 LL Nord","+43 650 701 02 44",IF(A19="U14 - Nord","+43 676 401 09 13",IF(A19="U13 - Nord","+43 677 613 55 114 & +43 664 114 43 52",IF(A19="U11 Nord D","+43 664 762 09 93 & +43 699 111 93 828",IF(A19="U9","+43 676 377 16 30 & +43 399 197 871 81",IF(A19="U8","+43 660 199 13 52 & +43 660 914 92 36",IF(A19="U7","+43 676 661 62 26 & +43 681 208 115 99",IF(A19="Camp","+43 660 77 39 500",IF(A19="Turnier","+43 660 77 39 500","FEHLER")))))))))))
A20: =Heimspiele!C21 | B20: =Heimspiele!D21 | D20: =Heimspiele!F21 | E20: =Heimspiele!G21 | F20: Großfeld | G20: =IF(F20="Großfeld","Großfeld",IF(F20="U16","Großfeld",IF(F20="U15","Großfeld",IF(F20="U14","Großfeld",IF(F20="U13","75x55",IF(F20="U11/U12","55x40",IF(F20="U9/U10","40x25",IF(F20="U8","29x22","25x20")))))))) | H20: =IF(F20="Großfeld","7,32x2,44",IF(F20="U16","7,32x2,44",IF(F20="U15","7,32x2,44",IF(F20="U14","7,32x2,44",IF(F20="U13","5x2",IF(F20="U11/U12","5x2",IF(F20="U9/U10","5x2","4 Minitore"))))))) | I20: =IF(F20="Großfeld","5",IF(F20="U16","5",IF(F20="U15","5",IF(F20="U14","4",IF(F20="U13","4",IF(F20="U11/U12","4",IF(F20="U9/U10","4",IF(F20="U9","4","3")))))))) | J20: =IF(A20="KM Neufeld","Pleninger Stefan",IF(A20="U16 LL","Josch Kögl",IF(A20="U15 LL Nord","Serdar Ekinci",IF(A20="U14 Nord","Gernot Servelda",IF(A20="U13 - Nord","Thomas Pöschl & Lenz Honc",IF(A20="U11 Nord D","Mario Magler&Ronny Archam",IF(A20="U9","Thomas Brandl&Daniel Hofbauer",IF(A20="U8","Berger Tobias&Sebastian Putric",IF(A20="U7","Türkes Ömer&Mahsumi Taha",IF(A20="Camp","Berger Dieter",IF(A20="Turnier","Berger Dieter","FEHLER"))))))))))) | K20: =IF(A20="KM Neufeld","+43 664 415 99 09",IF(A20="U16 LL","+43 650 262 82 63",IF(A20="U15 LL Nord","+43 650 701 02 44",IF(A20="U14 - Nord","+43 676 401 09 13",IF(A20="U13 - Nord","+43 677 613 55 114 & +43 664 114 43 52",IF(A20="U11 Nord D","+43 664 762 09 93 & +43 699 111 93 828",IF(A20="U9","+43 676 377 16 30 & +43 399 197 871 81",IF(A20="U8","+43 660 199 13 52 & +43 660 914 92 36",IF(A20="U7","+43 676 661 62 26 & +43 681 208 115 99",IF(A20="Camp","+43 660 77 39 500",IF(A20="Turnier","+43 660 77 39 500","FEHLER")))))))))))
A21: =Heimspiele!C22 | B21: =Heimspiele!D22 | D21: =Heimspiele!F22 | E21: =Heimspiele!G22 | F21: Großfeld | G21: =IF(F21="Großfeld","Großfeld",IF(F21="U16","Großfeld",IF(F21="U15","Großfeld",IF(F21="U14","Großfeld",IF(F21="U13","75x55",IF(F21="U11/U12","55x40",IF(F21="U9/U10","40x25",IF(F21="U8","29x22","25x20")))))))) | H21: =IF(F21="Großfeld","7,32x2,44",IF(F21="U16","7,32x2,44",IF(F21="U15","7,32x2,44",IF(F21="U14","7,32x2,44",IF(F21="U13","5x2",IF(F21="U11/U12","5x2",IF(F21="U9/U10","5x2","4 Minitore"))))))) | I21: =IF(F21="Großfeld","5",IF(F21="U16","5",IF(F21="U15","5",IF(F21="U14","4",IF(F21="U13","4",IF(F21="U11/U12","4",IF(F21="U9/U10","4",IF(F21="U9","4","3")))))))) | J21: =IF(A21="KM Neufeld","Pleninger Stefan",IF(A21="U16 LL","Josch Kögl",IF(A21="U15 LL Nord","Serdar Ekinci",IF(A21="U14 Nord","Gernot Servelda",IF(A21="U13 - Nord","Thomas Pöschl & Lenz Honc",IF(A21="U11 Nord D","Mario Magler&Ronny Archam",IF(A21="U9","Thomas Brandl&Daniel Hofbauer",IF(A21="U8","Berger Tobias&Sebastian Putric",IF(A21="U7","Türkes Ömer&Mahsumi Taha",IF(A21="Camp","Berger Dieter",IF(A21="Turnier","Berger Dieter","FEHLER"))))))))))) | K21: =IF(A21="KM Neufeld","+43 664 415 99 09",IF(A21="U16 LL","+43 650 262 82 63",IF(A21="U15 LL Nord","+43 650 701 02 44",IF(A21="U14 - Nord","+43 676 401 09 13",IF(A21="U13 - Nord","+43 677 613 55 114 & +43 664 114 43 52",IF(A21="U11 Nord D","+43 664 762 09 93 & +43 699 111 93 828",IF(A21="U9","+43 676 377 16 30 & +43 399 197 871 81",IF(A21="U8","+43 660 199 13 52 & +43 660 914 92 36",IF(A21="U7","+43 676 661 62 26 & +43 681 208 115 99",IF(A21="Camp","+43 660 77 39 500",IF(A21="Turnier","+43 660 77 39 500","FEHLER")))))))))))
