Workbook

Sheet Nach Mannschaften sortiert
A1: fortlaufende Nummer | B1: Runde | C1: Mannschaft | D1: fixierter Termin | E1: fixierte Uhrzeit | F1: Ort | G1: Gegner | H1: Auswärt/Heim
A2: 1 | B2: 0 | C2: U15 | D2: 46199 | E2: 0.66666667 | F2: Wimpassing | G2: SK Rapid Wien | H2: Heim
A3: =A2+1 -> 2 | B3: 0 | C3: U16 | D3: 46199 | E3: 0.75 | F3: Wimpassing | G3: SK Rapid Wien | H3: Heim
A4: =A3+1 -> 3 | B4: 0 | C4: KM | D4: 46213 | E4: 0.79166667 | F4: Neudörfl | G4: Neudörfl | H4: Auswärts
A5: =A4+1 -> 4 | B5: 0 | C5: KM | D5: 46220 | E5: 0.79166667 | F5: Rohbach | G5: Rohrbach | H5: Auswärts
A6: =A5+1 -> 5 | B6: 0 | C6: KM | D6: 46235 | E6: 0.72916667 | F6: Kittsee | G6: Kittsee | H6: Auswärts
A7: =A6+1 -> 6 | B7: 0 | C7: KM | D7: 46241 | E7: 0.79166667 | F7: Neufeld | G7: Bad Fischau | H7: Heim
A8: =A7+1 -> 7 | B8: 0 | C8: U16 | D8: 46243 | E8: 0.45833333 | F8: Wiener Neudorf | G8: Wiener Neudorf | H8: Auswärts
A9: =A8+1 -> 8 | B9: 1 | C9: KM | D9: 46249 | E9: 0.72916667 | F9: Kittsee | G9: Kittsee | H9: Auswärts
A10: =A9+1 -> 9 | B10: 2 | C10: KM | D10: 46256 | E10: 0.70833333 | F10: Deutsch Jahrndorf | G10: Deutsch Jahrndorf | H10: Auswärts
A11: =A10+1 -> 10 | B11: 3 | C11: KM | D11: 46263 | E11: 0.70833333 | F11: Neufeld | G11: Tadten | H11: Heim
A12: =A11+1 -> 11 | B12: 4 | C12: KM | D12: 46270 | E12: 0.6875 | F12: Mönchhof | G12: Mönchhof | H12: Auswärts
A13: =A12+1 -> 12 | B13: 5 | C13: KM | D13: 46277 | E13: 0.6875 | F13: Neufeld | G13: Winden | H13: Heim
A14: =A13+1 -> 13 | B14: 6 | C14: KM | D14: 46284 | E14: 0.66666667 | F14: Gattendorf | G14: Gattendorf | H14: Auswärts
... A34: =A33+1 -> 33 | B34: 13 | C34: U23 | D34: 46333 | E34: 0.5 | F34: Neufeld | G34: Andau | H34: Heim
A35: =A34+1 -> 34 | B35: 1 | C35: U16 | D35: 46023
A36: =A35+1 -> 35 | B36: 2 | C36: U16 | D36: 46024
A37: =A36+1 -> 36 | B37: 3 | C37: U16 | D37: 46025
A38: =A37+1 -> 37 | B38: 4 | C38: U16 | D38: 46026
A39: =A38+1 -> 38 | B39: 5 | C39: U16 | D39: 46027
A40: =A39+1 -> 39 | B40: 6 | C40: U16 | D40: 46028
A41: =A40+1 -> 40 | B41: 7 | C41: U16 | D41: 46029
A42: =A41+1 -> 41 | B42: 8 | C42: U16 | D42: 46030
A43: =A42+1 -> 42 | B43: 9 | C43: U16 | D43: 46031
A44: =A43+1 -> 43 | B44: 10 | C44: U16 | D44: 46032
A45: =A44+1 -> 44 | B45: 1 | C45: U14 | D45: 46033
A46: =A45+1 -> 45 | B46: 2 | C46: U14 | D46: 46034
... A109: =A108+1 -> 108 | B109: 5 | C109: U7 | D109: 46097
A110: =A109+1 -> 109 | B110: 1 | C110: Camp | D110: 46230 | E110: 0.375 | F110: Neufeld | G110: REAL MADRID CAMP | H110: Heim
A111: =A110+1 -> 110 | B111: 2 | C111: Camp | D111: 46231 | E111: 0.375 | F111: Neufeld | G111: REAL MADRID CAMP | H111: Heim
A112: =A111+1 -> 111 | B112: 3 | C112: Camp | D112: 46232 | E112: 0.375 | F112: Neufeld | G112: REAL MADRID CAMP | H112: Heim
A113: =A112+1 -> 112 | B113: 4 | C113: Camp | D113: 46233 | E113: 0.375 | F113: Neufeld | G113: REAL MADRID CAMP | H113: Heim
A114: =A113+1 -> 113 | B114: 5 | C114: Camp | D114: 46234 | E114: 0.375 | F114: Neufeld | G114: REAL MADRID CAMP | H114: Heim
A115: =A114+1 -> 114 | B115: 6 | C115: Camp | D115: 46237 | E115: 0.375 | F115: Neufeld | G115: MÄDCHENCAMP | H115: Heim
A116: =A115+1 -> 115 | B116: 7 | C116: Camp | D116: 46238 | E116: 0.375 | F116: Neufeld | G116: MÄDCHENCAMP | H116: Heim
A117: =A116+1 -> 116 | B117: 8 | C117: Camp | D117: 46239 | E117: 0.375 | F117: Neufeld | G117: MÄDCHENCAMP | H117: Heim
A118: =A117+1 -> 117 | B118: 9 | C118: Camp | D118: 46321 | E118: 0.375 | F118: Neufeld | G118: Teco 7 Camp | H118: Heim
A119: =A118+1 -> 118 | B119: 10 | C119: Camp | D119: 46322 | E119: 0.375 | F119: Neufeld | G119: Teco 7 Camp | H119: Heim
A120: =A119+1 -> 119 | B120: 11 | C120: Camp | D120: 46323 | E120: 0.375 | F120: Neufeld | G120: Teco 7 Camp | H120: Heim
A121: =A120+1 -> 120 | B121: 2 | C121: GGG | D121: 46256 | E121: 0.375 | F121: Neufeld | G121: viele Gegner | H121: Heim

Sheet ICS2
A1: TITEL | B1: DATUM | C1: STARTZEIT | D1: ENDZEIT | E1: ORT | F1: BESCHREIBUNG | G1: TYP | H1: GEGNER | I1: LIGA | J1: STATUS | K1: SPIELART | L1: ART
B2: ='Nach Mannschaften sortiert'!D2 -> 46199 | C2: ='Nach Mannschaften sortiert'!E2 -> 0.66666667 | D2: =IF(I2 = "KM",C2+"1:45",IF(I2="U23",C2+"1:45",IF(I2 = "U16",C2+"1:45",IF(I2 = "U15",C2+"1:30",IF(I2 = "U14",C2+"1:30",IF(I2 = "U13",C2+"1:35",IF(I2 = "U12",C2+"1:10",IF(I2 = "U11",C2+"1:10",IF(I2 = "U10",C2+"1:03",C2+"3:00"))))))))) -> 0.72916667 | E2: =UPPER('Nach Mannschaften sortiert'!F2) -> WIMPASSING | G2: ='Nach Mannschaften sortiert'!H2 -> Heim | H2: ='Nach Mannschaften sortiert'!G2 -> SK Rapid Wien | I2: ='Nach Mannschaften sortiert'!C2 -> U15 | J2: aktiv | K2: Liga | L2: Spiel
B3: ='Nach Mannschaften sortiert'!D3 -> 46199 | C3: ='Nach Mannschaften sortiert'!E3 -> 0.75 | D3: =IF(I3 = "KM",C3+"1:45",IF(I3="U23",C3+"1:45",IF(I3 = "U16",C3+"1:45",IF(I3 = "U15",C3+"1:30",IF(I3 = "U14",C3+"1:30",IF(I3 = "U13",C3+"1:35",IF(I3 = "U12",C3+"1:10",IF(I3 = "U11",C3+"1:10",IF(I3 = "U10",C3+"1:03",C3+"3:00"))))))))) -> 0.82291667 | E3: =UPPER('Nach Mannschaften sortiert'!F3) -> WIMPASSING | G3: ='Nach Mannschaften sortiert'!H3 -> Heim | H3: ='Nach Mannschaften sortiert'!G3 -> SK Rapid Wien | I3: ='Nach Mannschaften sortiert'!C3 -> U16 | J3: aktiv | K3: Liga | L3: Spiel
B4: ='Nach Mannschaften sortiert'!D4 -> 46213 | C4: ='Nach Mannschaften sortiert'!E4 -> 0.79166667 | D4: =IF(I4 = "KM",C4+"1:45",IF(I4="U23",C4+"1:45",IF(I4 = "U16",C4+"1:45",IF(I4 = "U15",C4+"1:30",IF(I4 = "U14",C4+"1:30",IF(I4 = "U13",C4+"1:35",IF(I4 = "U12",C4+"1:10",IF(I4 = "U11",C4+"1:10",IF(I4 = "U10",C4+"1:03",C4+"3:00"))))))))) -> 0.86458333 | E4: =UPPER('Nach Mannschaften sortiert'!F4) -> NEUDÖRFL | G4: ='Nach Mannschaften sortiert'!H4 -> Auswärts | H4: ='Nach Mannschaften sortiert'!G4 -> Neudörfl | I4: ='Nach Mannschaften sortiert'!C4 -> KM | J4: aktiv | K4: Liga | L4: Spiel
B5: ='Nach Mannschaften sortiert'!D5 -> 46220 | C5: ='Nach Mannschaften sortiert'!E5 -> 0.79166667 | D5: =IF(I5 = "KM",C5+"1:45",IF(I5="U23",C5+"1:45",IF(I5 = "U16",C5+"1:45",IF(I5 = "U15",C5+"1:30",IF(I5 = "U14",C5+"1:30",IF(I5 = "U13",C5+"1:35",IF(I5 = "U12",C5+"1:10",IF(I5 = "U11",C5+"1:10",IF(I5 = "U10",C5+"1:03",C5+"3:00"))))))))) -> 0.86458333 | E5: =UPPER('Nach Mannschaften sortiert'!F5) -> ROHBACH | G5: ='Nach Mannschaften sortiert'!H5 -> Auswärts | H5: ='Nach Mannschaften sortiert'!G5 -> Rohrbach | I5: ='Nach Mannschaften sortiert'!C5 -> KM | J5: aktiv | K5: Liga | L5: Spiel
B6: ='Nach Mannschaften sortiert'!D6 -> 46235 | C6: ='Nach Mannschaften sortiert'!E6 -> 0.72916667 | D6: =IF(I6 = "KM",C6+"1:45",IF(I6="U23",C6+"1:45",IF(I6 = "U16",C6+"1:45",IF(I6 = "U15",C6+"1:30",IF(I6 = "U14",C6+"1:30",IF(I6 = "U13",C6+"1:35",IF(I6 = "U12",C6+"1:10",IF(I6 = "U11",C6+"1:10",IF(I6 = "U10",C6+"1:03",C6+"3:00"))))))))) -> 0.80208333 | E6: =UPPER('Nach Mannschaften sortiert'!F6) -> KITTSEE | G6: ='Nach Mannschaften sortiert'!H6 -> Auswärts | H6: ='Nach Mannschaften sortiert'!G6 -> Kittsee | I6: ='Nach Mannschaften sortiert'!C6 -> KM | J6: aktiv | K6: Liga | L6: Spiel
B7: ='Nach Mannschaften sortiert'!D7 -> 46241 | C7: ='Nach Mannschaften sortiert'!E7 -> 0.79166667 | D7: =IF(I7 = "KM",C7+"1:45",IF(I7="U23",C7+"1:45",IF(I7 = "U16",C7+"1:45",IF(I7 = "U15",C7+"1:30",IF(I7 = "U14",C7+"1:30",IF(I7 = "U13",C7+"1:35",IF(I7 = "U12",C7+"1:10",IF(I7 = "U11",C7+"1:10",IF(I7 = "U10",C7+"1:03",C7+"3:00"))))))))) -> 0.86458333 | E7: =UPPER('Nach Mannschaften sortiert'!F7) -> NEUFELD | G7: ='Nach Mannschaften sortiert'!H7 -> Heim | H7: ='Nach Mannschaften sortiert'!G7 -> Bad Fischau | I7: ='Nach Mannschaften sortiert'!C7 -> KM | J7: aktiv | K7: Liga | L7: Spiel
B8: ='Nach Mannschaften sortiert'!D8 -> 46243 | C8: ='Nach Mannschaften sortiert'!E8 -> 0.45833333 | D8: =IF(I8 = "KM",C8+"1:45",IF(I8="U23",C8+"1:45",IF(I8 = "U16",C8+"1:45",IF(I8 = "U15",C8+"1:30",IF(I8 = "U14",C8+"1:30",IF(I8 = "U13",C8+"1:35",IF(I8 = "U12",C8+"1:10",IF(I8 = "U11",C8+"1:10",IF(I8 = "U10",C8+"1:03",C8+"3:00"))))))))) -> 0.53125 | E8: =UPPER('Nach Mannschaften sortiert'!F8) -> WIENER NEUDORF | G8: ='Nach Mannschaften sortiert'!H8 -> Auswärts | H8: ='Nach Mannschaften sortiert'!G8 -> Wiener Neudorf | I8: ='Nach Mannschaften sortiert'!C8 -> U16 | J8: aktiv | K8: Liga | L8: Spiel
B9: ='Nach Mannschaften sortiert'!D9 -> 46249 | C9: ='Nach Mannschaften sortiert'!E9 -> 0.72916667 | D9: =IF(I9 = "KM",C9+"1:45",IF(I9="U23",C9+"1:45",IF(I9 = "U16",C9+"1:45",IF(I9 = "U15",C9+"1:30",IF(I9 = "U14",C9+"1:30",IF(I9 = "U13",C9+"1:35",IF(I9 = "U12",C9+"1:10",IF(I9 = "U11",C9+"1:10",IF(I9 = "U10",C9+"1:03",C9+"3:00"))))))))) -> 0.80208333 | E9: =UPPER('Nach Mannschaften sortiert'!F9) -> KITTSEE | G9: ='Nach Mannschaften sortiert'!H9 -> Auswärts | H9: ='Nach Mannschaften sortiert'!G9 -> Kittsee | I9: ='Nach Mannschaften sortiert'!C9 -> KM | J9: aktiv | K9: Liga | L9: Spiel
B10: ='Nach Mannschaften sortiert'!D10 -> 46256 | C10: ='Nach Mannschaften sortiert'!E10 -> 0.70833333 | D10: =IF(I10 = "KM",C10+"1:45",IF(I10="U23",C10+"1:45",IF(I10 = "U16",C10+"1:45",IF(I10 = "U15",C10+"1:30",IF(I10 = "U14",C10+"1:30",IF(I10 = "U13",C10+"1:35",IF(I10 = "U12",C10+"1:10",IF(I10 = "U11",C10+"1:10",IF(I10 = "U10",C10+"1:03",C10+"3:00"))))))))) -> 0.78125 | E10: =UPPER('Nach Mannschaften sortiert'!F10) -> DEUTSCH JAHRNDORF | G10: ='Nach Mannschaften sortiert'!H10 -> Auswärts | H10: ='Nach Mannschaften sortiert'!G10 -> Deutsch Jahrndorf | I10: ='Nach Mannschaften sortiert'!C10 -> KM | J10: aktiv | K10: Liga | L10: Spiel
B11: ='Nach Mannschaften sortiert'!D11 -> 46263 | C11: ='Nach Mannschaften sortiert'!E11 -> 0.70833333 | D11: =IF(I11 = "KM",C11+"1:45",IF(I11="U23",C11+"1:45",IF(I11 = "U16",C11+"1:45",IF(I11 = "U15",C11+"1:30",IF(I11 = "U14",C11+"1:30",IF(I11 = "U13",C11+"1:35",IF(I11 = "U12",C11+"1:10",IF(I11 = "U11",C11+"1:10",IF(I11 = "U10",C11+"1:03",C11+"3:00"))))))))) -> 0.78125 | E11: =UPPER('Nach Mannschaften sortiert'!F11) -> NEUFELD | G11: ='Nach Mannschaften sortiert'!H11 -> Heim | H11: ='Nach Mannschaften sortiert'!G11 -> Tadten | I11: ='Nach Mannschaften sortiert'!C11 -> KM | J11: aktiv | K11: Liga | L11: Spiel
B12: ='Nach Mannschaften sortiert'!D12 -> 46270 | C12: ='Nach Mannschaften sortiert'!E12 -> 0.6875 | D12: =IF(I12 = "KM",C12+"1:45",IF(I12="U23",C12+"1:45",IF(I12 = "U16",C12+"1:45",IF(I12 = "U15",C12+"1:30",IF(I12 = "U14",C12+"1:30",IF(I12 = "U13",C12+"1:35",IF(I12 = "U12",C12+"1:10",IF(I12 = "U11",C12+"1:10",IF(I12 = "U10",C12+"1:03",C12+"3:00"))))))))) -> 0.76041667 | E12: =UPPER('Nach Mannschaften sortiert'!F12) -> MÖNCHHOF | G12: ='Nach Mannschaften sortiert'!H12 -> Auswärts | H12: ='Nach Mannschaften sortiert'!G12 -> Mönchhof | I12: ='Nach Mannschaften sortiert'!C12 -> KM | J12: aktiv | K12: Liga | L12: Spiel
B13: ='Nach Mannschaften sortiert'!D13 -> 46277 | C13: ='Nach Mannschaften sortiert'!E13 -> 0.6875 | D13: =IF(I13 = "KM",C13+"1:45",IF(I13="U23",C13+"1:45",IF(I13 = "U16",C13+"1:45",IF(I13 = "U15",C13+"1:30",IF(I13 = "U14",C13+"1:30",IF(I13 = "U13",C13+"1:35",IF(I13 = "U12",C13+"1:10",IF(I13 = "U11",C13+"1:10",IF(I13 = "U10",C13+"1:03",C13+"3:00"))))))))) -> 0.76041667 | E13: =UPPER('Nach Mannschaften sortiert'!F13) -> NEUFELD | G13: ='Nach Mannschaften sortiert'!H13 -> Heim | H13: ='Nach Mannschaften sortiert'!G13 -> Winden | I13: ='Nach Mannschaften sortiert'!C13 -> KM | J13: aktiv | K13: Liga | L13: Spiel
... B121: ='Nach Mannschaften sortiert'!D121 -> 46256 | C121: ='Nach Mannschaften sortiert'!E121 -> 0.375 | D121: =IF(I121 = "KM",C121+"1:45",IF(I121="U23",C121+"1:45",IF(I121 = "U16",C121+"1:45",IF(I121 = "U15",C121+"1:30",IF(I121 = "U14",C121+"1:30",IF(I121 = "U13",C121+"1:35",IF(I121 = "U12",C121+"1:10",IF(I121 = "U11",C121+"1:10",IF(I121 = "U10",C121+"1:03",C121+"3:00"))))))))) -> 0.5 | E121: =UPPER('Nach Mannschaften sortiert'!F121) -> NEUFELD | G121: ='Nach Mannschaften sortiert'!H121 -> Heim | H121: ='Nach Mannschaften sortiert'!G121 -> viele Gegner | I121: ='Nach Mannschaften sortiert'!C121 -> GGG | J121: aktiv | K121: Liga | L121: Spiel

Sheet Kalendernamen
A1: Kategorie | C1: ABOLINK
A2: Alle Spiele des ASV Neufeld | B2: alle_spiele.ics | C2: ="https://dtb-asv.github.io/asv-neufeld/"&B2 -> https://dtb-asv.github.io/asv-neufeld/alle_spiele.ics
A3: Alle Heimspiele des ASV Neufelds | B3: heimspiele.ics | C3: ="https://dtb-asv.github.io/asv-neufeld/"&B3 -> https://dtb-asv.github.io/asv-neufeld/heimspiele.ics
A4: Alle Auswärtsspiele des ASV Neufelds | B4: auswaertsspiele.ics | C4: ="https://dtb-asv.github.io/asv-neufeld/"&B4 -> https://dtb-asv.github.io/asv-neufeld/auswaertsspiele.ics
A5: Alle Spiele der Kampfmannschaft | B5: KM.ics | C5: ="https://dtb-asv.github.io/asv-neufeld/"&B5 -> https://dtb-asv.github.io/asv-neufeld/KM.ics
A6: Alle Spiele der U23 | B6: U23.ics | C6: ="https://dtb-asv.github.io/asv-neufeld/"&B6 -> https://dtb-asv.github.io/asv-neufeld/U23.ics
A7: Alle Spiele der U16 | B7: U16.ics | C7: ="https://dtb-asv.github.io/asv-neufeld/"&B7 -> https://dtb-asv.github.io/asv-neufeld/U16.ics
A8: Alle Spiele der U15 | B8: U15.ics | C8: ="https://dtb-asv.github.io/asv-neufeld/"&B8 -> https://dtb-asv.github.io/asv-neufeld/U15.ics
A9: Alle Spiele der U14 | B9: U14.ics | C9: ="https://dtb-asv.github.io/asv-neufeld/"&B9 -> https://dtb-asv.github.io/asv-neufeld/U14.ics
A10: Alle Spiele der U13 | B10: U13.ics | C10: ="https://dtb-asv.github.io/asv-neufeld/"&B10 -> https://dtb-asv.github.io/asv-neufeld/U13.ics
A11: Alle Spiele der U12 | B11: U12.ics | C11: ="https://dtb-asv.github.io/asv-neufeld/"&B11 -> https://dtb-asv.github.io/asv-neufeld/U12.ics
A12: Alle Spiele der U11 | B12: U11.ics | C12: ="https://dtb-asv.github.io/asv-neufeld/"&B12 -> https://dtb-asv.github.io/asv-neufeld/U11.ics
A13: Alle Spiele der U10 | B13: U10.ics | C13: ="https://dtb-asv.github.io/asv-neufeld/"&B13 -> https://dtb-asv.github.io/asv-neufeld/U10.ics
... A16: Alle Spiele der U7 | B16: U7.ics | C16: ="https://dtb-asv.github.io/asv-neufeld/"&B16 -> https://dtb-asv.github.io/asv-neufeld/ U7.ics
B17: Camp.ics | C17: ="https://dtb-asv.github.io/asv-neufeld/"&B17 -> https://dtb-asv.github.io/asv-neufeld/ Camp.ics
B18: GGG.ics | C18: ="https://dtb-asv.github.io/asv-neufeld/"&B18 -> https://dtb-asv.github.io/asv-neufeld/ GGG.ics

Sheet Trainingsplan
A1: TRAININGSORTE/TAGE
A2: MANNSCHAFT | B2: TRAINER | C2: MONTAG | D2: DIENSTAG | E2: MITTWOCH | F2: DONNERSTAG | G2: FREITAG | H2: SAMSTAG | I2: WENN KM-TRAINING MUSS DAS HAUPTFELD AB 18:45 FREI SEIN
A3: FKG | B3: RONNIE ARCHAM | E3: 16:00 - 16:45
A4: U7 | B4: ÖMER TÜRKES TAHA MAHSUMI | D4: 17:30 - 18:30 | F4: 17:30 - 18:30
A5: U8 | B5: TOBIAS BERGER SEBASTIAN PUTRIC | C5: 16:30 - 18:00 | F5: 17: 00 - 18:30
A6: U9 | B6: THOMAS BRANDL DANIEL HOFBAUER | D6: 17:00 - 18:30 | F6: 17:00 - 18:30
A7: U11 | B7: MARIO MAGLER RONNIE ARCHAM | C7: 17:00 - 18:30 | E7: 17:00 - 18:30 | G7: 17:00 - 18:30
A8: U13 | B8: THOMAS PÖSCHL LENZ HONC | C8: 17:00 - 18:30 | E8: 17:00 - 18:30 | G8: 17:00 - 18:30
A9: U14 | B9: GERNOT SEVELDA MARKUS DORINGER | C9: 17:00 - 18:30 | F9: 17:00 - 18:30 | G9: 17:00 - 18:30 | H9: 10:00 - 11:00
A10: U15 | B10: SERDAR EKINCI HUBERT OBERHOFER | D10: 18:30 - 20:15 | F10: 18:00 - 19:30 | G10: 18:30 - 20:15
A11: U16 | B11: JOSCH KÖGL | E11: 17:15 - 19:00 | G11: WIMPASSING
A12: U23 | B12: DINGES STEFAN | C12: 18:45 - 20:15 | E12: 18:45 - 20:15 | F12: 18:45 - 20:15
A13: KM | B13: PLENINGER STEFAN | C13: 18:45 - 20:15 | E13: 18:45 - 20:15 | F13: 18:45 - 20:15
A14: JUNIOREN/SENIOREN | D14: 18:45 - 20:15
A15: HAUPTFELD
A16: TRAININGSPLATZ
A17: HINTERM TOR
A18: SPIELGEMEINSCHAFTEN MIT WIMPASSING

Sheet Heimspiele
A1: ='Nach Mannschaften sortiert'!A1 -> fortlaufende Nummer | B1: ='Nach Mannschaften sortiert'!B1 -> Runde | C1: ='Nach Mannschaften sortiert'!C1 -> Mannschaft | D1: ='Nach Mannschaften sortiert'!D1 -> fixierter Termin | E1: ='Nach Mannschaften sortiert'!E1 -> fixierte Uhrzeit | F1: ='Nach Mannschaften sortiert'!F1 -> Ort | G1: ='Nach Mannschaften sortiert'!G1 -> Gegner | H1: ='Nach Mannschaften sortiert'!H1 -> Auswärt/Heim
A2: ='Nach Mannschaften sortiert'!A9 -> 8 | B2: ='Nach Mannschaften sortiert'!B9 -> 1 | C2: ='Nach Mannschaften sortiert'!C9 -> KM | D2: ='Nach Mannschaften sortiert'!D9 -> 46249 | E2: ='Nach Mannschaften sortiert'!E9 -> 0.72916667 | F2: ='Nach Mannschaften sortiert'!F9 -> Kittsee | G2: ='Nach Mannschaften sortiert'!G9 -> Kittsee | H2: ='Nach Mannschaften sortiert'!H9 -> Auswärts
A3: ='Nach Mannschaften sortiert'!A10 -> 9 | B3: ='Nach Mannschaften sortiert'!B10 -> 2 | C3: ='Nach Mannschaften sortiert'!C10 -> KM | D3: ='Nach Mannschaften sortiert'!D10 -> 46256 | E3: ='Nach Mannschaften sortiert'!E10 -> 0.70833333 | F3: ='Nach Mannschaften sortiert'!F10 -> Deutsch Jahrndorf | G3: ='Nach Mannschaften sortiert'!G10 -> Deutsch Jahrndorf | H3: ='Nach Mannschaften sortiert'!H10 -> Auswärts
A4: ='Nach Mannschaften sortiert'!A11 -> 10 | B4: ='Nach Mannschaften sortiert'!B11 -> 3 | C4: ='Nach Mannschaften sortiert'!C11 -> KM | D4: ='Nach Mannschaften sortiert'!D11 -> 46263 | E4: ='Nach Mannschaften sortiert'!E11 -> 0.70833333 | F4: ='Nach Mannschaften sortiert'!F11 -> Neufeld | G4: ='Nach Mannschaften sortiert'!G11 -> Tadten | H4: ='Nach Mannschaften sortiert'!H11 -> Heim
A5: ='Nach Mannschaften sortiert'!A45 -> 44 | B5: ='Nach Mannschaften sortiert'!B45 -> 1 | C5: ='Nach Mannschaften sortiert'!C45 -> U14 | D5: ='Nach Mannschaften sortiert'!D45 -> 46033 | E5: ='Nach Mannschaften sortiert'!E45 -> 0 | F5: ='Nach Mannschaften sortiert'!F45 -> 0 | G5: ='Nach Mannschaften sortiert'!G45 -> 0 | H5: ='Nach Mannschaften sortiert'!H45 -> 0
A6: ='Nach Mannschaften sortiert'!A13 -> 12 | B6: ='Nach Mannschaften sortiert'!B13 -> 5 | C6: ='Nach Mannschaften sortiert'!C13 -> KM | D6: ='Nach Mannschaften sortiert'!D13 -> 46277 | E6: ='Nach Mannschaften sortiert'!E13 -> 0.6875 | F6: ='Nach Mannschaften sortiert'!F13 -> Neufeld | G6: ='Nach Mannschaften sortiert'!G13 -> Winden | H6: ='Nach Mannschaften sortiert'!H13 -> Heim
A7: ='Nach Mannschaften sortiert'!A55 -> 54 | B7: ='Nach Mannschaften sortiert'!B55 -> 1 | C7: ='Nach Mannschaften sortiert'!C55 -> U12_1 | D7: ='Nach Mannschaften sortiert'!D55 -> 46043 | E7: ='Nach Mannschaften sortiert'!E55 -> 0 | F7: ='Nach Mannschaften sortiert'!F55 -> 0 | G7: ='Nach Mannschaften sortiert'!G55 -> 0 | H7: ='Nach Mannschaften sortiert'!H55 -> 0
A8: ='Nach Mannschaften sortiert'!A15 -> 14 | B8: ='Nach Mannschaften sortiert'!B15 -> 7 | C8: ='Nach Mannschaften sortiert'!C15 -> KM | D8: ='Nach Mannschaften sortiert'!D15 -> 46291 | E8: ='Nach Mannschaften sortiert'!E15 -> 0.66666667 | F8: ='Nach Mannschaften sortiert'!F15 -> Neufeld | G8: ='Nach Mannschaften sortiert'!G15 -> Wallern | H8: ='Nach Mannschaften sortiert'!H15 -> Heim
A9: ='Nach Mannschaften sortiert'!A110 -> 109 | B9: ='Nach Mannschaften sortiert'!B110 -> 1 | C9: ='Nach Mannschaften sortiert'!C110 -> Camp | D9: ='Nach Mannschaften sortiert'!D110 -> 46230 | E9: ='Nach Mannschaften sortiert'!E110 -> 0.375 | F9: ='Nach Mannschaften sortiert'!F110 -> Neufeld | G9: ='Nach Mannschaften sortiert'!G110 -> REAL MADRID CAMP | H9: ='Nach Mannschaften sortiert'!H110 -> Heim
A10: ='Nach Mannschaften sortiert'!A17 -> 16 | B10: ='Nach Mannschaften sortiert'!B17 -> 9 | C10: ='Nach Mannschaften sortiert'!C17 -> KM | D10: ='Nach Mannschaften sortiert'!D17 -> 46305 | E10: ='Nach Mannschaften sortiert'!E17 -> 0.64583333 | F10: ='Nach Mannschaften sortiert'!F17 -> Neufeld | G10: ='Nach Mannschaften sortiert'!G17 -> Wimpassing | H10: ='Nach Mannschaften sortiert'!H17 -> Heim
A11: ='Nach Mannschaften sortiert'!A111 -> 110 | B11: ='Nach Mannschaften sortiert'!B111 -> 2 | C11: ='Nach Mannschaften sortiert'!C111 -> Camp | D11: ='Nach Mannschaften sortiert'!D111 -> 46231 | E11: ='Nach Mannschaften sortiert'!E111 -> 0.375 | F11: ='Nach Mannschaften sortiert'!F111 -> Neufeld | G11: ='Nach Mannschaften sortiert'!G111 -> REAL MADRID CAMP | H11: ='Nach Mannschaften sortiert'!H111 -> Heim
A12: ='Nach Mannschaften sortiert'!A19 -> 18 | B12: ='Nach Mannschaften sortiert'!B19 -> 11 | C12: ='Nach Mannschaften sortiert'!C19 -> KM | D12: ='Nach Mannschaften sortiert'!D19 -> 46319 | E12: ='Nach Mannschaften sortiert'!E19 -> 0.625 | F12: ='Nach Mannschaften sortiert'!F19 -> Neufeld | G12: ='Nach Mannschaften sortiert'!G19 -> Gols | H12: ='Nach Mannschaften sortiert'!H19 -> Heim
A13: ='Nach Mannschaften sortiert'!A20 -> 19 | B13: ='Nach Mannschaften sortiert'!B20 -> 12 | C13: ='Nach Mannschaften sortiert'!C20 -> KM | D13: ='Nach Mannschaften sortiert'!D20 -> 46326 | E13: ='Nach Mannschaften sortiert'!E20 -> 0.58333333 | F13: ='Nach Mannschaften sortiert'!F20 -> Illmitz | G13: ='Nach Mannschaften sortiert'!G20 -> Illmitz | H13: ='Nach Mannschaften sortiert'!H20 -> Auswärts
A14: ='Nach Mannschaften sortiert'!A112 -> 111 | B14: ='Nach Mannschaften sortiert'!B112 -> 3 | C14: ='Nach Mannschaften sortiert'!C112 -> Camp | D14: ='Nach Mannschaften sortiert'!D112 -> 46232 | E14: ='Nach Mannschaften sortiert'!E112 -> 0.375 | F14: ='Nach Mannschaften sortiert'!F112 -> Neufeld | G14: ='Nach Mannschaften sortiert'!G112 -> REAL MADRID CAMP | H14: ='Nach Mannschaften sortiert'!H112 -> Heim
A15: ='Nach Mannschaften sortiert'!A35 -> 34 | B15: ='Nach Mannschaften sortiert'!B35 -> 1 | C15: ='Nach Mannschaften sortiert'!C35 -> U16 | D15: ='Nach Mannschaften sortiert'!D35 -> 46023 | E15: ='Nach Mannschaften sortiert'!E35 -> 0 | F15: ='Nach Mannschaften sortiert'!F35 -> 0 | G15: ='Nach Mannschaften sortiert'!G35 -> 0 | H15: ='Nach Mannschaften sortiert'!H35 -> 0
A16: ='Nach Mannschaften sortiert'!A36 -> 35 | B16: ='Nach Mannschaften sortiert'!B36 -> 2 | C16: ='Nach Mannschaften sortiert'!C36 -> U16 | D16: ='Nach Mannschaften sortiert'!D36 -> 46024 | E16: ='Nach Mannschaften sortiert'!E36 -> 0 | F16: ='Nach Mannschaften sortiert'!F36 -> 0 | G16: ='Nach Mannschaften sortiert'!G36 -> 0 | H16: ='Nach Mannschaften sortiert'!H36 -> 0
A17: ='Nach Mannschaften sortiert'!A37 -> 36 | B17: ='Nach Mannschaften sortiert'!B37 -> 3 | C17: ='Nach Mannschaften sortiert'!C37 -> U16 | D17: ='Nach Mannschaften sortiert'!D37 -> 46025 | E17: ='Nach Mannschaften sortiert'!E37 -> 0 | F17: ='Nach Mannschaften sortiert'!F37 -> 0 | G17: ='Nach Mannschaften sortiert'!G37 -> 0 | H17: ='Nach Mannschaften sortiert'!H37 -> 0
A18: ='Nach Mannschaften sortiert'!A12 -> 11 | B18: ='Nach Mannschaften sortiert'!B12 -> 4 | C18: ='Nach Mannschaften sortiert'!C12 -> KM | D18: ='Nach Mannschaften sortiert'!D12 -> 46270 | E18: ='Nach Mannschaften sortiert'!E12 -> 0.6875 | F18: ='Nach Mannschaften sortiert'!F12 -> Mönchhof | G18: ='Nach Mannschaften sortiert'!G12 -> Mönchhof | H18: ='Nach Mannschaften sortiert'!H12 -> Auswärts
A19: ='Nach Mannschaften sortiert'!A39 -> 38 | B19: ='Nach Mannschaften sortiert'!B39 -> 5 | C19: ='Nach Mannschaften sortiert'!C39 -> U16 | D19: ='Nach Mannschaften sortiert'!D39 -> 46027 | E19: ='Nach Mannschaften sortiert'!E39 -> 0 | F19: ='Nach Mannschaften sortiert'!F39 -> 0 | G19: ='Nach Mannschaften sortiert'!G39 -> 0 | H19: ='Nach Mannschaften sortiert'!H39 -> 0
A20: ='Nach Mannschaften sortiert'!A40 -> 39 | B20: ='Nach Mannschaften sortiert'!B40 -> 6 | C20: ='Nach Mannschaften sortiert'!C40 -> U16 | D20: ='Nach Mannschaften sortiert'!D40 -> 46028 | E20: ='Nach Mannschaften sortiert'!E40 -> 0 | F20: ='Nach Mannschaften sortiert'!F40 -> 0 | G20: ='Nach Mannschaften sortiert'!G40 -> 0 | H20: ='Nach Mannschaften sortiert'!H40 -> 0
A21: ='Nach Mannschaften sortiert'!A41 -> 40 | B21: ='Nach Mannschaften sortiert'!B41 -> 7 | C21: ='Nach Mannschaften sortiert'!C41 -> U16 | D21: ='Nach Mannschaften sortiert'!D41 -> 46029 | E21: ='Nach Mannschaften sortiert'!E41 -> 0 | F21: ='Nach Mannschaften sortiert'!F41 -> 0 | G21: ='Nach Mannschaften sortiert'!G41 -> 0 | H21: ='Nach Mannschaften sortiert'!H41 -> 0
A22: ='Nach Mannschaften sortiert'!A42 -> 41 | B22: ='Nach Mannschaften sortiert'!B42 -> 8 | C22: ='Nach Mannschaften sortiert'!C42 -> U16 | D22: ='Nach Mannschaften sortiert'!D42 -> 46030 | E22: ='Nach Mannschaften sortiert'!E42 -> 0 | F22: ='Nach Mannschaften sortiert'!F42 -> 0 | G22: ='Nach Mannschaften sortiert'!G42 -> 0 | H22: ='Nach Mannschaften sortiert'!H42 -> 0
A23: ='Nach Mannschaften sortiert'!A43 -> 42 | B23: ='Nach Mannschaften sortiert'!B43 -> 9 | C23: ='Nach Mannschaften sortiert'!C43 -> U16 | D23: ='Nach Mannschaften sortiert'!D43 -> 46031 | E23: ='Nach Mannschaften sortiert'!E43 -> 0 | F23: ='Nach Mannschaften sortiert'!F43 -> 0 | G23: ='Nach Mannschaften sortiert'!G43 -> 0 | H23: ='Nach Mannschaften sortiert'!H43 -> 0
A24: ='Nach Mannschaften sortiert'!A90 -> 89 | B24: ='Nach Mannschaften sortiert'!B90 -> 1 | C24: ='Nach Mannschaften sortiert'!C90 -> U9 | D24: ='Nach Mannschaften sortiert'!D90 -> 46078 | E24: ='Nach Mannschaften sortiert'!E90 -> 0 | F24: ='Nach Mannschaften sortiert'!F90 -> 0 | G24: ='Nach Mannschaften sortiert'!G90 -> 0 | H24: ='Nach Mannschaften sortiert'!H90 -> 0
A25: ='Nach Mannschaften sortiert'!#REF! -> #REF! | B25: ='Nach Mannschaften sortiert'!#REF! -> #REF! | C25: ='Nach Mannschaften sortiert'!#REF! -> #REF! | D25: ='Nach Mannschaften sortiert'!#REF! -> #REF! | E25: ='Nach Mannschaften sortiert'!#REF! -> #REF! | F25: ='Nach Mannschaften sortiert'!#REF! -> #REF! | G25: ='Nach Mannschaften sortiert'!#REF! -> #REF! | H25: ='Nach Mannschaften sortiert'!#REF! -> #REF!
A26: ='Nach Mannschaften sortiert'!A100 -> 99 | B26: ='Nach Mannschaften sortiert'!B100 -> 1 | C26: ='Nach Mannschaften sortiert'!C100 -> U8 | D26: ='Nach Mannschaften sortiert'!D100 -> 46088 | E26: ='Nach Mannschaften sortiert'!E100 -> 0 | F26: ='Nach Mannschaften sortiert'!F100 -> 0 | G26: ='Nach Mannschaften sortiert'!G100 -> 0 | H26: ='Nach Mannschaften sortiert'!H100 -> 0
A27: ='Nach Mannschaften sortiert'!#REF! -> #REF! | B27: ='Nach Mannschaften sortiert'!#REF! -> #REF! | C27: ='Nach Mannschaften sortiert'!#REF! -> #REF! | D27: ='Nach Mannschaften sortiert'!#REF! -> #REF! | E27: ='Nach Mannschaften sortiert'!#REF! -> #REF! | F27: ='Nach Mannschaften sortiert'!#REF! -> #REF! | G27: ='Nach Mannschaften sortiert'!#REF! -> #REF! | H27: ='Nach Mannschaften sortiert'!#REF! -> #REF!
A28: ='Nach Mannschaften sortiert'!#REF! -> #REF! | B28: ='Nach Mannschaften sortiert'!#REF! -> #REF! | C28: ='Nach Mannschaften sortiert'!#REF! -> #REF! | D28: ='Nach Mannschaften sortiert'!#REF! -> #REF! | E28: ='Nach Mannschaften sortiert'!#REF! -> #REF! | F28: ='Nach Mannschaften sortiert'!#REF! -> #REF! | G28: ='Nach Mannschaften sortiert'!#REF! -> #REF! | H28: ='Nach Mannschaften sortiert'!#REF! -> #REF!
A29: ='Nach Mannschaften sortiert'!A105 -> 104 | B29: ='Nach Mannschaften sortiert'!B105 -> 1 | C29: ='Nach Mannschaften sortiert'!C105 -> U7 | D29: ='Nach Mannschaften sortiert'!D105 -> 46093 | E29: ='Nach Mannschaften sortiert'!E105 -> 0 | F29: ='Nach Mannschaften sortiert'!F105 -> 0 | G29: ='Nach Mannschaften sortiert'!G105 -> 0 | H29: ='Nach Mannschaften sortiert'!H105 -> 0
A30: ='Nach Mannschaften sortiert'!#REF! -> #REF! | B30: ='Nach Mannschaften sortiert'!#REF! -> #REF! | C30: ='Nach Mannschaften sortiert'!#REF! -> #REF! | D30: ='Nach Mannschaften sortiert'!#REF! -> #REF! | E30: ='Nach Mannschaften sortiert'!#REF! -> #REF! | F30: ='Nach Mannschaften sortiert'!#REF! -> #REF! | G30: ='Nach Mannschaften sortiert'!#REF! -> #REF! | H30: ='Nach Mannschaften sortiert'!#REF! -> #REF!
A31: ='Nach Mannschaften sortiert'!#REF! -> #REF! | B31: ='Nach Mannschaften sortiert'!#REF! -> #REF! | C31: ='Nach Mannschaften sortiert'!#REF! -> #REF! | D31: ='Nach Mannschaften sortiert'!#REF! -> #REF! | E31: ='Nach Mannschaften sortiert'!#REF! -> #REF! | F31: ='Nach Mannschaften sortiert'!#REF! -> #REF! | G31: ='Nach Mannschaften sortiert'!#REF! -> #REF! | H31: ='Nach Mannschaften sortiert'!#REF! -> #REF!
A32: ='Nach Mannschaften sortiert'!#REF! -> #REF! | B32: ='Nach Mannschaften sortiert'!#REF! -> #REF! | C32: ='Nach Mannschaften sortiert'!#REF! -> #REF! | D32: ='Nach Mannschaften sortiert'!#REF! -> #REF! | E32: ='Nach Mannschaften sortiert'!#REF! -> #REF! | F32: ='Nach Mannschaften sortiert'!#REF! -> #REF! | G32: ='Nach Mannschaften sortiert'!#REF! -> #REF! | H32: ='Nach Mannschaften sortiert'!#REF! -> #REF!
A33: ='Nach Mannschaften sortiert'!#REF! -> #REF! | B33: ='Nach Mannschaften sortiert'!#REF! -> #REF! | C33: ='Nach Mannschaften sortiert'!#REF! -> #REF! | D33: ='Nach Mannschaften sortiert'!#REF! -> #REF! | E33: ='Nach Mannschaften sortiert'!#REF! -> #REF! | F33: ='Nach Mannschaften sortiert'!#REF! -> #REF! | G33: ='Nach Mannschaften sortiert'!#REF! -> #REF! | H33: ='Nach Mannschaften sortiert'!#REF! -> #REF!
A34: ='Nach Mannschaften sortiert'!#REF! -> #REF! | B34: ='Nach Mannschaften sortiert'!#REF! -> #REF! | C34: ='Nach Mannschaften sortiert'!#REF! -> #REF! | D34: ='Nach Mannschaften sortiert'!#REF! -> #REF! | E34: ='Nach Mannschaften sortiert'!#REF! -> #REF! | F34: ='Nach Mannschaften sortiert'!#REF! -> #REF! | G34: ='Nach Mannschaften sortiert'!#REF! -> #REF! | H34: ='Nach Mannschaften sortiert'!#REF! -> #REF!
A35: ='Nach Mannschaften sortiert'!A76 -> 75 | B35: ='Nach Mannschaften sortiert'!B76 -> 2 | C35: ='Nach Mannschaften sortiert'!C76 -> U11 | D35: ='Nach Mannschaften sortiert'!D76 -> 46064 | E35: ='Nach Mannschaften sortiert'!E76 -> 0 | F35: ='Nach Mannschaften sortiert'!F76 -> 0 | G35: ='Nach Mannschaften sortiert'!G76 -> 0 | H35: ='Nach Mannschaften sortiert'!H76 -> 0
A36: ='Nach Mannschaften sortiert'!A46 -> 45 | B36: ='Nach Mannschaften sortiert'!B46 -> 2 | C36: ='Nach Mannschaften sortiert'!C46 -> U14 | D36: ='Nach Mannschaften sortiert'!D46 -> 46034 | E36: ='Nach Mannschaften sortiert'!E46 -> 0 | F36: ='Nach Mannschaften sortiert'!F46 -> 0 | G36: ='Nach Mannschaften sortiert'!G46 -> 0 | H36: ='Nach Mannschaften sortiert'!H46 -> 0
A37: ='Nach Mannschaften sortiert'!A47 -> 46 | B37: ='Nach Mannschaften sortiert'!B47 -> 3 | C37: ='Nach Mannschaften sortiert'!C47 -> U14 | D37: ='Nach Mannschaften sortiert'!D47 -> 46035 | E37: ='Nach Mannschaften sortiert'!E47 -> 0 | F37: ='Nach Mannschaften sortiert'!F47 -> 0 | G37: ='Nach Mannschaften sortiert'!G47 -> 0 | H37: ='Nach Mannschaften sortiert'!H47 -> 0
A38: ='Nach Mannschaften sortiert'!#REF! -> #REF! | B38: ='Nach Mannschaften sortiert'!#REF! -> #REF! | C38: ='Nach Mannschaften sortiert'!#REF! -> #REF! | D38: ='Nach Mannschaften sortiert'!#REF! -> #REF! | E38: ='Nach Mannschaften sortiert'!#REF! -> #REF! | F38: ='Nach Mannschaften sortiert'!#REF! -> #REF! | G38: ='Nach Mannschaften sortiert'!#REF! -> #REF! | H38: ='Nach Mannschaften sortiert'!#REF! -> #REF!
A39: ='Nach Mannschaften sortiert'!#REF! -> #REF! | B39: ='Nach Mannschaften sortiert'!#REF! -> #REF! | C39: ='Nach Mannschaften sortiert'!#REF! -> #REF! | D39: ='Nach Mannschaften sortiert'!#REF! -> #REF! | E39: ='Nach Mannschaften sortiert'!#REF! -> #REF! | F39: ='Nach Mannschaften sortiert'!#REF! -> #REF! | G39: ='Nach Mannschaften sortiert'!#REF! -> #REF! | H39: ='Nach Mannschaften sortiert'!#REF! -> #REF!
A40: ='Nach Mannschaften sortiert'!A49 -> 48 | B40: ='Nach Mannschaften sortiert'!B49 -> 5 | C40: ='Nach Mannschaften sortiert'!C49 -> U14 | D40: ='Nach Mannschaften sortiert'!D49 -> 46037 | E40: ='Nach Mannschaften sortiert'!E49 -> 0 | F40: ='Nach Mannschaften sortiert'!F49 -> 0 | G40: ='Nach Mannschaften sortiert'!G49 -> 0 | H40: ='Nach Mannschaften sortiert'!H49 -> 0
...

Sheet Tabelle1
A1: U11 | B1: 25 - 26.04 | C1: freihalten
A2: U9 | B2: 04.06. - 08.06. | C2: kein Turnier

Sheet Stefans Liste 2026
A1: Mannschaft | B1: fixierter Termin | C1: Uhrzeit | D1: Ort | E1: Gegner | F1: Spielfeld | G1: Spielfeldgröße | H1: Tore | I1: Ball | J1: Trainer/Ansprechpartner | K1: Tel
A2: U8 | B2: 46091 | C2: 0.6875 | D2: Neufeld | E2: Freundschaftsspiel Großhöflein | F2: U8 | G2: =IF(F2="Großfeld","Großfeld",IF(F2="U16","Großfeld",IF(F2="U15","Großfeld",IF(F2="U14","Großfeld",IF(F2="U13","75x55",IF(F2="U11/U12","55x40",IF(F2="U9/U10","40x25",IF(F2="U8","29x22","25x20")))))))) -> 29x22 | H2: =IF(F2="Großfeld","7,32x2,44",IF(F2="U16","7,32x2,44",IF(F2="U15","7,32x2,44",IF(F2="U14","7,32x2,44",IF(F2="U13","5x2",IF(F2="U11/U12","5x2",IF(F2="U9/U10","5x2","4 Minitore"))))))) -> 4 Minitore | I2: =IF(F2="Großfeld","5",IF(F2="U16","5",IF(F2="U15","5",IF(F2="U14","4",IF(F2="U13","4",IF(F2="U11/U12","4",IF(F2="U9/U10","4",IF(F2="U9","4","3")))))))) -> 3 | J2: =IF(A2="KM Neufeld","Pleninger Stefan",IF(A2="U16 LL","Josch Kögl",IF(A2="U15 LL Nord","Serdar Ekinci",IF(A2="U14 Nord","Gernot Servelda",IF(A2="U13 Nord","Thomas Pöschl & Lenz Honc",IF(A2="U11 Nord D","Mario Magler&Ronny Archam",IF(A2="U9","Thomas Brandl&Daniel Hofbauer",IF(A2="U8","Berger Tobias&Sebastian Putric",IF(A2="U7","Türkes Ömer&Mahsumi Taha",IF(A2="Camp","Berger Dieter",IF(A2="Turnier","Berger Dieter","FEHLER"))))))))))) -> Berger Tobias&Sebastian Putric | K2: =IF(A2="KM Neufeld","+43 664 415 99 09",IF(A2="U16 LL","+43 650 262 82 63",IF(A2="U15 LL Nord","+43 650 701 02 44",IF(A2="U14 Nord","+43 676 401 09 13",IF(A2="U13 Nord","+43 677 613 55 114 & +43 664 114 43 52",IF(A2="U11 Nord D","+43 664 762 09 93 & +43 699 111 93 828",IF(A2="U9","+43 676 377 16 30 & +43 399 197 871 81",IF(A2="U8","+43 660 199 13 52 & +43 660 914 92 36",IF(A2="U7","+43 676 661 62 26 & +43 681 208 115 99",IF(A2="Camp","+43 660 77 39 500",IF(A2="Turnier","+43 660 77 39 500","FEHLER"))))))))))) -> +43 660 199 13 52 & +43 660 914 92 36
A3: =Heimspiele!C4 -> KM | B3: =Heimspiele!D4 -> 46263 | D3: =Heimspiele!F4 -> Neufeld | E3: =Heimspiele!G4 -> Tadten | F3: Großfeld | G3: =IF(F3="Großfeld","Großfeld",IF(F3="U16","Großfeld",IF(F3="U15","Großfeld",IF(F3="U14","Großfeld",IF(F3="U13","75x55",IF(F3="U11/U12","55x40",IF(F3="U9/U10","40x25",IF(F3="U8","29x22","25x20")))))))) -> Großfeld | H3: =IF(F3="Großfeld","7,32x2,44",IF(F3="U16","7,32x2,44",IF(F3="U15","7,32x2,44",IF(F3="U14","7,32x2,44",IF(F3="U13","5x2",IF(F3="U11/U12","5x2",IF(F3="U9/U10","5x2","4 Minitore"))))))) -> 7,32x2,44 | I3: =IF(F3="Großfeld","5",IF(F3="U16","5",IF(F3="U15","5",IF(F3="U14","4",IF(F3="U13","4",IF(F3="U11/U12","4",IF(F3="U9/U10","4",IF(F3="U9","4","3")))))))) -> 5 | J3: =IF(A3="KM Neufeld","Pleninger Stefan",IF(A3="U16 LL","Josch Kögl",IF(A3="U15 LL Nord","Serdar Ekinci",IF(A3="U14 Nord","Gernot Servelda",IF(A3="U13 - Nord","Thomas Pöschl & Lenz Honc",IF(A3="U11 Nord D","Mario Magler&Ronny Archam",IF(A3="U9","Thomas Brandl&Daniel Hofbauer",IF(A3="U8","Berger Tobias&Sebastian Putric",IF(A3="U7","Türkes Ömer&Mahsumi Taha",IF(A3="Camp","Berger Dieter",IF(A3="Turnier","Berger Dieter","FEHLER"))))))))))) -> FEHLER | K3: =IF(A3="KM Neufeld","+43 664 415 99 09",IF(A3="U16 LL","+43 650 262 82 63",IF(A3="U15 LL Nord","+43 650 701 02 44",IF(A3="U14 - Nord","+43 676 401 09 13",IF(A3="U13 - Nord","+43 677 613 55 114 & +43 664 114 43 52",IF(A3="U11 Nord D","+43 664 762 09 93 & +43 699 111 93 828",IF(A3="U9","+43 676 377 16 30 & +43 399 197 871 81",IF(A3="U8","+43 660 199 13 52 & +43 660 914 92 36",IF(A3="U7","+43 676 661 62 26 & +43 681 208 115 99",IF(A3="Camp","+43 660 77 39 500",IF(A3="Turnier","+43 660 77 39 500","FEHLER"))))))))))) -> FEHLER
A4: U16 LL | B4: 46095 | C4: 0.54166667 | D4: Neufeld | E4: Freundschaftspiel Felixdorf | F4: U16 | G4: =IF(F4="Großfeld","Großfeld",IF(F4="U16","Großfeld",IF(F4="U15","Großfeld",IF(F4="U14","Großfeld",IF(F4="U13","75x55",IF(F4="U11/U12","55x40",IF(F4="U9/U10","40x25",IF(F4="U8","29x22","25x20")))))))) -> Großfeld | H4: =IF(F4="Großfeld","7,32x2,44",IF(F4="U16","7,32x2,44",IF(F4="U15","7,32x2,44",IF(F4="U14","7,32x2,44",IF(F4="U13","5x2",IF(F4="U11/U12","5x2",IF(F4="U9/U10","5x2",IF(F3="Turnier","5x2","4 Minitore")))))))) -> 7,32x2,44 | I4: =IF(F4="Großfeld","5",IF(F4="U16","5",IF(F4="U15","5",IF(F4="U14","4",IF(F4="U13","4",IF(F4="U11/U12","4",IF(F4="U9/U10","4",IF(F4="U9","4","3")))))))) -> 5 | J4: =IF(A4="KM Neufeld","Pleninger Stefan",IF(A4="U16 LL","Josch Kögl",IF(A4="U15 LL Nord","Serdar Ekinci",IF(A4="U14 Nord","Gernot Servelda",IF(A4="U13 Nord","Thomas Pöschl & Lenz Honc",IF(A4="U11 Nord D","Mario Magler&Ronny Archam",IF(A4="U9","Thomas Brandl&Daniel Hofbauer",IF(A4="U8","Berger Tobias&Sebastian Putric",IF(A4="U7","Türkes Ömer&Mahsumi Taha",IF(A4="Camp","Berger Dieter",IF(A4="Turnier","Berger Dieter","FEHLER"))))))))))) -> Josch Kögl | K4: =IF(A4="KM Neufeld","+43 664 415 99 09",IF(A4="U16 LL","+43 650 262 82 63",IF(A4="U15 LL Nord","+43 650 701 02 44",IF(A4="U14 Nord","+43 676 401 09 13",IF(A4="U13 Nord","+43 677 613 55 114 & +43 664 114 43 52",IF(A4="U11 Nord D","+43 664 762 09 93 & +43 699 111 93 828",IF(A4="U9","+43 676 377 16 30 & +43 399 197 871 81",IF(A4="U8","+43 660 199 13 52 & +43 660 914 92 36",IF(A4="U7","+43 676 661 62 26 & +43 681 208 115 99",IF(A4="Camp","+43 660 77 39 500",IF(A4="Turnier","+43 660 77 39 500","FEHLER"))))))))))) -> +43 650 262 82 63
A5: =Heimspiele!C6 -> KM | B5: =Heimspiele!D6 -> 46277 | D5: =Heimspiele!F6 -> Neufeld | E5: =Heimspiele!G6 -> Winden | F5: Großfeld | G5: =IF(F5="Großfeld","Großfeld",IF(F5="U16","Großfeld",IF(F5="U15","Großfeld",IF(F5="U14","Großfeld",IF(F5="U13","75x55",IF(F5="U11/U12","55x40",IF(F5="U9/U10","40x25",IF(F5="U8","29x22","25x20")))))))) -> Großfeld | H5: =IF(F5="Großfeld","7,32x2,44",IF(F5="U16","7,32x2,44",IF(F5="U15","7,32x2,44",IF(F5="U14","7,32x2,44",IF(F5="U13","5x2",IF(F5="U11/U12","5x2",IF(F5="U9/U10","5x2","4 Minitore"))))))) -> 7,32x2,44 | I5: =IF(F5="Großfeld","5",IF(F5="U16","5",IF(F5="U15","5",IF(F5="U14","4",IF(F5="U13","4",IF(F5="U11/U12","4",IF(F5="U9/U10","4",IF(F5="U9","4","3")))))))) -> 5 | J5: =IF(A5="KM Neufeld","Pleninger Stefan",IF(A5="U16 LL","Josch Kögl",IF(A5="U15 LL Nord","Serdar Ekinci",IF(A5="U14 Nord","Gernot Servelda",IF(A5="U13 - Nord","Thomas Pöschl & Lenz Honc",IF(A5="U11 Nord D","Mario Magler&Ronny Archam",IF(A5="U9","Thomas Brandl&Daniel Hofbauer",IF(A5="U8","Berger Tobias&Sebastian Putric",IF(A5="U7","Türkes Ömer&Mahsumi Taha",IF(A5="Camp","Berger Dieter",IF(A5="Turnier","Berger Dieter","FEHLER"))))))))))) -> FEHLER | K5: =IF(A5="KM Neufeld","+43 664 415 99 09",IF(A5="U16 LL","+43 650 262 82 63",IF(A5="U15 LL Nord","+43 650 701 02 44",IF(A5="U14 - Nord","+43 676 401 09 13",IF(A5="U13 - Nord","+43 677 613 55 114 & +43 664 114 43 52",IF(A5="U11 Nord D","+43 664 762 09 93 & +43 699 111 93 828",IF(A5="U9","+43 676 377 16 30 & +43 399 197 871 81",IF(A5="U8","+43 660 199 13 52 & +43 660 914 92 36",IF(A5="U7","+43 676 661 62 26 & +43 681 208 115 99",IF(A5="Camp","+43 660 77 39 500",IF(A5="Turnier","+43 660 77 39 500","FEHLER"))))))))))) -> FEHLER
A6: U15 LL Nord | B6: 46096 | C6: 0.45833333 | D6: Neufeld | E6: Freundschaftsspiel Baden | F6: U15 | G6: =IF(F6="Großfeld","Großfeld",IF(F6="U16","Großfeld",IF(F6="U15","Großfeld",IF(F6="U14","Großfeld",IF(F6="U13","75x55",IF(F6="U11/U12","55x40",IF(F6="U9/U10","40x25",IF(F6="U8","29x22","25x20")))))))) -> Großfeld | H6: =IF(F6="Großfeld","7,32x2,44",IF(F6="U16","7,32x2,44",IF(F6="U15","7,32x2,44",IF(F6="U14","7,32x2,44",IF(F6="U13","5x2",IF(F6="U11/U12","5x2",IF(F6="U9/U10","5x2",IF(F5="Turnier","5x2","4 Minitore")))))))) -> 7,32x2,44 | I6: =IF(F6="Großfeld","5",IF(F6="U16","5",IF(F6="U15","5",IF(F6="U14","4",IF(F6="U13","4",IF(F6="U11/U12","4",IF(F6="U9/U10","4",IF(F6="U9","4","3")))))))) -> 5 | J6: =IF(A6="KM Neufeld","Pleninger Stefan",IF(A6="U16 LL","Josch Kögl",IF(A6="U15 LL Nord","Serdar Ekinci",IF(A6="U14 Nord","Gernot Servelda",IF(A6="U13 Nord","Thomas Pöschl & Lenz Honc",IF(A6="U11 Nord D","Mario Magler&Ronny Archam",IF(A6="U9","Thomas Brandl&Daniel Hofbauer",IF(A6="U8","Berger Tobias&Sebastian Putric",IF(A6="U7","Türkes Ömer&Mahsumi Taha",IF(A6="Camp","Berger Dieter",IF(A6="Turnier","Berger Dieter","FEHLER"))))))))))) -> Serdar Ekinci | K6: =IF(A6="KM Neufeld","+43 664 415 99 09",IF(A6="U16 LL","+43 650 262 82 63",IF(A6="U15 LL Nord","+43 650 701 02 44",IF(A6="U14 Nord","+43 676 401 09 13",IF(A6="U13 Nord","+43 677 613 55 114 & +43 664 114 43 52",IF(A6="U11 Nord D","+43 664 762 09 93 & +43 699 111 93 828",IF(A6="U9","+43 676 377 16 30 & +43 399 197 871 81",IF(A6="U8","+43 660 199 13 52 & +43 660 914 92 36",IF(A6="U7","+43 676 661 62 26 & +43 681 208 115 99",IF(A6="Camp","+43 660 77 39 500",IF(A6="Turnier","+43 660 77 39 500","FEHLER"))))))))))) -> +43 650 701 02 44
A7: =Heimspiele!C8 -> KM | B7: =Heimspiele!D8 -> 46291 | D7: =Heimspiele!F8 -> Neufeld | E7: =Heimspiele!G8 -> Wallern | F7: Großfeld | G7: =IF(F7="Großfeld","Großfeld",IF(F7="U16","Großfeld",IF(F7="U15","Großfeld",IF(F7="U14","Großfeld",IF(F7="U13","75x55",IF(F7="U11/U12","55x40",IF(F7="U9/U10","40x25",IF(F7="U8","29x22","25x20")))))))) -> Großfeld | H7: =IF(F7="Großfeld","7,32x2,44",IF(F7="U16","7,32x2,44",IF(F7="U15","7,32x2,44",IF(F7="U14","7,32x2,44",IF(F7="U13","5x2",IF(F7="U11/U12","5x2",IF(F7="U9/U10","5x2","4 Minitore"))))))) -> 7,32x2,44 | I7: =IF(F7="Großfeld","5",IF(F7="U16","5",IF(F7="U15","5",IF(F7="U14","4",IF(F7="U13","4",IF(F7="U11/U12","4",IF(F7="U9/U10","4",IF(F7="U9","4","3")))))))) -> 5 | J7: =IF(A7="KM Neufeld","Pleninger Stefan",IF(A7="U16 LL","Josch Kögl",IF(A7="U15 LL Nord","Serdar Ekinci",IF(A7="U14 Nord","Gernot Servelda",IF(A7="U13 - Nord","Thomas Pöschl & Lenz Honc",IF(A7="U11 Nord D","Mario Magler&Ronny Archam",IF(A7="U9","Thomas Brandl&Daniel Hofbauer",IF(A7="U8","Berger Tobias&Sebastian Putric",IF(A7="U7","Türkes Ömer&Mahsumi Taha",IF(A7="Camp","Berger Dieter",IF(A7="Turnier","Berger Dieter","FEHLER"))))))))))) -> FEHLER | K7: =IF(A7="KM Neufeld","+43 664 415 99 09",IF(A7="U16 LL","+43 650 262 82 63",IF(A7="U15 LL Nord","+43 650 701 02 44",IF(A7="U14 - Nord","+43 676 401 09 13",IF(A7="U13 - Nord","+43 677 613 55 114 & +43 664 114 43 52",IF(A7="U11 Nord D","+43 664 762 09 93 & +43 699 111 93 828",IF(A7="U9","+43 676 377 16 30 & +43 399 197 871 81",IF(A7="U8","+43 660 199 13 52 & +43 660 914 92 36",IF(A7="U7","+43 676 661 62 26 & +43 681 208 115 99",IF(A7="Camp","+43 660 77 39 500",IF(A7="Turnier","+43 660 77 39 500","FEHLER"))))))))))) -> FEHLER
A8: U11 Nord D | B8: 46102 | C8: 0.5 | D8: Neufeld | E8: Freundschaftspiel Pöttsching | F8: U11/U12 | G8: =IF(F8="Großfeld","Großfeld",IF(F8="U16","Großfeld",IF(F8="U15","Großfeld",IF(F8="U14","Großfeld",IF(F8="U13","75x55",IF(F8="U11/U12","55x40",IF(F8="U9/U10","40x25",IF(F8="U8","29x22","25x20")))))))) -> 55x40 | H8: =IF(F8="Großfeld","7,32x2,44",IF(F8="U16","7,32x2,44",IF(F8="U15","7,32x2,44",IF(F8="U14","7,32x2,44",IF(F8="U13","5x2",IF(F8="U11/U12","5x2",IF(F8="U9/U10","5x2",IF(F7="Turnier","5x2","4 Minitore")))))))) -> 5x2 | I8: =IF(F8="Großfeld","5",IF(F8="U16","5",IF(F8="U15","5",IF(F8="U14","4",IF(F8="U13","4",IF(F8="U11/U12","4",IF(F8="U9/U10","4",IF(F8="U9","4","3")))))))) -> 4 | J8: =IF(A8="KM Neufeld","Pleninger Stefan",IF(A8="U16 LL","Josch Kögl",IF(A8="U15 LL Nord","Serdar Ekinci",IF(A8="U14 Nord","Gernot Servelda",IF(A8="U13 Nord","Thomas Pöschl & Lenz Honc",IF(A8="U11 Nord D","Mario Magler&Ronny Archam",IF(A8="U9","Thomas Brandl&Daniel Hofbauer",IF(A8="U8","Berger Tobias&Sebastian Putric",IF(A8="U7","Türkes Ömer&Mahsumi Taha",IF(A8="Camp","Berger Dieter",IF(A8="Turnier","Berger Dieter","FEHLER"))))))))))) -> Mario Magler&Ronny Archam | K8: =IF(A8="KM Neufeld","+43 664 415 99 09",IF(A8="U16 LL","+43 650 262 82 63",IF(A8="U15 LL Nord","+43 650 701 02 44",IF(A8="U14 Nord","+43 676 401 09 13",IF(A8="U13 Nord","+43 677 613 55 114 & +43 664 114 43 52",IF(A8="U11 Nord D","+43 664 762 09 93 & +43 699 111 93 828",IF(A8="U9","+43 676 377 16 30 & +43 399 197 871 81",IF(A8="U8","+43 660 199 13 52 & +43 660 914 92 36",IF(A8="U7","+43 676 661 62 26 & +43 681 208 115 99",IF(A8="Camp","+43 660 77 39 500",IF(A8="Turnier","+43 660 77 39 500","FEHLER"))))))))))) -> +43 664 762 09 93 & +43 699 111 93 828
A9: =Heimspiele!C10 -> KM | B9: =Heimspiele!D10 -> 46305 | D9: =Heimspiele!F10 -> Neufeld | E9: =Heimspiele!G10 -> Wimpassing | F9: Großfeld | G9: =IF(F9="Großfeld","Großfeld",IF(F9="U16","Großfeld",IF(F9="U15","Großfeld",IF(F9="U14","Großfeld",IF(F9="U13","75x55",IF(F9="U11/U12","55x40",IF(F9="U9/U10","40x25",IF(F9="U8","29x22","25x20")))))))) -> Großfeld | H9: =IF(F9="Großfeld","7,32x2,44",IF(F9="U16","7,32x2,44",IF(F9="U15","7,32x2,44",IF(F9="U14","7,32x2,44",IF(F9="U13","5x2",IF(F9="U11/U12","5x2",IF(F9="U9/U10","5x2","4 Minitore"))))))) -> 7,32x2,44 | I9: =IF(F9="Großfeld","5",IF(F9="U16","5",IF(F9="U15","5",IF(F9="U14","4",IF(F9="U13","4",IF(F9="U11/U12","4",IF(F9="U9/U10","4",IF(F9="U9","4","3")))))))) -> 5 | J9: =IF(A9="KM Neufeld","Pleninger Stefan",IF(A9="U16 LL","Josch Kögl",IF(A9="U15 LL Nord","Serdar Ekinci",IF(A9="U14 Nord","Gernot Servelda",IF(A9="U13 - Nord","Thomas Pöschl & Lenz Honc",IF(A9="U11 Nord D","Mario Magler&Ronny Archam",IF(A9="U9","Thomas Brandl&Daniel Hofbauer",IF(A9="U8","Berger Tobias&Sebastian Putric",IF(A9="U7","Türkes Ömer&Mahsumi Taha",IF(A9="Camp","Berger Dieter",IF(A9="Turnier","Berger Dieter","FEHLER"))))))))))) -> FEHLER | K9: =IF(A9="KM Neufeld","+43 664 415 99 09",IF(A9="U16 LL","+43 650 262 82 63",IF(A9="U15 LL Nord","+43 650 701 02 44",IF(A9="U14 - Nord","+43 676 401 09 13",IF(A9="U13 - Nord","+43 677 613 55 114 & +43 664 114 43 52",IF(A9="U11 Nord D","+43 664 762 09 93 & +43 699 111 93 828",IF(A9="U9","+43 676 377 16 30 & +43 399 197 871 81",IF(A9="U8","+43 660 199 13 52 & +43 660 914 92 36",IF(A9="U7","+43 676 661 62 26 & +43 681 208 115 99",IF(A9="Camp","+43 660 77 39 500",IF(A9="Turnier","+43 660 77 39 500","FEHLER"))))))))))) -> FEHLER
A10: =Heimspiele!C3 -> KM | B10: =Heimspiele!D3 -> 46256 | C10: =Heimspiele!E3 -> 0.70833333 | D10: =Heimspiele!F3 -> Deutsch Jahrndorf | E10: =Heimspiele!G3 -> Deutsch Jahrndorf | F10: Großfeld | G10: =IF(F10="Großfeld","Großfeld",IF(F10="U16","Großfeld",IF(F10="U15","Großfeld",IF(F10="U14","Großfeld",IF(F10="U13","75x55",IF(F10="U11/U12","55x40",IF(F10="U9/U10","40x25",IF(F10="U8","29x22","25x20")))))))) -> Großfeld | H10: =IF(F10="Großfeld","7,32x2,44",IF(F10="U16","7,32x2,44",IF(F10="U15","7,32x2,44",IF(F10="U14","7,32x2,44",IF(F10="U13","5x2",IF(F10="U11/U12","5x2",IF(F10="U9/U10","5x2","4 Minitore"))))))) -> 7,32x2,44 | I10: =IF(F10="Großfeld","5",IF(F10="U16","5",IF(F10="U15","5",IF(F10="U14","4",IF(F10="U13","4",IF(F10="U11/U12","4",IF(F10="U9/U10","4",IF(F10="U9","4","3")))))))) -> 5 | J10: =IF(A10="KM Neufeld","Pleninger Stefan",IF(A10="U16 LL","Josch Kögl",IF(A10="U15 LL Nord","Serdar Ekinci",IF(A10="U14 Nord","Gernot Servelda",IF(A10="U13 Nord","Thomas Pöschl & Lenz Honc",IF(A10="U11 Nord D","Mario Magler&Ronny Archam",IF(A10="U9","Thomas Brandl&Daniel Hofbauer",IF(A10="U8","Berger Tobias&Sebastian Putric",IF(A10="U7","Türkes Ömer&Mahsumi Taha",IF(A10="Camp","Berger Dieter",IF(A10="Turnier","Berger Dieter","FEHLER"))))))))))) -> FEHLER | K10: =IF(A10="KM Neufeld","+43 664 415 99 09",IF(A10="U16 LL","+43 650 262 82 63",IF(A10="U15 LL Nord","+43 650 701 02 44",IF(A10="U14 Nord","+43 676 401 09 13",IF(A10="U13 Nord","+43 677 613 55 114 & +43 664 114 43 52",IF(A10="U11 Nord D","+43 664 762 09 93 & +43 699 111 93 828",IF(A10="U9","+43 676 377 16 30 & +43 399 197 871 81",IF(A10="U8","+43 660 199 13 52 & +43 660 914 92 36",IF(A10="U7","+43 676 661 62 26 & +43 681 208 115 99",IF(A10="Camp","+43 660 77 39 500",IF(A10="Turnier","+43 660 77 39 500","FEHLER"))))))))))) -> FEHLER
A11: =Heimspiele!C12 -> KM | B11: =Heimspiele!D12 -> 46319 | D11: =Heimspiele!F12 -> Neufeld | E11: =Heimspiele!G12 -> Gols | F11: Großfeld | G11: =IF(F11="Großfeld","Großfeld",IF(F11="U16","Großfeld",IF(F11="U15","Großfeld",IF(F11="U14","Großfeld",IF(F11="U13","75x55",IF(F11="U11/U12","55x40",IF(F11="U9/U10","40x25",IF(F11="U8","29x22","25x20")))))))) -> Großfeld | H11: =IF(F11="Großfeld","7,32x2,44",IF(F11="U16","7,32x2,44",IF(F11="U15","7,32x2,44",IF(F11="U14","7,32x2,44",IF(F11="U13","5x2",IF(F11="U11/U12","5x2",IF(F11="U9/U10","5x2","4 Minitore"))))))) -> 7,32x2,44 | I11: =IF(F11="Großfeld","5",IF(F11="U16","5",IF(F11="U15","5",IF(F11="U14","4",IF(F11="U13","4",IF(F11="U11/U12","4",IF(F11="U9/U10","4",IF(F11="U9","4","3")))))))) -> 5 | J11: =IF(A11="KM Neufeld","Pleninger Stefan",IF(A11="U16 LL","Josch Kögl",IF(A11="U15 LL Nord","Serdar Ekinci",IF(A11="U14 Nord","Gernot Servelda",IF(A11="U13 - Nord","Thomas Pöschl & Lenz Honc",IF(A11="U11 Nord D","Mario Magler&Ronny Archam",IF(A11="U9","Thomas Brandl&Daniel Hofbauer",IF(A11="U8","Berger Tobias&Sebastian Putric",IF(A11="U7","Türkes Ömer&Mahsumi Taha",IF(A11="Camp","Berger Dieter",IF(A11="Turnier","Berger Dieter","FEHLER"))))))))))) -> FEHLER | K11: =IF(A11="KM Neufeld","+43 664 415 99 09",IF(A11="U16 LL","+43 650 262 82 63",IF(A11="U15 LL Nord","+43 650 701 02 44",IF(A11="U14 - Nord","+43 676 401 09 13",IF(A11="U13 - Nord","+43 677 613 55 114 & +43 664 114 43 52",IF(A11="U11 Nord D","+43 664 762 09 93 & +43 699 111 93 828",IF(A11="U9","+43 676 377 16 30 & +43 399 197 871 81",IF(A11="U8","+43 660 199 13 52 & +43 660 914 92 36",IF(A11="U7","+43 676 661 62 26 & +43 681 208 115 99",IF(A11="Camp","+43 660 77 39 500",IF(A11="Turnier","+43 660 77 39 500","FEHLER"))))))))))) -> FEHLER
A12: =Heimspiele!C13 -> KM | B12: =Heimspiele!D13 -> 46326 | D12: =Heimspiele!F13 -> Illmitz | E12: =Heimspiele!G13 -> Illmitz | F12: Großfeld | G12: =IF(F12="Großfeld","Großfeld",IF(F12="U16","Großfeld",IF(F12="U15","Großfeld",IF(F12="U14","Großfeld",IF(F12="U13","75x55",IF(F12="U11/U12","55x40",IF(F12="U9/U10","40x25",IF(F12="U8","29x22","25x20")))))))) -> Großfeld | H12: =IF(F12="Großfeld","7,32x2,44",IF(F12="U16","7,32x2,44",IF(F12="U15","7,32x2,44",IF(F12="U14","7,32x2,44",IF(F12="U13","5x2",IF(F12="U11/U12","5x2",IF(F12="U9/U10","5x2","4 Minitore"))))))) -> 7,32x2,44 | I12: =IF(F12="Großfeld","5",IF(F12="U16","5",IF(F12="U15","5",IF(F12="U14","4",IF(F12="U13","4",IF(F12="U11/U12","4",IF(F12="U9/U10","4",IF(F12="U9","4","3")))))))) -> 5 | J12: =IF(A12="KM Neufeld","Pleninger Stefan",IF(A12="U16 LL","Josch Kögl",IF(A12="U15 LL Nord","Serdar Ekinci",IF(A12="U14 Nord","Gernot Servelda",IF(A12="U13 - Nord","Thomas Pöschl & Lenz Honc",IF(A12="U11 Nord D","Mario Magler&Ronny Archam",IF(A12="U9","Thomas Brandl&Daniel Hofbauer",IF(A12="U8","Berger Tobias&Sebastian Putric",IF(A12="U7","Türkes Ömer&Mahsumi Taha",IF(A12="Camp","Berger Dieter",IF(A12="Turnier","Berger Dieter","FEHLER"))))))))))) -> FEHLER | K12: =IF(A12="KM Neufeld","+43 664 415 99 09",IF(A12="U16 LL","+43 650 262 82 63",IF(A12="U15 LL Nord","+43 650 701 02 44",IF(A12="U14 - Nord","+43 676 401 09 13",IF(A12="U13 - Nord","+43 677 613 55 114 & +43 664 114 43 52",IF(A12="U11 Nord D","+43 664 762 09 93 & +43 699 111 93 828",IF(A12="U9","+43 676 377 16 30 & +43 399 197 871 81",IF(A12="U8","+43 660 199 13 52 & +43 660 914 92 36",IF(A12="U7","+43 676 661 62 26 & +43 681 208 115 99",IF(A12="Camp","+43 660 77 39 500",IF(A12="Turnier","+43 660 77 39 500","FEHLER"))))))))))) -> FEHLER
A13: =Heimspiele!C5 -> U14 | B13: =Heimspiele!D5 -> 46033 | C13: =Heimspiele!E5 -> 0 | D13: =Heimspiele!F5 -> 0 | E13: =Heimspiele!G5 -> 0 | F13: U14 | G13: =IF(F13="Großfeld","Großfeld",IF(F13="U16","Großfeld",IF(F13="U15","Großfeld",IF(F13="U14","Großfeld",IF(F13="U13","75x55",IF(F13="U11/U12","55x40",IF(F13="U9/U10","40x25",IF(F13="U8","29x22","25x20")))))))) -> Großfeld | H13: =IF(F13="Großfeld","7,32x2,44",IF(F13="U16","7,32x2,44",IF(F13="U15","7,32x2,44",IF(F13="U14","7,32x2,44",IF(F13="U13","5x2",IF(F13="U11/U12","5x2",IF(F13="U9/U10","5x2","4 Minitore"))))))) -> 7,32x2,44 | I13: =IF(F13="Großfeld","5",IF(F13="U16","5",IF(F13="U15","5",IF(F13="U14","4",IF(F13="U13","4",IF(F13="U11/U12","4",IF(F13="U9/U10","4",IF(F13="U9","4","3")))))))) -> 4 | J13: =IF(A13="KM Neufeld","Pleninger Stefan",IF(A13="U16 LL","Josch Kögl",IF(A13="U15 LL Nord","Serdar Ekinci",IF(A13="U14 Nord","Gernot Servelda",IF(A13="U13 Nord","Thomas Pöschl & Lenz Honc",IF(A13="U11 Nord D","Mario Magler&Ronny Archam",IF(A13="U9","Thomas Brandl&Daniel Hofbauer",IF(A13="U8","Berger Tobias&Sebastian Putric",IF(A13="U7","Türkes Ömer&Mahsumi Taha",IF(A13="Camp","Berger Dieter",IF(A13="Turnier","Berger Dieter","FEHLER"))))))))))) -> FEHLER | K13: =IF(A13="KM Neufeld","+43 664 415 99 09",IF(A13="U16 LL","+43 650 262 82 63",IF(A13="U15 LL Nord","+43 650 701 02 44",IF(A13="U14 Nord","+43 676 401 09 13",IF(A13="U13 Nord","+43 677 613 55 114 & +43 664 114 43 52",IF(A13="U11 Nord D","+43 664 762 09 93 & +43 699 111 93 828",IF(A13="U9","+43 676 377 16 30 & +43 399 197 871 81",IF(A13="U8","+43 660 199 13 52 & +43 660 914 92 36",IF(A13="U7","+43 676 661 62 26 & +43 681 208 115 99",IF(A13="Camp","+43 660 77 39 500",IF(A13="Turnier","+43 660 77 39 500","FEHLER"))))))))))) -> FEHLER
A14: =Heimspiele!C15 -> U16 | B14: =Heimspiele!D15 -> 46023 | D14: =Heimspiele!F15 -> 0 | E14: =Heimspiele!G15 -> 0 | F14: Großfeld | G14: =IF(F14="Großfeld","Großfeld",IF(F14="U16","Großfeld",IF(F14="U15","Großfeld",IF(F14="U14","Großfeld",IF(F14="U13","75x55",IF(F14="U11/U12","55x40",IF(F14="U9/U10","40x25",IF(F14="U8","29x22","25x20")))))))) -> Großfeld | H14: =IF(F14="Großfeld","7,32x2,44",IF(F14="U16","7,32x2,44",IF(F14="U15","7,32x2,44",IF(F14="U14","7,32x2,44",IF(F14="U13","5x2",IF(F14="U11/U12","5x2",IF(F14="U9/U10","5x2","4 Minitore"))))))) -> 7,32x2,44 | I14: =IF(F14="Großfeld","5",IF(F14="U16","5",IF(F14="U15","5",IF(F14="U14","4",IF(F14="U13","4",IF(F14="U11/U12","4",IF(F14="U9/U10","4",IF(F14="U9","4","3")))))))) -> 5 | J14: =IF(A14="KM Neufeld","Pleninger Stefan",IF(A14="U16 LL","Josch Kögl",IF(A14="U15 LL Nord","Serdar Ekinci",IF(A14="U14 Nord","Gernot Servelda",IF(A14="U13 - Nord","Thomas Pöschl & Lenz Honc",IF(A14="U11 Nord D","Mario Magler&Ronny Archam",IF(A14="U9","Thomas Brandl&Daniel Hofbauer",IF(A14="U8","Berger Tobias&Sebastian Putric",IF(A14="U7","Türkes Ömer&Mahsumi Taha",IF(A14="Camp","Berger Dieter",IF(A14="Turnier","Berger Dieter","FEHLER"))))))))))) -> FEHLER | K14: =IF(A14="KM Neufeld","+43 664 415 99 09",IF(A14="U16 LL","+43 650 262 82 63",IF(A14="U15 LL Nord","+43 650 701 02 44",IF(A14="U14 - Nord","+43 676 401 09 13",IF(A14="U13 - Nord","+43 677 613 55 114 & +43 664 114 43 52",IF(A14="U11 Nord D","+43 664 762 09 93 & +43 699 111 93 828",IF(A14="U9","+43 676 377 16 30 & +43 399 197 871 81",IF(A14="U8","+43 660 199 13 52 & +43 660 914 92 36",IF(A14="U7","+43 676 661 62 26 & +43 681 208 115 99",IF(A14="Camp","+43 660 77 39 500",IF(A14="Turnier","+43 660 77 39 500","FEHLER"))))))))))) -> FEHLER
A15: =Heimspiele!C16 -> U16 | B15: =Heimspiele!D16 -> 46024 | D15: =Heimspiele!F16 -> 0 | E15: =Heimspiele!G16 -> 0 | F15: Großfeld | G15: =IF(F15="Großfeld","Großfeld",IF(F15="U16","Großfeld",IF(F15="U15","Großfeld",IF(F15="U14","Großfeld",IF(F15="U13","75x55",IF(F15="U11/U12","55x40",IF(F15="U9/U10","40x25",IF(F15="U8","29x22","25x20")))))))) -> Großfeld | H15: =IF(F15="Großfeld","7,32x2,44",IF(F15="U16","7,32x2,44",IF(F15="U15","7,32x2,44",IF(F15="U14","7,32x2,44",IF(F15="U13","5x2",IF(F15="U11/U12","5x2",IF(F15="U9/U10","5x2","4 Minitore"))))))) -> 7,32x2,44 | I15: =IF(F15="Großfeld","5",IF(F15="U16","5",IF(F15="U15","5",IF(F15="U14","4",IF(F15="U13","4",IF(F15="U11/U12","4",IF(F15="U9/U10","4",IF(F15="U9","4","3")))))))) -> 5 | J15: =IF(A15="KM Neufeld","Pleninger Stefan",IF(A15="U16 LL","Josch Kögl",IF(A15="U15 LL Nord","Serdar Ekinci",IF(A15="U14 Nord","Gernot Servelda",IF(A15="U13 - Nord","Thomas Pöschl & Lenz Honc",IF(A15="U11 Nord D","Mario Magler&Ronny Archam",IF(A15="U9","Thomas Brandl&Daniel Hofbauer",IF(A15="U8","Berger Tobias&Sebastian Putric",IF(A15="U7","Türkes Ömer&Mahsumi Taha",IF(A15="Camp","Berger Dieter",IF(A15="Turnier","Berger Dieter","FEHLER"))))))))))) -> FEHLER | K15: =IF(A15="KM Neufeld","+43 664 415 99 09",IF(A15="U16 LL","+43 650 262 82 63",IF(A15="U15 LL Nord","+43 650 701 02 44",IF(A15="U14 - Nord","+43 676 401 09 13",IF(A15="U13 - Nord","+43 677 613 55 114 & +43 664 114 43 52",IF(A15="U11 Nord D","+43 664 762 09 93 & +43 699 111 93 828",IF(A15="U9","+43 676 377 16 30 & +43 399 197 871 81",IF(A15="U8","+43 660 199 13 52 & +43 660 914 92 36",IF(A15="U7","+43 676 661 62 26 & +43 681 208 115 99",IF(A15="Camp","+43 660 77 39 500",IF(A15="Turnier","+43 660 77 39 500","FEHLER"))))))))))) -> FEHLER
A16: =Heimspiele!C17 -> U16 | B16: =Heimspiele!D17 -> 46025 | D16: =Heimspiele!F17 -> 0 | E16: =Heimspiele!G17 -> 0 | F16: Großfeld | G16: =IF(F16="Großfeld","Großfeld",IF(F16="U16","Großfeld",IF(F16="U15","Großfeld",IF(F16="U14","Großfeld",IF(F16="U13","75x55",IF(F16="U11/U12","55x40",IF(F16="U9/U10","40x25",IF(F16="U8","29x22","25x20")))))))) -> Großfeld | H16: =IF(F16="Großfeld","7,32x2,44",IF(F16="U16","7,32x2,44",IF(F16="U15","7,32x2,44",IF(F16="U14","7,32x2,44",IF(F16="U13","5x2",IF(F16="U11/U12","5x2",IF(F16="U9/U10","5x2","4 Minitore"))))))) -> 7,32x2,44 | I16: =IF(F16="Großfeld","5",IF(F16="U16","5",IF(F16="U15","5",IF(F16="U14","4",IF(F16="U13","4",IF(F16="U11/U12","4",IF(F16="U9/U10","4",IF(F16="U9","4","3")))))))) -> 5 | J16: =IF(A16="KM Neufeld","Pleninger Stefan",IF(A16="U16 LL","Josch Kögl",IF(A16="U15 LL Nord","Serdar Ekinci",IF(A16="U14 Nord","Gernot Servelda",IF(A16="U13 - Nord","Thomas Pöschl & Lenz Honc",IF(A16="U11 Nord D","Mario Magler&Ronny Archam",IF(A16="U9","Thomas Brandl&Daniel Hofbauer",IF(A16="U8","Berger Tobias&Sebastian Putric",IF(A16="U7","Türkes Ömer&Mahsumi Taha",IF(A16="Camp","Berger Dieter",IF(A16="Turnier","Berger Dieter","FEHLER"))))))))))) -> FEHLER | K16: =IF(A16="KM Neufeld","+43 664 415 99 09",IF(A16="U16 LL","+43 650 262 82 63",IF(A16="U15 LL Nord","+43 650 701 02 44",IF(A16="U14 - Nord","+43 676 401 09 13",IF(A16="U13 - Nord","+43 677 613 55 114 & +43 664 114 43 52",IF(A16="U11 Nord D","+43 664 762 09 93 & +43 699 111 93 828",IF(A16="U9","+43 676 377 16 30 & +43 399 197 871 81",IF(A16="U8","+43 660 199 13 52 & +43 660 914 92 36",IF(A16="U7","+43 676 661 62 26 & +43 681 208 115 99",IF(A16="Camp","+43 660 77 39 500",IF(A16="Turnier","+43 660 77 39 500","FEHLER"))))))))))) -> FEHLER
A17: =Heimspiele!C7 -> U12_1 | B17: =Heimspiele!D7 -> 46043 | C17: =Heimspiele!E7 -> 0 | D17: =Heimspiele!F7 -> 0 | E17: =Heimspiele!G7 -> 0 | F17: U13 | G17: =IF(F17="Großfeld","Großfeld",IF(F17="U16","Großfeld",IF(F17="U15","Großfeld",IF(F17="U14","Großfeld",IF(F17="U13","75x55",IF(F17="U11/U12","55x40",IF(F17="U9/U10","40x25",IF(F17="U8","29x22","25x20")))))))) -> 75x55 | H17: =IF(F17="Großfeld","7,32x2,44",IF(F17="U16","7,32x2,44",IF(F17="U15","7,32x2,44",IF(F17="U14","7,32x2,44",IF(F17="U13","5x2",IF(F17="U11/U12","5x2",IF(F17="U9/U10","5x2","4 Minitore"))))))) -> 5x2 | I17: =IF(F17="Großfeld","5",IF(F17="U16","5",IF(F17="U15","5",IF(F17="U14","4",IF(F17="U13","4",IF(F17="U11/U12","4",IF(F17="U9/U10","4",IF(F17="U9","4","3")))))))) -> 4 | J17: =IF(A17="KM Neufeld","Pleninger Stefan",IF(A17="U16 LL","Josch Kögl",IF(A17="U15 LL Nord","Serdar Ekinci",IF(A17="U14 Nord","Gernot Servelda",IF(A17="U13 Nord","Thomas Pöschl & Lenz Honc",IF(A17="U11 Nord D","Mario Magler&Ronny Archam",IF(A17="U9","Thomas Brandl&Daniel Hofbauer",IF(A17="U8","Berger Tobias&Sebastian Putric",IF(A17="U7","Türkes Ömer&Mahsumi Taha",IF(A17="Camp","Berger Dieter",IF(A17="Turnier","Berger Dieter","FEHLER"))))))))))) -> FEHLER | K17: =IF(A17="KM Neufeld","+43 664 415 99 09",IF(A17="U16 LL","+43 650 262 82 63",IF(A17="U15 LL Nord","+43 650 701 02 44",IF(A17="U14 Nord","+43 676 401 09 13",IF(A17="U13 Nord","+43 677 613 55 114 & +43 664 114 43 52",IF(A17="U11 Nord D","+43 664 762 09 93 & +43 699 111 93 828",IF(A17="U9","+43 676 377 16 30 & +43 399 197 871 81",IF(A17="U8","+43 660 199 13 52 & +43 660 914 92 36",IF(A17="U7","+43 676 661 62 26 & +43 681 208 115 99",IF(A17="Camp","+43 660 77 39 500",IF(A17="Turnier","+43 660 77 39 500","FEHLER"))))))))))) -> FEHLER
