Workbook

Sheet Nach Mannschaften sortiert
A1: fortlaufende Nummer | B1: Runde | C1: Mannschaft | D1: fixierter Termin | E1: fixierte Uhrzeit | F1: Ort | G1: Gegner | H1: Auswärt/Heim
A2: 1 | B2: 0 | C2: U15 | D2: 46199 | E2: 0.66666667 | F2: Wimpassing | G2: SK Rapid Wien | H2: Heim
A3: =A2+1 -> 2 | B3: 0 | C3: U16 | D3: 46199 | E3: 0.75 | F3: Wimpassing | G3: SK Rapid Wien | H3: Heim
A4: =A3+1 -> 3 | B4: 0 | C4: KM | D4: 46213 | E4: 0.79166667 | F4: Neudörfl | G4: Neudörfl | H4: Auswärts
A5: =A4+1 -> 4 | B5: 0 | C5: KM | D5: 46217 | E5: 0.8125 | F5: Pöttsching | G5: Pöttsching | H5: Auswärts
A6: =A5+1 -> 5 | B6: 0 | C6: KM | D6: 46220 | E6: 0.79166667 | F6: Rohbach | G6: Rohrbach | H6: Auswärts
A7: =A6+1 -> 6 | B7: 0 | C7: KM | D7: 46227 | E7: 0.8125 | F7: Sommerein | G7: Sommerein | H7: Auswärts
A8: =A7+1 -> 7 | B8: 0 | C8: U23 | D8: 46234 | E8: 0.70833333 | F8: Wiener Neustadt | G8: Admira Wiener Neustadt | H8: Auswärts
A9: =A8+1 -> 8 | B9: 0 | C9: KM | D9: 46235 | E9: 0.72916667 | F9: Kittsee | G9: Kittsee | H9: Auswärts
A10: =A9+1 -> 9 | B10: 0 | C10: U16 | D10: 46236 | E10: 0.4375 | F10: Neufeld | G10: Theresienfeld | H10: Heim
A11: =A10+1 -> 10 | B11: 0 | C11: KM | D11: 46241 | E11: 0.79166667 | F11: Neufeld | G11: Bad Fischau | H11: Heim
A12: =A11+1 -> 11 | B12: 0 | C12: U16 | D12: 46243 | E12: 0.45833333 | F12: Wiener Neudorf | G12: Wiener Neudorf | H12: Auswärts
A13: =A12+1 -> 12 | B13: 0 | C13: U14 | D13: 46243 | E13: 0.625 | F13: Großhöflein | G13: Vienna U13 | H13: Heim
A14: =A13+1 -> 13 | B14: 0 | C14: U23 | D14: 46245 | E14: 0.79166667 | F14: Wr. Neustadt | G14: Admira Wiener Neustadt | H14: Auswärts
... A48: =A47+1 -> 47 | B48: 13 | C48: U23 | D48: 46333 | E48: 0.60416667 | F48: Neufeld | G48: Andau | H48: Heim
A49: =A48+1 -> 48 | B49: 1 | C49: U16 | D49: 46271 | G49: Spielfrei
A50: =A49+1 -> 49 | B50: 2 | C50: U16 | D50: 46277 | E50: 0.52083333 | F50: Gols | G50: GMWP | H50: Auswärts
A51: =A50+1 -> 50 | B51: 3 | C51: U16 | D51: 46284 | E51: 0.70833333 | F51: Wimpassing | G51: Eisenstadt | H51: Heim
A52: =A51+1 -> 51 | B52: 4 | C52: U16 | D52: 46292 | E52: 0.70833333 | F52: Großhöflein | G52: Großhöflein | H52: Auswärts
A53: =A52+1 -> 52 | B53: 5 | C53: U16 | D53: 46298 | E53: 0.58333333 | F53: Neufeld | G53: Neusiedl | H53: Heim
A54: =A53+1 -> 53 | B54: 6 | C54: U16 | D54: 46305 | E54: 0.66666667 | F54: Neufeld | G54: Parndorf | H54: Heim
A55: =A54+1 -> 54 | B55: 7 | C55: U16 | D55: 46311 | E55: 0.75 | F55: St. Georgen | G55: St. Georgen/Eisenstadt | H55: Auswärts
A56: =A55+1 -> 55 | B56: 8 | C56: U16 | D56: 46320 | G56: Spielfrei
A57: =A56+1 -> 56 | B57: 9 | C57: U16 | D57: 46326 | E57: 0.60416667 | F57: Neufeld | G57: SPG GMWP | H57: Heim
A58: =A57+1 -> 57 | B58: 10 | C58: U16 | D58: 46333 | E58: 0.54166667 | F58: Trausdorf | G58: Eisenstadt | H58: Auswärts
A59: =A58+1 -> 58 | B59: 11 | C59: U16 | D59: 46340 | E59: 0.625 | F59: Neufeld | G59: Großhöflein | H59: Heim
A60: =A59+1 -> 59 | B60: 1 | C60: U14 | D60: 46270 | E60: 0.4375 | F60: Großhöflein | G60: St. Georgen/Eisenstadt | H60: Heim
A61: =A60+1 -> 60 | B61: 2 | C61: U14 | D61: 46288 | E61: 0.79166667 | F61: Neudörfl | G61: Neudörfl | H61: Auswärts
A62: =A61+1 -> 61 | B62: 3 | C62: U14 | D62: 46284 | E62: 0.66666667 | F62: Großhöflein | G62: Parndorf | H62: Heim
A63: =A62+1 -> 62 | B63: 4 | C63: U14 | D63: 46292 | E63: 0.4375 | F63: Großhöflein | G63: SPG Seewinkel | H63: Heim
A64: =A63+1 -> 63 | B64: 5 | C64: U14 | D64: 46298 | E64: 0.70833333 | F64: Draßburg | G64: SPG Draßburg/ZSP/Kemeten | H64: Auswärts
A65: =A64+1 -> 64 | B65: 6 | C65: U14 | D65: 46306 | E65: 0.45833333 | F65: Neufeld | G65: SPG Pubach/Breitenbrunn/Winden | H65: Heim
A66: =A65+1 -> 65 | B66: 7 | C66: U14 | D66: 46313 | E66: 0.45833333 | F66: Kemeten | G66: Kemeten | H66: Auswärts
A67: =A66+1 -> 66 | B67: 8 | C67: U14 | D67: 46320 | E67: 0.58333333 | F67: Neufeld | G67: MSV 2020 | H67: Heim
A68: =A67+1 -> 67 | B68: 9 | C68: U14 | D68: 46326 | E68: 0.58333333 | F68: Gols | G68: GMWP | H68: Auswärts
... A104: =A103+1 -> 103 | B104: 2 | C104: U9 | D104: 46278 | E104: 0.45833333 | F104: Neufeld | G104: Steinbrunn | H104: Heim
A105: =A104+1 -> 104 | B105: 3 | C105: U9 | D105: 46283 | G105: Spielfrei
A106: =A105+1 -> 105 | B106: 4 | C106: U9 | D106: 46291 | E106: 0.41666667 | F106: Eisenstadt | G106: Eisenstadt | H106: Auswärts
A107: =A106+1 -> 106 | B107: 5 | C107: U9 | D107: 46298 | E107: 0.39583333 | F107: Neufeld | G107: Hornstein | H107: Heim
A108: =A107+1 -> 107 | B108: 6 | C108: U9 | D108: 46305 | E108: 0.58333333 | F108: Neufeld | G108: Großhöflein | H108: Heim
...

Sheet ICS2
A1: TITEL | B1: DATUM | C1: STARTZEIT | D1: ENDZEIT | E1: ORT | F1: BESCHREIBUNG | G1: TYP | H1: GEGNER | I1: LIGA | J1: STATUS | K1: SPIELART | L1: ART
B2: ='Nach Mannschaften sortiert'!D2 -> 46199 | C2: ='Nach Mannschaften sortiert'!E2 -> 0.66666667 | D2: =IF(I2="KM",C2+"1:45",IF(I2="U23",C2+"1:45",IF(I2="U16",C2+"1:45",IF(I2="U15",C2+"1:30",IF(I2="U14",C2+"1:30",IF(I2="U13",C2+"1:35",IF(I2="U12_1",C2+"1:10",IF(I2="U12_2",C2+"1:10",IF(I2="U11",C2+"1:10",IF(I2="U10",C2+"1:03",IF(I2="U9",C2+"1:03",C2+"3:00"))))))))))) -> 0.72916667 | E2: =UPPER('Nach Mannschaften sortiert'!F2) -> WIMPASSING | G2: ='Nach Mannschaften sortiert'!H2 -> Heim | H2: ='Nach Mannschaften sortiert'!G2 -> SK Rapid Wien | I2: ='Nach Mannschaften sortiert'!C2 -> U15 | J2: aktiv | K2: Freundschaftsspiel | L2: Spiel
B3: ='Nach Mannschaften sortiert'!D3 -> 46199 | C3: ='Nach Mannschaften sortiert'!E3 -> 0.75 | D3: =IF(I3="KM",C3+"1:45",IF(I3="U23",C3+"1:45",IF(I3="U16",C3+"1:45",IF(I3="U15",C3+"1:30",IF(I3="U14",C3+"1:30",IF(I3="U13",C3+"1:35",IF(I3="U12_1",C3+"1:10",IF(I3="U12_2",C3+"1:10",IF(I3="U11",C3+"1:10",IF(I3="U10",C3+"1:03",IF(I3="U9",C3+"1:03",C3+"3:00"))))))))))) -> 0.82291667 | E3: =UPPER('Nach Mannschaften sortiert'!F3) -> WIMPASSING | G3: ='Nach Mannschaften sortiert'!H3 -> Heim | H3: ='Nach Mannschaften sortiert'!G3 -> SK Rapid Wien | I3: ='Nach Mannschaften sortiert'!C3 -> U16 | J3: aktiv | K3: Freundschaftsspiel | L3: Spiel
B4: ='Nach Mannschaften sortiert'!D4 -> 46213 | C4: ='Nach Mannschaften sortiert'!E4 -> 0.79166667 | D4: =IF(I4="KM",C4+"1:45",IF(I4="U23",C4+"1:45",IF(I4="U16",C4+"1:45",IF(I4="U15",C4+"1:30",IF(I4="U14",C4+"1:30",IF(I4="U13",C4+"1:35",IF(I4="U12_1",C4+"1:10",IF(I4="U12_2",C4+"1:10",IF(I4="U11",C4+"1:10",IF(I4="U10",C4+"1:03",IF(I4="U9",C4+"1:03",C4+"3:00"))))))))))) -> 0.86458333 | E4: =UPPER('Nach Mannschaften sortiert'!F4) -> NEUDÖRFL | G4: ='Nach Mannschaften sortiert'!H4 -> Auswärts | H4: ='Nach Mannschaften sortiert'!G4 -> Neudörfl | I4: ='Nach Mannschaften sortiert'!C4 -> KM | J4: aktiv | K4: Freundschaftsspiel | L4: Spiel
B5: ='Nach Mannschaften sortiert'!D5 -> 46217 | C5: ='Nach Mannschaften sortiert'!E5 -> 0.8125 | D5: =IF(I5="KM",C5+"1:45",IF(I5="U23",C5+"1:45",IF(I5="U16",C5+"1:45",IF(I5="U15",C5+"1:30",IF(I5="U14",C5+"1:30",IF(I5="U13",C5+"1:35",IF(I5="U12_1",C5+"1:10",IF(I5="U12_2",C5+"1:10",IF(I5="U11",C5+"1:10",IF(I5="U10",C5+"1:03",IF(I5="U9",C5+"1:03",C5+"3:00"))))))))))) -> 0.88541667 | E5: =UPPER('Nach Mannschaften sortiert'!F5) -> PÖTTSCHING | G5: ='Nach Mannschaften sortiert'!H5 -> Auswärts | H5: ='Nach Mannschaften sortiert'!G5 -> Pöttsching | I5: ='Nach Mannschaften sortiert'!C5 -> KM | J5: aktiv | K5: Freundschaftsspiel | L5: Spiel
B6: ='Nach Mannschaften sortiert'!D6 -> 46220 | C6: ='Nach Mannschaften sortiert'!E6 -> 0.79166667 | D6: =IF(I6="KM",C6+"1:45",IF(I6="U23",C6+"1:45",IF(I6="U16",C6+"1:45",IF(I6="U15",C6+"1:30",IF(I6="U14",C6+"1:30",IF(I6="U13",C6+"1:35",IF(I6="U12_1",C6+"1:10",IF(I6="U12_2",C6+"1:10",IF(I6="U11",C6+"1:10",IF(I6="U10",C6+"1:03",IF(I6="U9",C6+"1:03",C6+"3:00"))))))))))) -> 0.86458333 | E6: =UPPER('Nach Mannschaften sortiert'!F6) -> ROHBACH | G6: ='Nach Mannschaften sortiert'!H6 -> Auswärts | H6: ='Nach Mannschaften sortiert'!G6 -> Rohrbach | I6: ='Nach Mannschaften sortiert'!C6 -> KM | J6: aktiv | K6: Freundschaftsspiel | L6: Spiel
B7: ='Nach Mannschaften sortiert'!D7 -> 46227 | C7: ='Nach Mannschaften sortiert'!E7 -> 0.8125 | D7: =IF(I7="KM",C7+"1:45",IF(I7="U23",C7+"1:45",IF(I7="U16",C7+"1:45",IF(I7="U15",C7+"1:30",IF(I7="U14",C7+"1:30",IF(I7="U13",C7+"1:35",IF(I7="U12_1",C7+"1:10",IF(I7="U12_2",C7+"1:10",IF(I7="U11",C7+"1:10",IF(I7="U10",C7+"1:03",IF(I7="U9",C7+"1:03",C7+"3:00"))))))))))) -> 0.88541667 | E7: =UPPER('Nach Mannschaften sortiert'!F7) -> SOMMEREIN | G7: ='Nach Mannschaften sortiert'!H7 -> Auswärts | H7: ='Nach Mannschaften sortiert'!G7 -> Sommerein | I7: ='Nach Mannschaften sortiert'!C7 -> KM | J7: aktiv | K7: Freundschaftsspiel | L7: Spiel
B8: ='Nach Mannschaften sortiert'!D8 -> 46234 | C8: ='Nach Mannschaften sortiert'!E8 -> 0.70833333 | D8: =IF(I8="KM",C8+"1:45",IF(I8="U23",C8+"1:45",IF(I8="U16",C8+"1:45",IF(I8="U15",C8+"1:30",IF(I8="U14",C8+"1:30",IF(I8="U13",C8+"1:35",IF(I8="U12_1",C8+"1:10",IF(I8="U12_2",C8+"1:10",IF(I8="U11",C8+"1:10",IF(I8="U10",C8+"1:03",IF(I8="U9",C8+"1:03",C8+"3:00"))))))))))) -> 0.78125 | E8: =UPPER('Nach Mannschaften sortiert'!F8) -> WIENER NEUSTADT | G8: ='Nach Mannschaften sortiert'!H8 -> Auswärts | H8: ='Nach Mannschaften sortiert'!G8 -> Admira Wiener Neustadt | I8: ='Nach Mannschaften sortiert'!C8 -> U23 | J8: abgesagt | K8: Freundschaftsspiel | L8: Spiel
B9: ='Nach Mannschaften sortiert'!D9 -> 46235 | C9: ='Nach Mannschaften sortiert'!E9 -> 0.72916667 | D9: =IF(I9="KM",C9+"1:45",IF(I9="U23",C9+"1:45",IF(I9="U16",C9+"1:45",IF(I9="U15",C9+"1:30",IF(I9="U14",C9+"1:30",IF(I9="U13",C9+"1:35",IF(I9="U12_1",C9+"1:10",IF(I9="U12_2",C9+"1:10",IF(I9="U11",C9+"1:10",IF(I9="U10",C9+"1:03",IF(I9="U9",C9+"1:03",C9+"3:00"))))))))))) -> 0.80208333 | E9: =UPPER('Nach Mannschaften sortiert'!F9) -> KITTSEE | F9: bittere 1:0 Niederlage, somit aus dem BFV-Cup ausgeschieden | G9: ='Nach Mannschaften sortiert'!H9 -> Auswärts | H9: ='Nach Mannschaften sortiert'!G9 -> Kittsee | I9: ='Nach Mannschaften sortiert'!C9 -> KM | J9: aktiv | K9: Freundschaftsspiel | L9: Spiel
B10: ='Nach Mannschaften sortiert'!D10 -> 46236 | C10: ='Nach Mannschaften sortiert'!E10 -> 0.4375 | D10: =IF(I10="KM",C10+"1:45",IF(I10="U23",C10+"1:45",IF(I10="U16",C10+"1:45",IF(I10="U15",C10+"1:30",IF(I10="U14",C10+"1:30",IF(I10="U13",C10+"1:35",IF(I10="U12_1",C10+"1:10",IF(I10="U12_2",C10+"1:10",IF(I10="U11",C10+"1:10",IF(I10="U10",C10+"1:03",IF(I10="U9",C10+"1:03",C10+"3:00"))))))))))) -> 0.51041667 | E10: =UPPER('Nach Mannschaften sortiert'!F10) -> NEUFELD | G10: ='Nach Mannschaften sortiert'!H10 -> Heim | H10: ='Nach Mannschaften sortiert'!G10 -> Theresienfeld | I10: ='Nach Mannschaften sortiert'!C10 -> U16 | J10: abgesagt | K10: Freundschaftsspiel | L10: Spiel
B11: ='Nach Mannschaften sortiert'!D11 -> 46241 | C11: ='Nach Mannschaften sortiert'!E11 -> 0.79166667 | D11: =IF(I11="KM",C11+"1:45",IF(I11="U23",C11+"1:45",IF(I11="U16",C11+"1:45",IF(I11="U15",C11+"1:30",IF(I11="U14",C11+"1:30",IF(I11="U13",C11+"1:35",IF(I11="U12_1",C11+"1:10",IF(I11="U12_2",C11+"1:10",IF(I11="U11",C11+"1:10",IF(I11="U10",C11+"1:03",IF(I11="U9",C11+"1:03",C11+"3:00"))))))))))) -> 0.86458333 | E11: =UPPER('Nach Mannschaften sortiert'!F11) -> NEUFELD | G11: ='Nach Mannschaften sortiert'!H11 -> Heim | H11: ='Nach Mannschaften sortiert'!G11 -> Bad Fischau | I11: ='Nach Mannschaften sortiert'!C11 -> KM | J11: aktiv | K11: Freundschaftsspiel | L11: Spiel
B12: ='Nach Mannschaften sortiert'!D12 -> 46243 | C12: ='Nach Mannschaften sortiert'!E12 -> 0.45833333 | D12: =IF(I12="KM",C12+"1:45",IF(I12="U23",C12+"1:45",IF(I12="U16",C12+"1:45",IF(I12="U15",C12+"1:30",IF(I12="U14",C12+"1:30",IF(I12="U13",C12+"1:35",IF(I12="U12_1",C12+"1:10",IF(I12="U12_2",C12+"1:10",IF(I12="U11",C12+"1:10",IF(I12="U10",C12+"1:03",IF(I12="U9",C12+"1:03",C12+"3:00"))))))))))) -> 0.53125 | E12: =UPPER('Nach Mannschaften sortiert'!F12) -> WIENER NEUDORF | G12: ='Nach Mannschaften sortiert'!H12 -> Auswärts | H12: ='Nach Mannschaften sortiert'!G12 -> Wiener Neudorf | I12: ='Nach Mannschaften sortiert'!C12 -> U16 | J12: aktiv | K12: Freundschaftsspiel | L12: Spiel
B13: ='Nach Mannschaften sortiert'!D13 -> 46243 | C13: ='Nach Mannschaften sortiert'!E13 -> 0.625 | D13: =IF(I13="KM",C13+"1:45",IF(I13="U23",C13+"1:45",IF(I13="U16",C13+"1:45",IF(I13="U15",C13+"1:30",IF(I13="U14",C13+"1:30",IF(I13="U13",C13+"1:35",IF(I13="U12_1",C13+"1:10",IF(I13="U12_2",C13+"1:10",IF(I13="U11",C13+"1:10",IF(I13="U10",C13+"1:03",IF(I13="U9",C13+"1:03",C13+"3:00"))))))))))) -> 0.6875 | E13: =UPPER('Nach Mannschaften sortiert'!F13) -> GROßHÖFLEIN | G13: ='Nach Mannschaften sortiert'!H13 -> Heim | H13: ='Nach Mannschaften sortiert'!G13 -> Vienna U13 | I13: ='Nach Mannschaften sortiert'!C13 -> U14 | J13: aktiv | K13: Freundschaftsspiel | L13: Spiel
B14: ='Nach Mannschaften sortiert'!D14 -> 46245 | C14: ='Nach Mannschaften sortiert'!E14 -> 0.79166667 | D14: =IF(I14="KM",C14+"1:45",IF(I14="U23",C14+"1:45",IF(I14="U16",C14+"1:45",IF(I14="U15",C14+"1:30",IF(I14="U14",C14+"1:30",IF(I14="U13",C14+"1:35",IF(I14="U12_1",C14+"1:10",IF(I14="U12_2",C14+"1:10",IF(I14="U11",C14+"1:10",IF(I14="U10",C14+"1:03",IF(I14="U9",C14+"1:03",C14+"3:00"))))))))))) -> 0.86458333 | E14: =UPPER('Nach Mannschaften sortiert'!F14) -> WR. NEUSTADT | G14: ='Nach Mannschaften sortiert'!H14 -> Auswärts | H14: ='Nach Mannschaften sortiert'!G14 -> Admira Wiener Neustadt | I14: ='Nach Mannschaften sortiert'!C14 -> U23 | J14: aktiv | K14: Freundschaftsspiel | L14: Spiel
B15: ='Nach Mannschaften sortiert'!D15 -> 46247 | C15: ='Nach Mannschaften sortiert'!E15 -> 0.79166667 | D15: =IF(I15="KM",C15+"1:45",IF(I15="U23",C15+"1:45",IF(I15="U16",C15+"1:45",IF(I15="U15",C15+"1:30",IF(I15="U14",C15+"1:30",IF(I15="U13",C15+"1:35",IF(I15="U12_1",C15+"1:10",IF(I15="U12_2",C15+"1:10",IF(I15="U11",C15+"1:10",IF(I15="U10",C15+"1:03",IF(I15="U9",C15+"1:03",C15+"3:00"))))))))))) -> 0.85416667 | E15: =UPPER('Nach Mannschaften sortiert'!F15) -> OGGAU | G15: ='Nach Mannschaften sortiert'!H15 -> Auswärts | H15: ='Nach Mannschaften sortiert'!G15 -> Oggau | I15: ='Nach Mannschaften sortiert'!C15 -> U14 | J15: aktiv | K15: Freundschaftsspiel | L15: Spiel
B16: ='Nach Mannschaften sortiert'!D16 -> 46255 | C16: ='Nach Mannschaften sortiert'!E16 -> 0.75 | D16: =IF(I16="KM",C16+"1:45",IF(I16="U23",C16+"1:45",IF(I16="U16",C16+"1:45",IF(I16="U15",C16+"1:30",IF(I16="U14",C16+"1:30",IF(I16="U13",C16+"1:35",IF(I16="U12_1",C16+"1:10",IF(I16="U12_2",C16+"1:10",IF(I16="U11",C16+"1:10",IF(I16="U10",C16+"1:03",IF(I16="U9",C16+"1:03",C16+"3:00"))))))))))) -> 0.8125 | E16: =UPPER('Nach Mannschaften sortiert'!F16) -> GROßHÖFLEIN | G16: ='Nach Mannschaften sortiert'!H16 -> Heim | H16: ='Nach Mannschaften sortiert'!G16 -> Bad Erlach | I16: ='Nach Mannschaften sortiert'!C16 -> U14 | J16: aktiv | K16: Freundschaftsspiel | L16: Spiel
B17: ='Nach Mannschaften sortiert'!D17 -> 46256 | C17: ='Nach Mannschaften sortiert'!E17 -> 0.70833333 | D17: =IF(I17="KM",C17+"1:45",IF(I17="U23",C17+"1:45",IF(I17="U16",C17+"1:45",IF(I17="U15",C17+"1:30",IF(I17="U14",C17+"1:30",IF(I17="U13",C17+"1:35",IF(I17="U12_1",C17+"1:10",IF(I17="U12_2",C17+"1:10",IF(I17="U11",C17+"1:10",IF(I17="U10",C17+"1:03",IF(I17="U9",C17+"1:03",C17+"3:00"))))))))))) -> 0.78125 | E17: =UPPER('Nach Mannschaften sortiert'!F17) -> LAXENBURG | G17: ='Nach Mannschaften sortiert'!H17 -> Auswärts | H17: ='Nach Mannschaften sortiert'!G17 -> Laxenburg | I17: ='Nach Mannschaften sortiert'!C17 -> U16 | J17: abgesagt | K17: Freundschaftsspiel | L17: Spiel
B18: ='Nach Mannschaften sortiert'!D18 -> 46260 | C18: ='Nach Mannschaften sortiert'!E18 -> 0.41666667 | D18: =IF(I18="KM",C18+"1:45",IF(I18="U23",C18+"1:45",IF(I18="U16",C18+"1:45",IF(I18="U15",C18+"1:30",IF(I18="U14",C18+"1:30",IF(I18="U13",C18+"1:35",IF(I18="U12_1",C18+"1:10",IF(I18="U12_2",C18+"1:10",IF(I18="U11",C18+"1:10",IF(I18="U10",C18+"1:03",IF(I18="U9",C18+"1:03",C18+"3:00"))))))))))) -> 0.48958333 | E18: =UPPER('Nach Mannschaften sortiert'!F18) -> NEUFELD | G18: ='Nach Mannschaften sortiert'!H18 -> Heim | H18: ='Nach Mannschaften sortiert'!G18 -> Traiskirchen | I18: ='Nach Mannschaften sortiert'!C18 -> U16 | J18: abgesagt | K18: Freundschaftsspiel | L18: Spiel
B19: ='Nach Mannschaften sortiert'!D19 -> 46260 | C19: ='Nach Mannschaften sortiert'!E19 -> 0.79166667 | D19: =IF(I19="KM",C19+"1:45",IF(I19="U23",C19+"1:45",IF(I19="U16",C19+"1:45",IF(I19="U15",C19+"1:30",IF(I19="U14",C19+"1:30",IF(I19="U13",C19+"1:35",IF(I19="U12_1",C19+"1:10",IF(I19="U12_2",C19+"1:10",IF(I19="U11",C19+"1:10",IF(I19="U10",C19+"1:03",IF(I19="U9",C19+"1:03",C19+"3:00"))))))))))) -> 0.85416667 | E19: =UPPER('Nach Mannschaften sortiert'!F19) -> GROßHÖFLEIN | G19: ='Nach Mannschaften sortiert'!H19 -> Heim | H19: ='Nach Mannschaften sortiert'!G19 -> SPG Leitha/Stotzing | I19: ='Nach Mannschaften sortiert'!C19 -> U14 | J19: aktiv | K19: Freundschaftsspiel | L19: Spiel
B20: ='Nach Mannschaften sortiert'!D20 -> 46263 | C20: ='Nach Mannschaften sortiert'!E20 -> 0.4375 | D20: =IF(I20="KM",C20+"1:45",IF(I20="U23",C20+"1:45",IF(I20="U16",C20+"1:45",IF(I20="U15",C20+"1:30",IF(I20="U14",C20+"1:30",IF(I20="U13",C20+"1:35",IF(I20="U12_1",C20+"1:10",IF(I20="U12_2",C20+"1:10",IF(I20="U11",C20+"1:10",IF(I20="U10",C20+"1:03",IF(I20="U9",C20+"1:03",C20+"3:00"))))))))))) -> 0.5 | E20: =UPPER('Nach Mannschaften sortiert'!F20) -> GROßHÖFLEIN | G20: ='Nach Mannschaften sortiert'!H20 -> Heim | H20: ='Nach Mannschaften sortiert'!G20 -> Oggau | I20: ='Nach Mannschaften sortiert'!C20 -> U14 | J20: aktiv | K20: Freundschaftsspiel | L20: Spiel
B21: ='Nach Mannschaften sortiert'!D21 -> 46264 | C21: ='Nach Mannschaften sortiert'!E21 -> 0.4375 | D21: =IF(I21="KM",C21+"1:45",IF(I21="U23",C21+"1:45",IF(I21="U16",C21+"1:45",IF(I21="U15",C21+"1:30",IF(I21="U14",C21+"1:30",IF(I21="U13",C21+"1:35",IF(I21="U12_1",C21+"1:10",IF(I21="U12_2",C21+"1:10",IF(I21="U11",C21+"1:10",IF(I21="U10",C21+"1:03",IF(I21="U9",C21+"1:03",C21+"3:00"))))))))))) -> 0.51041667 | E21: =UPPER('Nach Mannschaften sortiert'!F21) -> THERESIENFELD | G21: ='Nach Mannschaften sortiert'!H21 -> Auswärts | H21: ='Nach Mannschaften sortiert'!G21 -> SPG Theresienfeld | I21: ='Nach Mannschaften sortiert'!C21 -> U16 | J21: aktiv | K21: Freundschaftsspiel | L21: Spiel
B22: ='Nach Mannschaften sortiert'!D22 -> 46445 | C22: ='Nach Mannschaften sortiert'!E22 -> 0.5 | D22: =IF(I22="KM",C22+"1:45",IF(I22="U23",C22+"1:45",IF(I22="U16",C22+"1:45",IF(I22="U15",C22+"1:30",IF(I22="U14",C22+"1:30",IF(I22="U13",C22+"1:35",IF(I22="U12_1",C22+"1:10",IF(I22="U12_2",C22+"1:10",IF(I22="U11",C22+"1:10",IF(I22="U10",C22+"1:03",IF(I22="U9",C22+"1:03",C22+"3:00"))))))))))) -> 0.57291667 | E22: =UPPER('Nach Mannschaften sortiert'!F22) -> BAD ERLACH | G22: ='Nach Mannschaften sortiert'!H22 -> Auswärts | H22: ='Nach Mannschaften sortiert'!G22 -> Bad Erlach | I22: ='Nach Mannschaften sortiert'!C22 -> KM | J22: aktiv | K22: Freundschaftsspiel | L22: Spiel
B23: ='Nach Mannschaften sortiert'!D23 -> 46250 | C23: ='Nach Mannschaften sortiert'!E23 -> 0.72916667 | D23: =IF(I23="KM",C23+"1:45",IF(I23="U23",C23+"1:45",IF(I23="U16",C23+"1:45",IF(I23="U15",C23+"1:30",IF(I23="U14",C23+"1:30",IF(I23="U13",C23+"1:35",IF(I23="U12_1",C23+"1:10",IF(I23="U12_2",C23+"1:10",IF(I23="U11",C23+"1:10",IF(I23="U10",C23+"1:03",IF(I23="U9",C23+"1:03",C23+"3:00"))))))))))) -> 0.80208333 | E23: =UPPER('Nach Mannschaften sortiert'!F23) -> KITTSEE | F23: nach einer 2:0 Führung noch 4:2 verloren | G23: ='Nach Mannschaften sortiert'!H23 -> Auswärts | H23: ='Nach Mannschaften sortiert'!G23 -> Kittsee | I23: ='Nach Mannschaften sortiert'!C23 -> KM | J23: aktiv | K23: Liga | L23: Spiel
B24: ='Nach Mannschaften sortiert'!D24 -> 46255 | C24: ='Nach Mannschaften sortiert'!E24 -> 0.83333333 | D24: =IF(I24="KM",C24+"1:45",IF(I24="U23",C24+"1:45",IF(I24="U16",C24+"1:45",IF(I24="U15",C24+"1:30",IF(I24="U14",C24+"1:30",IF(I24="U13",C24+"1:35",IF(I24="U12_1",C24+"1:10",IF(I24="U12_2",C24+"1:10",IF(I24="U11",C24+"1:10",IF(I24="U10",C24+"1:03",IF(I24="U9",C24+"1:03",C24+"3:00"))))))))))) -> 0.90625 | E24: =UPPER('Nach Mannschaften sortiert'!F24) -> DEUTSCH JAHRNDORF | F24: 4:0 für Deutsch-Jahndorf | G24: ='Nach Mannschaften sortiert'!H24 -> Auswärts | H24: ='Nach Mannschaften sortiert'!G24 -> Deutsch Jahrndorf | I24: ='Nach Mannschaften sortiert'!C24 -> KM | J24: aktiv | K24: Liga | L24: Spiel
B25: ='Nach Mannschaften sortiert'!D25 -> 46263 | C25: ='Nach Mannschaften sortiert'!E25 -> 0.75 | D25: =IF(I25="KM",C25+"1:45",IF(I25="U23",C25+"1:45",IF(I25="U16",C25+"1:45",IF(I25="U15",C25+"1:30",IF(I25="U14",C25+"1:30",IF(I25="U13",C25+"1:35",IF(I25="U12_1",C25+"1:10",IF(I25="U12_2",C25+"1:10",IF(I25="U11",C25+"1:10",IF(I25="U10",C25+"1:03",IF(I25="U9",C25+"1:03",C25+"3:00"))))))))))) -> 0.82291667 | E25: =UPPER('Nach Mannschaften sortiert'!F25) -> NEUFELD | F25: 2:2 | G25: ='Nach Mannschaften sortiert'!H25 -> Heim | H25: ='Nach Mannschaften sortiert'!G25 -> Tadten | I25: ='Nach Mannschaften sortiert'!C25 -> KM | J25: aktiv | K25: Liga | L25: Spiel
B26: ='Nach Mannschaften sortiert'!D26 -> 46270 | C26: ='Nach Mannschaften sortiert'!E26 -> 0.6875 | D26: =IF(I26="KM",C26+"1:45",IF(I26="U23",C26+"1:45",IF(I26="U16",C26+"1:45",IF(I26="U15",C26+"1:30",IF(I26="U14",C26+"1:30",IF(I26="U13",C26+"1:35",IF(I26="U12_1",C26+"1:10",IF(I26="U12_2",C26+"1:10",IF(I26="U11",C26+"1:10",IF(I26="U10",C26+"1:03",IF(I26="U9",C26+"1:03",C26+"3:00"))))))))))) -> 0.76041667 | E26: =UPPER('Nach Mannschaften sortiert'!F26) -> MÖNCHHOF | F26: 5:1 für Mönchhof | G26: ='Nach Mannschaften sortiert'!H26 -> Auswärts | H26: ='Nach Mannschaften sortiert'!G26 -> Mönchhof | I26: ='Nach Mannschaften sortiert'!C26 -> KM | J26: aktiv | K26: Liga | L26: Spiel
B27: ='Nach Mannschaften sortiert'!D27 -> 46276 | C27: ='Nach Mannschaften sortiert'!E27 -> 0.8125 | D27: =IF(I27="KM",C27+"1:45",IF(I27="U23",C27+"1:45",IF(I27="U16",C27+"1:45",IF(I27="U15",C27+"1:30",IF(I27="U14",C27+"1:30",IF(I27="U13",C27+"1:35",IF(I27="U12_1",C27+"1:10",IF(I27="U12_2",C27+"1:10",IF(I27="U11",C27+"1:10",IF(I27="U10",C27+"1:03",IF(I27="U9",C27+"1:03",C27+"3:00"))))))))))) -> 0.88541667 | E27: =UPPER('Nach Mannschaften sortiert'!F27) -> NEUFELD | F27: 4:0 für Neufeld | G27: ='Nach Mannschaften sortiert'!H27 -> Heim | H27: ='Nach Mannschaften sortiert'!G27 -> Winden | I27: ='Nach Mannschaften sortiert'!C27 -> KM | J27: aktiv | K27: Liga | L27: Spiel
B28: ='Nach Mannschaften sortiert'!D28 -> 46284 | C28: ='Nach Mannschaften sortiert'!E28 -> 0.66666667 | D28: =IF(I28="KM",C28+"1:45",IF(I28="U23",C28+"1:45",IF(I28="U16",C28+"1:45",IF(I28="U15",C28+"1:30",IF(I28="U14",C28+"1:30",IF(I28="U13",C28+"1:35",IF(I28="U12_1",C28+"1:10",IF(I28="U12_2",C28+"1:10",IF(I28="U11",C28+"1:10",IF(I28="U10",C28+"1:03",IF(I28="U9",C28+"1:03",C28+"3:00"))))))))))) -> 0.73958333 | E28: =UPPER('Nach Mannschaften sortiert'!F28) -> GATTENDORF | F28: 2:0 für Neufeld | G28: ='Nach Mannschaften sortiert'!H28 -> Auswärts | H28: ='Nach Mannschaften sortiert'!G28 -> Gattendorf | I28: ='Nach Mannschaften sortiert'!C28 -> KM | J28: aktiv | K28: Liga | L28: Spiel
B29: ='Nach Mannschaften sortiert'!D29 -> 46291 | C29: ='Nach Mannschaften sortiert'!E29 -> 0.75 | D29: =IF(I29="KM",C29+"1:45",IF(I29="U23",C29+"1:45",IF(I29="U16",C29+"1:45",IF(I29="U15",C29+"1:30",IF(I29="U14",C29+"1:30",IF(I29="U13",C29+"1:35",IF(I29="U12_1",C29+"1:10",IF(I29="U12_2",C29+"1:10",IF(I29="U11",C29+"1:10",IF(I29="U10",C29+"1:03",IF(I29="U9",C29+"1:03",C29+"3:00"))))))))))) -> 0.82291667 | E29: =UPPER('Nach Mannschaften sortiert'!F29) -> NEUFELD | F29: 1:1 | G29: ='Nach Mannschaften sortiert'!H29 -> Heim | H29: ='Nach Mannschaften sortiert'!G29 -> Wallern | I29: ='Nach Mannschaften sortiert'!C29 -> KM | J29: aktiv | K29: Liga | L29: Spiel
B30: ='Nach Mannschaften sortiert'!D30 -> 46297 | C30: ='Nach Mannschaften sortiert'!E30 -> 0.8125 | D30: =IF(I30="KM",C30+"1:45",IF(I30="U23",C30+"1:45",IF(I30="U16",C30+"1:45",IF(I30="U15",C30+"1:30",IF(I30="U14",C30+"1:30",IF(I30="U13",C30+"1:35",IF(I30="U12_1",C30+"1:10",IF(I30="U12_2",C30+"1:10",IF(I30="U11",C30+"1:10",IF(I30="U10",C30+"1:03",IF(I30="U9",C30+"1:03",C30+"3:00"))))))))))) -> 0.88541667 | E30: =UPPER('Nach Mannschaften sortiert'!F30) -> SIEGENDORF | F30: 2:0 für Siegendorf | G30: ='Nach Mannschaften sortiert'!H30 -> Auswärts | H30: ='Nach Mannschaften sortiert'!G30 -> Siegendorf | I30: ='Nach Mannschaften sortiert'!C30 -> KM | J30: aktiv | K30: Liga | L30: Spiel
B31: ='Nach Mannschaften sortiert'!D31 -> 46304 | C31: ='Nach Mannschaften sortiert'!E31 -> 0.8125 | D31: =IF(I31="KM",C31+"1:45",IF(I31="U23",C31+"1:45",IF(I31="U16",C31+"1:45",IF(I31="U15",C31+"1:30",IF(I31="U14",C31+"1:30",IF(I31="U13",C31+"1:35",IF(I31="U12_1",C31+"1:10",IF(I31="U12_2",C31+"1:10",IF(I31="U11",C31+"1:10",IF(I31="U10",C31+"1:03",IF(I31="U9",C31+"1:03",C31+"3:00"))))))))))) -> 0.88541667 | E31: =UPPER('Nach Mannschaften sortiert'!F31) -> NEUFELD | F31: 1:0 für Neufeld | G31: ='Nach Mannschaften sortiert'!H31 -> Heim | H31: ='Nach Mannschaften sortiert'!G31 -> Wimpassing | I31: ='Nach Mannschaften sortiert'!C31 -> KM | J31: aktiv | K31: Liga | L31: Spiel
B32: ='Nach Mannschaften sortiert'!D32 -> 46311 | C32: ='Nach Mannschaften sortiert'!E32 -> 0.8125 | D32: =IF(I32="KM",C32+"1:45",IF(I32="U23",C32+"1:45",IF(I32="U16",C32+"1:45",IF(I32="U15",C32+"1:30",IF(I32="U14",C32+"1:30",IF(I32="U13",C32+"1:35",IF(I32="U12_1",C32+"1:10",IF(I32="U12_2",C32+"1:10",IF(I32="U11",C32+"1:10",IF(I32="U10",C32+"1:03",IF(I32="U9",C32+"1:03",C32+"3:00"))))))))))) -> 0.88541667 | E32: =UPPER('Nach Mannschaften sortiert'!F32) -> HORNSTEIN | F32: 5:0 für Hornstein | G32: ='Nach Mannschaften sortiert'!H32 -> Auswärts | H32: ='Nach Mannschaften sortiert'!G32 -> Hornstein | I32: ='Nach Mannschaften sortiert'!C32 -> KM | J32: aktiv | K32: Liga | L32: Spiel
B33: ='Nach Mannschaften sortiert'!D33 -> 46318 | C33: ='Nach Mannschaften sortiert'!E33 -> 0.8125 | D33: =IF(I33="KM",C33+"1:45",IF(I33="U23",C33+"1:45",IF(I33="U16",C33+"1:45",IF(I33="U15",C33+"1:30",IF(I33="U14",C33+"1:30",IF(I33="U13",C33+"1:35",IF(I33="U12_1",C33+"1:10",IF(I33="U12_2",C33+"1:10",IF(I33="U11",C33+"1:10",IF(I33="U10",C33+"1:03",IF(I33="U9",C33+"1:03",C33+"3:00"))))))))))) -> 0.88541667 | E33: =UPPER('Nach Mannschaften sortiert'!F33) -> NEUFELD | G33: ='Nach Mannschaften sortiert'!H33 -> Heim | H33: ='Nach Mannschaften sortiert'!G33 -> Gols | I33: ='Nach Mannschaften sortiert'!C33 -> KM | J33: aktiv | K33: Liga | L33: Spiel
B34: ='Nach Mannschaften sortiert'!D34 -> 46326 | C34: ='Nach Mannschaften sortiert'!E34 -> 0.75 | D34: =IF(I34="KM",C34+"1:45",IF(I34="U23",C34+"1:45",IF(I34="U16",C34+"1:45",IF(I34="U15",C34+"1:30",IF(I34="U14",C34+"1:30",IF(I34="U13",C34+"1:35",IF(I34="U12_1",C34+"1:10",IF(I34="U12_2",C34+"1:10",IF(I34="U11",C34+"1:10",IF(I34="U10",C34+"1:03",IF(I34="U9",C34+"1:03",C34+"3:00"))))))))))) -> 0.82291667 | E34: =UPPER('Nach Mannschaften sortiert'!F34) -> ILLMITZ | G34: ='Nach Mannschaften sortiert'!H34 -> Auswärts | H34: ='Nach Mannschaften sortiert'!G34 -> Illmitz | I34: ='Nach Mannschaften sortiert'!C34 -> KM | J34: aktiv | K34: Liga | L34: Spiel
B35: ='Nach Mannschaften sortiert'!D35 -> 46333 | C35: ='Nach Mannschaften sortiert'!E35 -> 0.6875 | D35: =IF(I35="KM",C35+"1:45",IF(I35="U23",C35+"1:45",IF(I35="U16",C35+"1:45",IF(I35="U15",C35+"1:30",IF(I35="U14",C35+"1:30",IF(I35="U13",C35+"1:35",IF(I35="U12_1",C35+"1:10",IF(I35="U12_2",C35+"1:10",IF(I35="U11",C35+"1:10",IF(I35="U10",C35+"1:03",IF(I35="U9",C35+"1:03",C35+"3:00"))))))))))) -> 0.76041667 | E35: =UPPER('Nach Mannschaften sortiert'!F35) -> NEUFELD | G35: ='Nach Mannschaften sortiert'!H35 -> Heim | H35: ='Nach Mannschaften sortiert'!G35 -> Andau | I35: ='Nach Mannschaften sortiert'!C35 -> KM | J35: aktiv | K35: Liga | L35: Spiel
B36: ='Nach Mannschaften sortiert'!D36 -> 46250 | C36: ='Nach Mannschaften sortiert'!E36 -> 0.64583333 | D36: =IF(I36="KM",C36+"1:45",IF(I36="U23",C36+"1:45",IF(I36="U16",C36+"1:45",IF(I36="U15",C36+"1:30",IF(I36="U14",C36+"1:30",IF(I36="U13",C36+"1:35",IF(I36="U12_1",C36+"1:10",IF(I36="U12_2",C36+"1:10",IF(I36="U11",C36+"1:10",IF(I36="U10",C36+"1:03",IF(I36="U9",C36+"1:03",C36+"3:00"))))))))))) -> 0.71875 | E36: =UPPER('Nach Mannschaften sortiert'!F36) -> KITTSEE | F36: 9:2 für Kittsee | G36: ='Nach Mannschaften sortiert'!H36 -> Auswärts | H36: ='Nach Mannschaften sortiert'!G36 -> Kittsee | I36: ='Nach Mannschaften sortiert'!C36 -> U23 | J36: aktiv | K36: Liga | L36: Spiel
B37: ='Nach Mannschaften sortiert'!D37 -> 46255 | C37: ='Nach Mannschaften sortiert'!E37 -> 0.75 | D37: =IF(I37="KM",C37+"1:45",IF(I37="U23",C37+"1:45",IF(I37="U16",C37+"1:45",IF(I37="U15",C37+"1:30",IF(I37="U14",C37+"1:30",IF(I37="U13",C37+"1:35",IF(I37="U12_1",C37+"1:10",IF(I37="U12_2",C37+"1:10",IF(I37="U11",C37+"1:10",IF(I37="U10",C37+"1:03",IF(I37="U9",C37+"1:03",C37+"3:00"))))))))))) -> 0.82291667 | E37: =UPPER('Nach Mannschaften sortiert'!F37) -> DEUTSCH JAHRNDORF | F37: 3:0 für Deutsch-Jahndof | G37: ='Nach Mannschaften sortiert'!H37 -> Auswärts | H37: ='Nach Mannschaften sortiert'!G37 -> Deutsch Jahrndorf | I37: ='Nach Mannschaften sortiert'!C37 -> U23 | J37: aktiv | K37: Liga | L37: Spiel
B38: ='Nach Mannschaften sortiert'!D38 -> 46263 | C38: ='Nach Mannschaften sortiert'!E38 -> 0.66666667 | D38: =IF(I38="KM",C38+"1:45",IF(I38="U23",C38+"1:45",IF(I38="U16",C38+"1:45",IF(I38="U15",C38+"1:30",IF(I38="U14",C38+"1:30",IF(I38="U13",C38+"1:35",IF(I38="U12_1",C38+"1:10",IF(I38="U12_2",C38+"1:10",IF(I38="U11",C38+"1:10",IF(I38="U10",C38+"1:03",IF(I38="U9",C38+"1:03",C38+"3:00"))))))))))) -> 0.73958333 | E38: =UPPER('Nach Mannschaften sortiert'!F38) -> NEUFELD | F38: 2:4 für Tadten | G38: ='Nach Mannschaften sortiert'!H38 -> Heim | H38: ='Nach Mannschaften sortiert'!G38 -> Tadten | I38: ='Nach Mannschaften sortiert'!C38 -> U23 | J38: aktiv | K38: Liga | L38: Spiel
B39: ='Nach Mannschaften sortiert'!D39 -> 46270 | C39: ='Nach Mannschaften sortiert'!E39 -> 0.60416667 | D39: =IF(I39="KM",C39+"1:45",IF(I39="U23",C39+"1:45",IF(I39="U16",C39+"1:45",IF(I39="U15",C39+"1:30",IF(I39="U14",C39+"1:30",IF(I39="U13",C39+"1:35",IF(I39="U12_1",C39+"1:10",IF(I39="U12_2",C39+"1:10",IF(I39="U11",C39+"1:10",IF(I39="U10",C39+"1:03",IF(I39="U9",C39+"1:03",C39+"3:00"))))))))))) -> 0.67708333 | E39: =UPPER('Nach Mannschaften sortiert'!F39) -> MÖNCHHOF | F39: 2:0 für Mönchhof | G39: ='Nach Mannschaften sortiert'!H39 -> Auswärts | H39: ='Nach Mannschaften sortiert'!G39 -> Mönchhof | I39: ='Nach Mannschaften sortiert'!C39 -> U23 | J39: aktiv | K39: Liga | L39: Spiel
B40: ='Nach Mannschaften sortiert'!D40 -> 46276 | C40: ='Nach Mannschaften sortiert'!E40 -> 0.72916667 | D40: =IF(I40="KM",C40+"1:45",IF(I40="U23",C40+"1:45",IF(I40="U16",C40+"1:45",IF(I40="U15",C40+"1:30",IF(I40="U14",C40+"1:30",IF(I40="U13",C40+"1:35",IF(I40="U12_1",C40+"1:10",IF(I40="U12_2",C40+"1:10",IF(I40="U11",C40+"1:10",IF(I40="U10",C40+"1:03",IF(I40="U9",C40+"1:03",C40+"3:00"))))))))))) -> 0.80208333 | E40: =UPPER('Nach Mannschaften sortiert'!F40) -> NEUFELD | F40: 5:0 für Neufeld | G40: ='Nach Mannschaften sortiert'!H40 -> Heim | H40: ='Nach Mannschaften sortiert'!G40 -> Winden | I40: ='Nach Mannschaften sortiert'!C40 -> U23 | J40: aktiv | K40: Liga | L40: Spiel
...

Sheet Stefans Liste 2026
A1: Mannschaft | B1: fixierter Termin | C1: Uhrzeit | D1: Ort | E1: Gegner | F1: Spielfeld | G1: Spielfeldgröße | H1: Tore | I1: Ball | J1: Trainer/Ansprechpartner | K1: Tel
A2: ='ICS2'!I117 -> U8 | B2: ='ICS2'!B117 -> 46278 | C2: ='ICS2'!C117 -> 0.41666667 | D2: ='ICS2'!E117 -> STEINBRUNN | E2: ='ICS2'!H117 -> Turnier | F2: =A2 -> U8 | G2: =IF(F2="KM","Großfeld",IF(F2="U23","Großfeld",IF(F2="U16","Großfeld",IF(F2="U15","Großfeld",IF(F2="U14","Großfeld",IF(F2="U12_1","55*40",IF(F2="U12_2","55x40",IF(F2="U11","55x40",IF(F2="U10","40x25",IF(F2="U9","40x25",IF(F2="U8","29x22",IF(F2="U7","25x20","16x15")))))))))))) -> 29x22 | H2: =IF(F2="KM","7,32x2,44",IF(F2="U23","7,32x2,44",IF(F2="U16","7,32x2,44",IF(F2="U15","7,32x2,44",IF(F2="U14","7,32x2,44",IF(F2="U13","5x2",IF(F2="U12_1","7,32x2,44",IF(F2="U12_2","7,32x2,44",IF(F2="U11","5x2",IF(F2="U10","5x2 ",IF(F2="U9","5x2","4 Minitore"))))))))))) -> 4 Minitore | I2: =IF(F2="KM","5",IF(F2="U23",5,IF(F2="U16","5",IF(F2="U15","5",IF(F2="U14","4",IF(F2="U13","4",IF(F2="U12_1","4",IF(F2="U12_2","4",IF(F2="U11","4",IF(F2="U10","4",IF(F2="U9","4","3"))))))))))) -> 3 | J2: =IF(F2="KM","Pleninger Stefan & Matthias Wachter",IF(F2="U23","Egzon Gentiani & Dinges Stefan",IF(F2="U16","Serdar Ekinci & Gernot Sevelda & Hubi Oberhofer",IF(F2="U15","",IF(F2="U14","Christian Neckamm & Thomas Pöschl",IF(F2="U13","",IF(F2="U12_1","Tobias Berger & Mario Magler",IF(F2="U12_2","Tobias Berger & Mario Magler",IF(F2="U11","Christian Wirth",IF(F2="U10","Thomas Brandl",IF(F2="U9","Tobias Berger & Sebastian Putric",IF(F2="U8","Ömer Türkes & Taha Mahsumi",IF(F2="U7","Alexander Zax & Jürgen Joszt",IF(F2="FKG","Ronny Archam & Florian Rac",IF(A2="Camp","Berger Dieter",IF(A2="Turnier","Berger Dieter","FEHLER")))))))))))))))) -> Ömer Türkes & Taha Mahsumi | K2: =IF(F2="KM","+43 664 415 99 09 & +43 699 119 70 312",IF(F2="U23","+43 670 18 59 080 & +43 664 451 22 16",IF(F2="U16","+43 690 104 20 129 & +43 676 401 09 13 & +43 699 181 68 504",IF(F2="U15","",IF(F2="U14","+43 699 192 49 527 & +43 677 613 55 114",IF(F2="U13","",IF(F2="U12_1","+43 66 199 13 52 & +43 664 762 09 93",IF(F2="U12_2","+43 66 199 13 52 & +43 664 762 09 93",IF(F2="U11","+43 660 423 93 83",IF(F2="U10","+43 676 377 16 30",IF(F2="U9","+43 66 199 13 52 & +43 660 914 92 36",IF(F2="U8","+43 676 661 62 26 & +43 681 208 11 599",IF(F2="U7","+43 664 458 88 84 & +43 660 549 82 40",IF(F2="FKG","+43 699 111 93 828 & +43 660 600 25 06",IF(A2="Camp","+43 660 77 39 500",IF(A2="Turnier","+43 660 77 39 500","FEHLER")))))))))))))))) -> +43 676 661 62 26 & +43 681 208 11 599
A3: ='ICS2'!I2 -> U15 | B3: ='ICS2'!B2 -> 46199 | C3: ='ICS2'!C2 -> 0.66666667 | D3: ='ICS2'!E2 -> WIMPASSING | E3: ='ICS2'!H2 -> SK Rapid Wien | F3: =A3 -> U15 | G3: =IF(F3="KM","Großfeld",IF(F3="U23","Großfeld",IF(F3="U16","Großfeld",IF(F3="U15","Großfeld",IF(F3="U14","Großfeld",IF(F3="U12_1","55*40",IF(F3="U12_2","55x40",IF(F3="U11","55x40",IF(F3="U10","40x25",IF(F3="U9","40x25",IF(F3="U8","29x22",IF(F3="U7","25x20","16x15")))))))))))) -> Großfeld | H3: =IF(F3="KM","7,32x2,44",IF(F3="U23","7,32x2,44",IF(F3="U16","7,32x2,44",IF(F3="U15","7,32x2,44",IF(F3="U14","7,32x2,44",IF(F3="U13","5x2",IF(F3="U12_1","7,32x2,44",IF(F3="U12_2","7,32x2,44",IF(F3="U11","5x2",IF(F3="U10","5x2 ",IF(F3="U9","5x2","4 Minitore"))))))))))) -> 7,32x2,44 | I3: =IF(F3="KM","5",IF(F3="U23",5,IF(F3="U16","5",IF(F3="U15","5",IF(F3="U14","4",IF(F3="U13","4",IF(F3="U12_1","4",IF(F3="U12_2","4",IF(F3="U11","4",IF(F3="U10","4",IF(F3="U9","4","3"))))))))))) -> 5 | J3: =IF(F3="KM","Pleninger Stefan & Matthias Wachter",IF(F3="U23","Egzon Gentiani & Dinges Stefan",IF(F3="U16","Serdar Ekinci & Gernot Sevelda & Hubi Oberhofer",IF(F3="U15","",IF(F3="U14","Christian Neckamm & Thomas Pöschl",IF(F3="U13","",IF(F3="U12_1","Tobias Berger & Mario Magler",IF(F3="U12_2","Tobias Berger & Mario Magler",IF(F3="U11","Christian Wirth",IF(F3="U10","Thomas Brandl",IF(F3="U9","Tobias Berger & Sebastian Putric",IF(F3="U8","Ömer Türkes & Taha Mahsumi",IF(F3="U7","Alexander Zax & Jürgen Joszt",IF(F3="FKG","Ronny Archam & Florian Rac",IF(A3="Camp","Berger Dieter",IF(A3="Turnier","Berger Dieter","FEHLER")))))))))))))))) | K3: =IF(F3="KM","+43 664 415 99 09 & +43 699 119 70 312",IF(F3="U23","+43 670 18 59 080 & +43 664 451 22 16",IF(F3="U16","+43 690 104 20 129 & +43 676 401 09 13 & +43 699 181 68 504",IF(F3="U15","",IF(F3="U14","+43 699 192 49 527 & +43 677 613 55 114",IF(F3="U13","",IF(F3="U12_1","+43 66 199 13 52 & +43 664 762 09 93",IF(F3="U12_2","+43 66 199 13 52 & +43 664 762 09 93",IF(F3="U11","+43 660 423 93 83",IF(F3="U10","+43 676 377 16 30",IF(F3="U9","+43 66 199 13 52 & +43 660 914 92 36",IF(F3="U8","+43 676 661 62 26 & +43 681 208 11 599",IF(F3="U7","+43 664 458 88 84 & +43 660 549 82 40",IF(F3="FKG","+43 699 111 93 828 & +43 660 600 25 06",IF(A3="Camp","+43 660 77 39 500",IF(A3="Turnier","+43 660 77 39 500","FEHLER"))))))))))))))))
A4: ='ICS2'!I3 -> U16 | B4: ='ICS2'!B3 -> 46199 | C4: ='ICS2'!C3 -> 0.75 | D4: ='ICS2'!E3 -> WIMPASSING | E4: ='ICS2'!H3 -> SK Rapid Wien | F4: =A4 -> U16 | G4: =IF(F4="KM","Großfeld",IF(F4="U23","Großfeld",IF(F4="U16","Großfeld",IF(F4="U15","Großfeld",IF(F4="U14","Großfeld",IF(F4="U12_1","55*40",IF(F4="U12_2","55x40",IF(F4="U11","55x40",IF(F4="U10","40x25",IF(F4="U9","40x25",IF(F4="U8","29x22",IF(F4="U7","25x20","16x15")))))))))))) -> Großfeld | H4: =IF(F4="KM","7,32x2,44",IF(F4="U23","7,32x2,44",IF(F4="U16","7,32x2,44",IF(F4="U15","7,32x2,44",IF(F4="U14","7,32x2,44",IF(F4="U13","5x2",IF(F4="U12_1","7,32x2,44",IF(F4="U12_2","7,32x2,44",IF(F4="U11","5x2",IF(F4="U10","5x2 ",IF(F4="U9","5x2","4 Minitore"))))))))))) -> 7,32x2,44 | I4: =IF(F4="KM","5",IF(F4="U23",5,IF(F4="U16","5",IF(F4="U15","5",IF(F4="U14","4",IF(F4="U13","4",IF(F4="U12_1","4",IF(F4="U12_2","4",IF(F4="U11","4",IF(F4="U10","4",IF(F4="U9","4","3"))))))))))) -> 5 | J4: =IF(F4="KM","Pleninger Stefan & Matthias Wachter",IF(F4="U23","Egzon Gentiani & Dinges Stefan",IF(F4="U16","Serdar Ekinci & Gernot Sevelda & Hubi Oberhofer",IF(F4="U15","",IF(F4="U14","Christian Neckamm & Thomas Pöschl",IF(F4="U13","",IF(F4="U12_1","Tobias Berger & Mario Magler",IF(F4="U12_2","Tobias Berger & Mario Magler",IF(F4="U11","Christian Wirth",IF(F4="U10","Thomas Brandl",IF(F4="U9","Tobias Berger & Sebastian Putric",IF(F4="U8","Ömer Türkes & Taha Mahsumi",IF(F4="U7","Alexander Zax & Jürgen Joszt",IF(F4="FKG","Ronny Archam & Florian Rac",IF(A4="Camp","Berger Dieter",IF(A4="Turnier","Berger Dieter","FEHLER")))))))))))))))) -> Serdar Ekinci & Gernot Sevelda & Hubi Oberhofer | K4: =IF(F4="KM","+43 664 415 99 09 & +43 699 119 70 312",IF(F4="U23","+43 670 18 59 080 & +43 664 451 22 16",IF(F4="U16","+43 690 104 20 129 & +43 676 401 09 13 & +43 699 181 68 504",IF(F4="U15","",IF(F4="U14","+43 699 192 49 527 & +43 677 613 55 114",IF(F4="U13","",IF(F4="U12_1","+43 66 199 13 52 & +43 664 762 09 93",IF(F4="U12_2","+43 66 199 13 52 & +43 664 762 09 93",IF(F4="U11","+43 660 423 93 83",IF(F4="U10","+43 676 377 16 30",IF(F4="U9","+43 66 199 13 52 & +43 660 914 92 36",IF(F4="U8","+43 676 661 62 26 & +43 681 208 11 599",IF(F4="U7","+43 664 458 88 84 & +43 660 549 82 40",IF(F4="FKG","+43 699 111 93 828 & +43 660 600 25 06",IF(A4="Camp","+43 660 77 39 500",IF(A4="Turnier","+43 660 77 39 500","FEHLER")))))))))))))))) -> +43 690 104 20 129 & +43 676 401 09 13 & +43 699 181 68 504
A5: ='ICS2'!I123 -> Camp | B5: ='ICS2'!B123 -> 46230 | C5: ='ICS2'!C123 -> 0.375 | D5: ='ICS2'!E123 -> NEUFELD | E5: ='ICS2'!H123 -> REAL MADRID CAMP | F5: =A5 -> Camp | G5: =IF(F5="KM","Großfeld",IF(F5="U23","Großfeld",IF(F5="U16","Großfeld",IF(F5="U15","Großfeld",IF(F5="U14","Großfeld",IF(F5="U12_1","55*40",IF(F5="U12_2","55x40",IF(F5="U11","55x40",IF(F5="U10","40x25",IF(F5="U9","40x25",IF(F5="U8","29x22",IF(F5="U7","25x20","16x15")))))))))))) -> 16x15 | H5: =IF(F5="KM","7,32x2,44",IF(F5="U23","7,32x2,44",IF(F5="U16","7,32x2,44",IF(F5="U15","7,32x2,44",IF(F5="U14","7,32x2,44",IF(F5="U13","5x2",IF(F5="U12_1","7,32x2,44",IF(F5="U12_2","7,32x2,44",IF(F5="U11","5x2",IF(F5="U10","5x2 ",IF(F5="U9","5x2","4 Minitore"))))))))))) -> 4 Minitore | I5: =IF(F5="KM","5",IF(F5="U23",5,IF(F5="U16","5",IF(F5="U15","5",IF(F5="U14","4",IF(F5="U13","4",IF(F5="U12_1","4",IF(F5="U12_2","4",IF(F5="U11","4",IF(F5="U10","4",IF(F5="U9","4","3"))))))))))) -> 3 | J5: =IF(F5="KM","Pleninger Stefan & Matthias Wachter",IF(F5="U23","Egzon Gentiani & Dinges Stefan",IF(F5="U16","Serdar Ekinci & Gernot Sevelda & Hubi Oberhofer",IF(F5="U15","",IF(F5="U14","Christian Neckamm & Thomas Pöschl",IF(F5="U13","",IF(F5="U12_1","Tobias Berger & Mario Magler",IF(F5="U12_2","Tobias Berger & Mario Magler",IF(F5="U11","Christian Wirth",IF(F5="U10","Thomas Brandl",IF(F5="U9","Tobias Berger & Sebastian Putric",IF(F5="U8","Ömer Türkes & Taha Mahsumi",IF(F5="U7","Alexander Zax & Jürgen Joszt",IF(F5="FKG","Ronny Archam & Florian Rac",IF(A5="Camp","Berger Dieter",IF(A5="Turnier","Berger Dieter","FEHLER")))))))))))))))) -> Berger Dieter | K5: =IF(F5="KM","+43 664 415 99 09 & +43 699 119 70 312",IF(F5="U23","+43 670 18 59 080 & +43 664 451 22 16",IF(F5="U16","+43 690 104 20 129 & +43 676 401 09 13 & +43 699 181 68 504",IF(F5="U15","",IF(F5="U14","+43 699 192 49 527 & +43 677 613 55 114",IF(F5="U13","",IF(F5="U12_1","+43 66 199 13 52 & +43 664 762 09 93",IF(F5="U12_2","+43 66 199 13 52 & +43 664 762 09 93",IF(F5="U11","+43 660 423 93 83",IF(F5="U10","+43 676 377 16 30",IF(F5="U9","+43 66 199 13 52 & +43 660 914 92 36",IF(F5="U8","+43 676 661 62 26 & +43 681 208 11 599",IF(F5="U7","+43 664 458 88 84 & +43 660 549 82 40",IF(F5="FKG","+43 699 111 93 828 & +43 660 600 25 06",IF(A5="Camp","+43 660 77 39 500",IF(A5="Turnier","+43 660 77 39 500","FEHLER")))))))))))))))) -> +43 660 77 39 500
A6: ='ICS2'!I124 -> Camp | B6: ='ICS2'!B124 -> 46231 | C6: ='ICS2'!C124 -> 0.375 | D6: ='ICS2'!E124 -> NEUFELD | E6: ='ICS2'!H124 -> REAL MADRID CAMP | F6: =A6 -> Camp | G6: =IF(F6="KM","Großfeld",IF(F6="U23","Großfeld",IF(F6="U16","Großfeld",IF(F6="U15","Großfeld",IF(F6="U14","Großfeld",IF(F6="U12_1","55*40",IF(F6="U12_2","55x40",IF(F6="U11","55x40",IF(F6="U10","40x25",IF(F6="U9","40x25",IF(F6="U8","29x22",IF(F6="U7","25x20","16x15")))))))))))) -> 16x15 | H6: =IF(F6="KM","7,32x2,44",IF(F6="U23","7,32x2,44",IF(F6="U16","7,32x2,44",IF(F6="U15","7,32x2,44",IF(F6="U14","7,32x2,44",IF(F6="U13","5x2",IF(F6="U12_1","7,32x2,44",IF(F6="U12_2","7,32x2,44",IF(F6="U11","5x2",IF(F6="U10","5x2 ",IF(F6="U9","5x2","4 Minitore"))))))))))) -> 4 Minitore | I6: =IF(F6="KM","5",IF(F6="U23",5,IF(F6="U16","5",IF(F6="U15","5",IF(F6="U14","4",IF(F6="U13","4",IF(F6="U12_1","4",IF(F6="U12_2","4",IF(F6="U11","4",IF(F6="U10","4",IF(F6="U9","4","3"))))))))))) -> 3 | J6: =IF(F6="KM","Pleninger Stefan & Matthias Wachter",IF(F6="U23","Egzon Gentiani & Dinges Stefan",IF(F6="U16","Serdar Ekinci & Gernot Sevelda & Hubi Oberhofer",IF(F6="U15","",IF(F6="U14","Christian Neckamm & Thomas Pöschl",IF(F6="U13","",IF(F6="U12_1","Tobias Berger & Mario Magler",IF(F6="U12_2","Tobias Berger & Mario Magler",IF(F6="U11","Christian Wirth",IF(F6="U10","Thomas Brandl",IF(F6="U9","Tobias Berger & Sebastian Putric",IF(F6="U8","Ömer Türkes & Taha Mahsumi",IF(F6="U7","Alexander Zax & Jürgen Joszt",IF(F6="FKG","Ronny Archam & Florian Rac",IF(A6="Camp","Berger Dieter",IF(A6="Turnier","Berger Dieter","FEHLER")))))))))))))))) -> Berger Dieter | K6: =IF(F6="KM","+43 664 415 99 09 & +43 699 119 70 312",IF(F6="U23","+43 670 18 59 080 & +43 664 451 22 16",IF(F6="U16","+43 690 104 20 129 & +43 676 401 09 13 & +43 699 181 68 504",IF(F6="U15","",IF(F6="U14","+43 699 192 49 527 & +43 677 613 55 114",IF(F6="U13","",IF(F6="U12_1","+43 66 199 13 52 & +43 664 762 09 93",IF(F6="U12_2","+43 66 199 13 52 & +43 664 762 09 93",IF(F6="U11","+43 660 423 93 83",IF(F6="U10","+43 676 377 16 30",IF(F6="U9","+43 66 199 13 52 & +43 660 914 92 36",IF(F6="U8","+43 676 661 62 26 & +43 681 208 11 599",IF(F6="U7","+43 664 458 88 84 & +43 660 549 82 40",IF(F6="FKG","+43 699 111 93 828 & +43 660 600 25 06",IF(A6="Camp","+43 660 77 39 500",IF(A6="Turnier","+43 660 77 39 500","FEHLER")))))))))))))))) -> +43 660 77 39 500
A7: ='ICS2'!I125 -> Camp | B7: ='ICS2'!B125 -> 46232 | C7: ='ICS2'!C125 -> 0.375 | D7: ='ICS2'!E125 -> NEUFELD | E7: ='ICS2'!H125 -> REAL MADRID CAMP | F7: =A7 -> Camp | G7: =IF(F7="KM","Großfeld",IF(F7="U23","Großfeld",IF(F7="U16","Großfeld",IF(F7="U15","Großfeld",IF(F7="U14","Großfeld",IF(F7="U12_1","55*40",IF(F7="U12_2","55x40",IF(F7="U11","55x40",IF(F7="U10","40x25",IF(F7="U9","40x25",IF(F7="U8","29x22",IF(F7="U7","25x20","16x15")))))))))))) -> 16x15 | H7: =IF(F7="KM","7,32x2,44",IF(F7="U23","7,32x2,44",IF(F7="U16","7,32x2,44",IF(F7="U15","7,32x2,44",IF(F7="U14","7,32x2,44",IF(F7="U13","5x2",IF(F7="U12_1","7,32x2,44",IF(F7="U12_2","7,32x2,44",IF(F7="U11","5x2",IF(F7="U10","5x2 ",IF(F7="U9","5x2","4 Minitore"))))))))))) -> 4 Minitore | I7: =IF(F7="KM","5",IF(F7="U23",5,IF(F7="U16","5",IF(F7="U15","5",IF(F7="U14","4",IF(F7="U13","4",IF(F7="U12_1","4",IF(F7="U12_2","4",IF(F7="U11","4",IF(F7="U10","4",IF(F7="U9","4","3"))))))))))) -> 3 | J7: =IF(F7="KM","Pleninger Stefan & Matthias Wachter",IF(F7="U23","Egzon Gentiani & Dinges Stefan",IF(F7="U16","Serdar Ekinci & Gernot Sevelda & Hubi Oberhofer",IF(F7="U15","",IF(F7="U14","Christian Neckamm & Thomas Pöschl",IF(F7="U13","",IF(F7="U12_1","Tobias Berger & Mario Magler",IF(F7="U12_2","Tobias Berger & Mario Magler",IF(F7="U11","Christian Wirth",IF(F7="U10","Thomas Brandl",IF(F7="U9","Tobias Berger & Sebastian Putric",IF(F7="U8","Ömer Türkes & Taha Mahsumi",IF(F7="U7","Alexander Zax & Jürgen Joszt",IF(F7="FKG","Ronny Archam & Florian Rac",IF(A7="Camp","Berger Dieter",IF(A7="Turnier","Berger Dieter","FEHLER")))))))))))))))) -> Berger Dieter | K7: =IF(F7="KM","+43 664 415 99 09 & +43 699 119 70 312",IF(F7="U23","+43 670 18 59 080 & +43 664 451 22 16",IF(F7="U16","+43 690 104 20 129 & +43 676 401 09 13 & +43 699 181 68 504",IF(F7="U15","",IF(F7="U14","+43 699 192 49 527 & +43 677 613 55 114",IF(F7="U13","",IF(F7="U12_1","+43 66 199 13 52 & +43 664 762 09 93",IF(F7="U12_2","+43 66 199 13 52 & +43 664 762 09 93",IF(F7="U11","+43 660 423 93 83",IF(F7="U10","+43 676 377 16 30",IF(F7="U9","+43 66 199 13 52 & +43 660 914 92 36",IF(F7="U8","+43 676 661 62 26 & +43 681 208 11 599",IF(F7="U7","+43 664 458 88 84 & +43 660 549 82 40",IF(F7="FKG","+43 699 111 93 828 & +43 660 600 25 06",IF(A7="Camp","+43 660 77 39 500",IF(A7="Turnier","+43 660 77 39 500","FEHLER")))))))))))))))) -> +43 660 77 39 500
A8: ='ICS2'!I126 -> Camp | B8: ='ICS2'!B126 -> 46233 | C8: ='ICS2'!C126 -> 0.375 | D8: ='ICS2'!E126 -> NEUFELD | E8: ='ICS2'!H126 -> REAL MADRID CAMP | F8: =A8 -> Camp | G8: =IF(F8="KM","Großfeld",IF(F8="U23","Großfeld",IF(F8="U16","Großfeld",IF(F8="U15","Großfeld",IF(F8="U14","Großfeld",IF(F8="U12_1","55*40",IF(F8="U12_2","55x40",IF(F8="U11","55x40",IF(F8="U10","40x25",IF(F8="U9","40x25",IF(F8="U8","29x22",IF(F8="U7","25x20","16x15")))))))))))) -> 16x15 | H8: =IF(F8="KM","7,32x2,44",IF(F8="U23","7,32x2,44",IF(F8="U16","7,32x2,44",IF(F8="U15","7,32x2,44",IF(F8="U14","7,32x2,44",IF(F8="U13","5x2",IF(F8="U12_1","7,32x2,44",IF(F8="U12_2","7,32x2,44",IF(F8="U11","5x2",IF(F8="U10","5x2 ",IF(F8="U9","5x2","4 Minitore"))))))))))) -> 4 Minitore | I8: =IF(F8="KM","5",IF(F8="U23",5,IF(F8="U16","5",IF(F8="U15","5",IF(F8="U14","4",IF(F8="U13","4",IF(F8="U12_1","4",IF(F8="U12_2","4",IF(F8="U11","4",IF(F8="U10","4",IF(F8="U9","4","3"))))))))))) -> 3 | J8: =IF(F8="KM","Pleninger Stefan & Matthias Wachter",IF(F8="U23","Egzon Gentiani & Dinges Stefan",IF(F8="U16","Serdar Ekinci & Gernot Sevelda & Hubi Oberhofer",IF(F8="U15","",IF(F8="U14","Christian Neckamm & Thomas Pöschl",IF(F8="U13","",IF(F8="U12_1","Tobias Berger & Mario Magler",IF(F8="U12_2","Tobias Berger & Mario Magler",IF(F8="U11","Christian Wirth",IF(F8="U10","Thomas Brandl",IF(F8="U9","Tobias Berger & Sebastian Putric",IF(F8="U8","Ömer Türkes & Taha Mahsumi",IF(F8="U7","Alexander Zax & Jürgen Joszt",IF(F8="FKG","Ronny Archam & Florian Rac",IF(A8="Camp","Berger Dieter",IF(A8="Turnier","Berger Dieter","FEHLER")))))))))))))))) -> Berger Dieter | K8: =IF(F8="KM","+43 664 415 99 09 & +43 699 119 70 312",IF(F8="U23","+43 670 18 59 080 & +43 664 451 22 16",IF(F8="U16","+43 690 104 20 129 & +43 676 401 09 13 & +43 699 181 68 504",IF(F8="U15","",IF(F8="U14","+43 699 192 49 527 & +43 677 613 55 114",IF(F8="U13","",IF(F8="U12_1","+43 66 199 13 52 & +43 664 762 09 93",IF(F8="U12_2","+43 66 199 13 52 & +43 664 762 09 93",IF(F8="U11","+43 660 423 93 83",IF(F8="U10","+43 676 377 16 30",IF(F8="U9","+43 66 199 13 52 & +43 660 914 92 36",IF(F8="U8","+43 676 661 62 26 & +43 681 208 11 599",IF(F8="U7","+43 664 458 88 84 & +43 660 549 82 40",IF(F8="FKG","+43 699 111 93 828 & +43 660 600 25 06",IF(A8="Camp","+43 660 77 39 500",IF(A8="Turnier","+43 660 77 39 500","FEHLER")))))))))))))))) -> +43 660 77 39 500
A9: ='ICS2'!I127 -> Camp | B9: ='ICS2'!B127 -> 46234 | C9: ='ICS2'!C127 -> 0.375 | D9: ='ICS2'!E127 -> NEUFELD | E9: ='ICS2'!H127 -> REAL MADRID CAMP | F9: =A9 -> Camp | G9: =IF(F9="KM","Großfeld",IF(F9="U23","Großfeld",IF(F9="U16","Großfeld",IF(F9="U15","Großfeld",IF(F9="U14","Großfeld",IF(F9="U12_1","55*40",IF(F9="U12_2","55x40",IF(F9="U11","55x40",IF(F9="U10","40x25",IF(F9="U9","40x25",IF(F9="U8","29x22",IF(F9="U7","25x20","16x15")))))))))))) -> 16x15 | H9: =IF(F9="KM","7,32x2,44",IF(F9="U23","7,32x2,44",IF(F9="U16","7,32x2,44",IF(F9="U15","7,32x2,44",IF(F9="U14","7,32x2,44",IF(F9="U13","5x2",IF(F9="U12_1","7,32x2,44",IF(F9="U12_2","7,32x2,44",IF(F9="U11","5x2",IF(F9="U10","5x2 ",IF(F9="U9","5x2","4 Minitore"))))))))))) -> 4 Minitore | I9: =IF(F9="KM","5",IF(F9="U23",5,IF(F9="U16","5",IF(F9="U15","5",IF(F9="U14","4",IF(F9="U13","4",IF(F9="U12_1","4",IF(F9="U12_2","4",IF(F9="U11","4",IF(F9="U10","4",IF(F9="U9","4","3"))))))))))) -> 3 | J9: =IF(F9="KM","Pleninger Stefan & Matthias Wachter",IF(F9="U23","Egzon Gentiani & Dinges Stefan",IF(F9="U16","Serdar Ekinci & Gernot Sevelda & Hubi Oberhofer",IF(F9="U15","",IF(F9="U14","Christian Neckamm & Thomas Pöschl",IF(F9="U13","",IF(F9="U12_1","Tobias Berger & Mario Magler",IF(F9="U12_2","Tobias Berger & Mario Magler",IF(F9="U11","Christian Wirth",IF(F9="U10","Thomas Brandl",IF(F9="U9","Tobias Berger & Sebastian Putric",IF(F9="U8","Ömer Türkes & Taha Mahsumi",IF(F9="U7","Alexander Zax & Jürgen Joszt",IF(F9="FKG","Ronny Archam & Florian Rac",IF(A9="Camp","Berger Dieter",IF(A9="Turnier","Berger Dieter","FEHLER")))))))))))))))) -> Berger Dieter | K9: =IF(F9="KM","+43 664 415 99 09 & +43 699 119 70 312",IF(F9="U23","+43 670 18 59 080 & +43 664 451 22 16",IF(F9="U16","+43 690 104 20 129 & +43 676 401 09 13 & +43 699 181 68 504",IF(F9="U15","",IF(F9="U14","+43 699 192 49 527 & +43 677 613 55 114",IF(F9="U13","",IF(F9="U12_1","+43 66 199 13 52 & +43 664 762 09 93",IF(F9="U12_2","+43 66 199 13 52 & +43 664 762 09 93",IF(F9="U11","+43 660 423 93 83",IF(F9="U10","+43 676 377 16 30",IF(F9="U9","+43 66 199 13 52 & +43 660 914 92 36",IF(F9="U8","+43 676 661 62 26 & +43 681 208 11 599",IF(F9="U7","+43 664 458 88 84 & +43 660 549 82 40",IF(F9="FKG","+43 699 111 93 828 & +43 660 600 25 06",IF(A9="Camp","+43 660 77 39 500",IF(A9="Turnier","+43 660 77 39 500","FEHLER")))))))))))))))) -> +43 660 77 39 500
A10: ='ICS2'!I10 -> U16 | B10: ='ICS2'!B10 -> 46236 | C10: ='ICS2'!C10 -> 0.4375 | D10: ='ICS2'!E10 -> NEUFELD | E10: ='ICS2'!H10 -> Theresienfeld | F10: =A10 -> U16 | G10: =IF(F10="KM","Großfeld",IF(F10="U23","Großfeld",IF(F10="U16","Großfeld",IF(F10="U15","Großfeld",IF(F10="U14","Großfeld",IF(F10="U12_1","55*40",IF(F10="U12_2","55x40",IF(F10="U11","55x40",IF(F10="U10","40x25",IF(F10="U9","40x25",IF(F10="U8","29x22",IF(F10="U7","25x20","16x15")))))))))))) -> Großfeld | H10: =IF(F10="KM","7,32x2,44",IF(F10="U23","7,32x2,44",IF(F10="U16","7,32x2,44",IF(F10="U15","7,32x2,44",IF(F10="U14","7,32x2,44",IF(F10="U13","5x2",IF(F10="U12_1","7,32x2,44",IF(F10="U12_2","7,32x2,44",IF(F10="U11","5x2",IF(F10="U10","5x2 ",IF(F10="U9","5x2","4 Minitore"))))))))))) -> 7,32x2,44 | I10: =IF(F10="KM","5",IF(F10="U23",5,IF(F10="U16","5",IF(F10="U15","5",IF(F10="U14","4",IF(F10="U13","4",IF(F10="U12_1","4",IF(F10="U12_2","4",IF(F10="U11","4",IF(F10="U10","4",IF(F10="U9","4","3"))))))))))) -> 5 | J10: =IF(F10="KM","Pleninger Stefan & Matthias Wachter",IF(F10="U23","Egzon Gentiani & Dinges Stefan",IF(F10="U16","Serdar Ekinci & Gernot Sevelda & Hubi Oberhofer",IF(F10="U15","",IF(F10="U14","Christian Neckamm & Thomas Pöschl",IF(F10="U13","",IF(F10="U12_1","Tobias Berger & Mario Magler",IF(F10="U12_2","Tobias Berger & Mario Magler",IF(F10="U11","Christian Wirth",IF(F10="U10","Thomas Brandl",IF(F10="U9","Tobias Berger & Sebastian Putric",IF(F10="U8","Ömer Türkes & Taha Mahsumi",IF(F10="U7","Alexander Zax & Jürgen Joszt",IF(F10="FKG","Ronny Archam & Florian Rac",IF(A10="Camp","Berger Dieter",IF(A10="Turnier","Berger Dieter","FEHLER")))))))))))))))) -> Serdar Ekinci & Gernot Sevelda & Hubi Oberhofer | K10: =IF(F10="KM","+43 664 415 99 09 & +43 699 119 70 312",IF(F10="U23","+43 670 18 59 080 & +43 664 451 22 16",IF(F10="U16","+43 690 104 20 129 & +43 676 401 09 13 & +43 699 181 68 504",IF(F10="U15","",IF(F10="U14","+43 699 192 49 527 & +43 677 613 55 114",IF(F10="U13","",IF(F10="U12_1","+43 66 199 13 52 & +43 664 762 09 93",IF(F10="U12_2","+43 66 199 13 52 & +43 664 762 09 93",IF(F10="U11","+43 660 423 93 83",IF(F10="U10","+43 676 377 16 30",IF(F10="U9","+43 66 199 13 52 & +43 660 914 92 36",IF(F10="U8","+43 676 661 62 26 & +43 681 208 11 599",IF(F10="U7","+43 664 458 88 84 & +43 660 549 82 40",IF(F10="FKG","+43 699 111 93 828 & +43 660 600 25 06",IF(A10="Camp","+43 660 77 39 500",IF(A10="Turnier","+43 660 77 39 500","FEHLER")))))))))))))))) -> +43 690 104 20 129 & +43 676 401 09 13 & +43 699 181 68 504
A11: ='ICS2'!I128 -> Camp | B11: ='ICS2'!B128 -> 46237 | C11: ='ICS2'!C128 -> 0.375 | D11: ='ICS2'!E128 -> NEUFELD | E11: ='ICS2'!H128 -> MÄDCHENCAMP | F11: =A11 -> Camp | I11: =IF(F11="Großfeld","5",IF(F11="U16","5",IF(F11="U15","5",IF(F11="U14","4",IF(F11="U13","4",IF(F11="U11/U12","4",IF(F11="U9/U10","4",IF(F11="U9","4","3")))))))) -> 3 | J11: =IF(F11="KM","Pleninger Stefan & Matthias Wachter",IF(F11="U23","Egzon Gentiani & Dinges Stefan",IF(F11="U16","Serdar Ekinci & Gernot Sevelda & Hubi Oberhofer",IF(F11="U15","",IF(F11="U14","Christian Neckamm & Thomas Pöschl",IF(F11="U13","",IF(F11="U12_1","Tobias Berger & Mario Magler",IF(F11="U12_2","Tobias Berger & Mario Magler",IF(F11="U11","Christian Wirth",IF(F11="U10","Thomas Brandl",IF(F11="U9","Tobias Berger & Sebastian Putric",IF(F11="U8","Ömer Türkes & Taha Mahsumi",IF(F11="U7","Alexander Zax & Jürgen Joszt",IF(F11="FKG","Ronny Archam & Florian Rac",IF(A11="Camp","Berger Dieter",IF(A11="Turnier","Berger Dieter","FEHLER")))))))))))))))) -> Berger Dieter | K11: =IF(F11="KM","+43 664 415 99 09 & +43 699 119 70 312",IF(F11="U23","+43 670 18 59 080 & +43 664 451 22 16",IF(F11="U16","+43 690 104 20 129 & +43 676 401 09 13 & +43 699 181 68 504",IF(F11="U15","",IF(F11="U14","+43 699 192 49 527 & +43 677 613 55 114",IF(F11="U13","",IF(F11="U12_1","+43 66 199 13 52 & +43 664 762 09 93",IF(F11="U12_2","+43 66 199 13 52 & +43 664 762 09 93",IF(F11="U11","+43 660 423 93 83",IF(F11="U10","+43 676 377 16 30",IF(F11="U9","+43 66 199 13 52 & +43 660 914 92 36",IF(F11="U8","+43 676 661 62 26 & +43 681 208 11 599",IF(F11="U7","+43 664 458 88 84 & +43 660 549 82 40",IF(F11="FKG","+43 699 111 93 828 & +43 660 600 25 06",IF(A11="Camp","+43 660 77 39 500",IF(A11="Turnier","+43 660 77 39 500","FEHLER")))))))))))))))) -> +43 660 77 39 500
A12: ='ICS2'!I129 -> Camp | B12: ='ICS2'!B129 -> 46238 | C12: ='ICS2'!C129 -> 0.375 | D12: ='ICS2'!E129 -> NEUFELD | E12: ='ICS2'!H129 -> MÄDCHENCAMP | F12: =A12 -> Camp | I12: =IF(F12="Großfeld","5",IF(F12="U16","5",IF(F12="U15","5",IF(F12="U14","4",IF(F12="U13","4",IF(F12="U11/U12","4",IF(F12="U9/U10","4",IF(F12="U9","4","3")))))))) -> 3 | J12: =IF(F12="KM","Pleninger Stefan & Matthias Wachter",IF(F12="U23","Egzon Gentiani & Dinges Stefan",IF(F12="U16","Serdar Ekinci & Gernot Sevelda & Hubi Oberhofer",IF(F12="U15","",IF(F12="U14","Christian Neckamm & Thomas Pöschl",IF(F12="U13","",IF(F12="U12_1","Tobias Berger & Mario Magler",IF(F12="U12_2","Tobias Berger & Mario Magler",IF(F12="U11","Christian Wirth",IF(F12="U10","Thomas Brandl",IF(F12="U9","Tobias Berger & Sebastian Putric",IF(F12="U8","Ömer Türkes & Taha Mahsumi",IF(F12="U7","Alexander Zax & Jürgen Joszt",IF(F12="FKG","Ronny Archam & Florian Rac",IF(A12="Camp","Berger Dieter",IF(A12="Turnier","Berger Dieter","FEHLER")))))))))))))))) -> Berger Dieter | K12: =IF(F12="KM","+43 664 415 99 09 & +43 699 119 70 312",IF(F12="U23","+43 670 18 59 080 & +43 664 451 22 16",IF(F12="U16","+43 690 104 20 129 & +43 676 401 09 13 & +43 699 181 68 504",IF(F12="U15","",IF(F12="U14","+43 699 192 49 527 & +43 677 613 55 114",IF(F12="U13","",IF(F12="U12_1","+43 66 199 13 52 & +43 664 762 09 93",IF(F12="U12_2","+43 66 199 13 52 & +43 664 762 09 93",IF(F12="U11","+43 660 423 93 83",IF(F12="U10","+43 676 377 16 30",IF(F12="U9","+43 66 199 13 52 & +43 660 914 92 36",IF(F12="U8","+43 676 661 62 26 & +43 681 208 11 599",IF(F12="U7","+43 664 458 88 84 & +43 660 549 82 40",IF(F12="FKG","+43 699 111 93 828 & +43 660 600 25 06",IF(A12="Camp","+43 660 77 39 500",IF(A12="Turnier","+43 660 77 39 500","FEHLER")))))))))))))))) -> +43 660 77 39 500
A13: ='ICS2'!I130 -> Camp | B13: ='ICS2'!B130 -> 46239 | C13: ='ICS2'!C130 -> 0.375 | D13: ='ICS2'!E130 -> NEUFELD | E13: ='ICS2'!H130 -> MÄDCHENCAMP | F13: =A13 -> Camp | I13: =IF(F13="Großfeld","5",IF(F13="U16","5",IF(F13="U15","5",IF(F13="U14","4",IF(F13="U13","4",IF(F13="U11/U12","4",IF(F13="U9/U10","4",IF(F13="U9","4","3")))))))) -> 3 | J13: =IF(F13="KM","Pleninger Stefan & Matthias Wachter",IF(F13="U23","Egzon Gentiani & Dinges Stefan",IF(F13="U16","Serdar Ekinci & Gernot Sevelda & Hubi Oberhofer",IF(F13="U15","",IF(F13="U14","Christian Neckamm & Thomas Pöschl",IF(F13="U13","",IF(F13="U12_1","Tobias Berger & Mario Magler",IF(F13="U12_2","Tobias Berger & Mario Magler",IF(F13="U11","Christian Wirth",IF(F13="U10","Thomas Brandl",IF(F13="U9","Tobias Berger & Sebastian Putric",IF(F13="U8","Ömer Türkes & Taha Mahsumi",IF(F13="U7","Alexander Zax & Jürgen Joszt",IF(F13="FKG","Ronny Archam & Florian Rac",IF(A13="Camp","Berger Dieter",IF(A13="Turnier","Berger Dieter","FEHLER")))))))))))))))) -> Berger Dieter | K13: =IF(F13="KM","+43 664 415 99 09 & +43 699 119 70 312",IF(F13="U23","+43 670 18 59 080 & +43 664 451 22 16",IF(F13="U16","+43 690 104 20 129 & +43 676 401 09 13 & +43 699 181 68 504",IF(F13="U15","",IF(F13="U14","+43 699 192 49 527 & +43 677 613 55 114",IF(F13="U13","",IF(F13="U12_1","+43 66 199 13 52 & +43 664 762 09 93",IF(F13="U12_2","+43 66 199 13 52 & +43 664 762 09 93",IF(F13="U11","+43 660 423 93 83",IF(F13="U10","+43 676 377 16 30",IF(F13="U9","+43 66 199 13 52 & +43 660 914 92 36",IF(F13="U8","+43 676 661 62 26 & +43 681 208 11 599",IF(F13="U7","+43 664 458 88 84 & +43 660 549 82 40",IF(F13="FKG","+43 699 111 93 828 & +43 660 600 25 06",IF(A13="Camp","+43 660 77 39 500",IF(A13="Turnier","+43 660 77 39 500","FEHLER")))))))))))))))) -> +43 660 77 39 500
